Workbook

Sheet Pviots
A3: Count of Sample ID | B3: Column Labels
A4: Row Labels | B4: 45868 | C4: 45869 | D4: 45873 | E4: 45874 | F4: 45875 | G4: 45876 | H4: 45877 | I4: Grand Total
A5: Subramanian | B5: 101 | C5: 389 | D5: 146 | E5: 53 | F5: 137 | G5: 233 | H5: 48 | I5: 1107
A6: A.Banu | B6: 40 | C6: 106 | D6: 22 | I6: 168
A7: G.muthukumar | B7: 1 | C7: 6 | F7: 30 | G7: 61 | I7: 98
A8: Sinthanai selvi | B8: 24 | C8: 123 | I8: 147
A9: U.Amir nisha | B9: 36 | C9: 154 | D9: 65 | I9: 255
A10: priya | D10: 22 | E10: 25 | F10: 41 | G10: 61 | H10: 25 | I10: 174
A11: Immaculatebanumathi | D11: 37 | E11: 28 | F11: 53 | G11: 72 | H11: 23 | I11: 213
A12: pantyan | F12: 13 | G12: 39 | I12: 52
A13: Grand Total | B13: 101 | C13: 389 | D13: 146 | E13: 53 | F13: 137 | G13: 233 | H13: 48 | I13: 1107
A21: Date | B21: 45877 | G21: Date | H21: 45876
A22: Surveyor Vendor Name | B22: (All) | G22: Surveyor Vendor Name | H22: (All)
A24: Count of Sample ID | B24: Column Labels | G24: Count of Sample ID | H24: Column Labels
A25: Row Labels | B25: Greater than 3 Minutes | C25: Grand Total | G25: Row Labels | H25: 18-30 | I25: 31-45 | J25: 46-60 | K25: 60+ | L25: Grand Total
A26: priya | B26: 25 | C26: 25 | G26: G.muthukumar | H26: 23 | I26: 8 | J26: 24 | K26: 6 | L26: 61
A27: Immaculatebanumathi | B27: 23 | C27: 23 | G27: priya | H27: 11 | I27: 28 | J27: 17 | K27: 5 | L27: 61
A28: Grand Total | B28: 48 | C28: 48 | G28: Immaculatebanumathi | H28: 18 | I28: 26 | J28: 19 | K28: 9 | L28: 72
G29: pantyan | H29: 4 | I29: 13 | J29: 16 | K29: 6 | L29: 39
G30: Grand Total | H30: 56 | I30: 75 | J30: 76 | K30: 26 | L30: 233
A37: Date | B37: 45877
A39: Count of Sample ID | B39: Column Labels
A40: Row Labels | B40: ஆண்/Male | C40: பெண்/Female | D40: Grand Total
A41: Subramanian | B41: 0.39583333 | C41: 0.60416667 | D41: 1 | E41: Sample Count
A42: priya | B42: 0.4 | C42: 0.6 | D42: 1 | E42: 23
A43: Immaculatebanumathi | B43: 0.39130435 | C43: 0.60869565 | D43: 1 | E43: 29
A44: Grand Total | B44: 0.39583333 | C44: 0.60416667 | D44: 1 | E44: 30
E45: 13
E46: 95

Sheet Data Updation
A1: Date | B1: 45877 | D1: Date | E1: (All) | I1: DMK | J1: TVK | K1: AIADMK | L1: INC | M1: BJP | N1: NTK | O1: DMDK | P1: VCK | Q1: PMK | R1: CPI | S1: CPM | T1: Others
A2: Consider | B2: Yes | D2: Consider | E2: Yes | I2: =IFERROR(VLOOKUP(I1,$A$4:$B$15,2,0),0%) -> 0.4 | J2: =IFERROR(VLOOKUP(J1,$A$4:$B$15,2,0),0%) -> 0.13333333 | K2: =IFERROR(VLOOKUP(K1,$A$4:$B$15,2,0),0%) -> 0.36666667 | L2: =IFERROR(VLOOKUP(L1,$A$4:$B$15,2,0),0%) -> 0 | M2: =IFERROR(VLOOKUP(M1,$A$4:$B$15,2,0),0%) -> 0 | N2: =IFERROR(VLOOKUP(N1,$A$4:$B$15,2,0),0%) -> 0 | O2: =IFERROR(VLOOKUP(O1,$A$4:$B$15,2,0),0%) -> 0 | P2: =IFERROR(VLOOKUP(P1,$A$4:$B$15,2,0),0%) -> 0 | ... T2: =IFERROR(VLOOKUP(T1,$A$4:$B$15,2,0),0%) -> 0.1
I3: =IFERROR(VLOOKUP(I$1,$D$4:$E$19,2,0),0%) -> 0.38769531 | J3: =IFERROR(VLOOKUP(J$1,$D$4:$E$19,2,0),0%) -> 0.22363281 | K3: =IFERROR(VLOOKUP(K$1,$D$4:$E$19,2,0),0%) -> 0.31445312 | L3: =IFERROR(VLOOKUP(L$1,$D$4:$E$19,2,0),0%) -> 0.0087890625 | M3: =IFERROR(VLOOKUP(M$1,$D$4:$E$19,2,0),0%) -> 0.0068359375 | N3: =IFERROR(VLOOKUP(N$1,$D$4:$E$19,2,0),0%) -> 0.0078125 | O3: =IFERROR(VLOOKUP(O$1,$D$4:$E$19,2,0),0%) -> 0.012695312 | P3: =IFERROR(VLOOKUP(P$1,$D$4:$E$19,2,0),0%) -> 0 | ... T3: =IFERROR(VLOOKUP(T$1,$D$4:$E$19,2,0),0%) -> 0.034179688
A4: Row Labels | B4: Count of Sample ID | D4: Row Labels | E4: Count of Sample ID
A5: DMK | B5: 0.4 | D5: INC | E5: 0.0087890625
A6: AIADMK | B6: 0.36666667 | D6: DMK | E6: 0.38769531
A7: TVK | B7: 0.13333333 | D7: AIADMK | E7: 0.31445312
A8: Others | B8: 0.1 | D8: TVK | E8: 0.22363281
A9: Grand Total | B9: 1 | D9: DMDK | E9: 0.012695312
D10: BJP | E10: 0.0068359375
D11: CPM | E11: 0.00390625
D12: Others | E12: 0.034179688
D13: NTK | E13: 0.0078125
D14: Grand Total | E14: 1 | I14: Consider | J14: Yes
I16: Row Labels | J16: Count of Sample ID | L16: Count of Sample ID | M16: Column Labels
I17: 45868 | J17: 77 | L17: Row Labels | M17: AIADMK | N17: BJP | O17: CPM | P17: DMDK | Q17: DMK | R17: INC | S17: NTK | T17: Others | U17: TVK | V17: Grand Total
I18: 45869 | J18: 353 | L18: ANNAVASAL | M18: 45 | N18: 3 | O18: 4 | P18: 4 | Q18: 51 | R18: 5 | T18: 4 | U18: 31 | V18: 147
I19: 45873 | J19: 143 | L19: ATHIPALLAM | Q19: 1 | V19: 1
I20: 45874 | J20: 53 | L20: KILIKUDI | M20: 37 | Q20: 12 | U20: 22 | V20: 71
I21: 45875 | J21: 135 | L21: KUDUMIYANMALAI | M21: 28 | Q21: 46 | T21: 1 | U21: 29 | V21: 104
I22: 45876 | J22: 233 | L22: MANGUDI | M22: 40 | Q22: 29 | S22: 4 | U22: 14 | V22: 87
I23: 45877 | J23: 30 | L23: MUKKANNAMALAIPATTI | M23: 12 | P23: 7 | Q23: 42 | U23: 14 | V23: 75
I24: Grand Total | J24: 1024 | L24: PARAMBUR | M24: 25 | Q24: 45 | T24: 3 | U24: 12 | V24: 85
L25: RAJALIPATTI | M25: 12 | Q25: 25 | S25: 1 | U25: 2 | V25: 40
L26: VEERAPATTI | U26: 1 | V26: 1
L27: VIRALIMALAI | M27: 133 | N27: 4 | P27: 3 | Q27: 158 | R27: 4 | S27: 4 | T27: 24 | U27: 118 | V27: 448
L28: MATHUR | M28: 12 | Q28: 24 | T28: 4 | U28: 8 | V28: 48
L29: Grand Total | M29: 344 | N29: 7 | O29: 4 | P29: 14 | Q29: 433 | R29: 9 | S29: 9 | T29: 36 | U29: 251 | V29: 1107

Sheet Factor
F3: Party | G3: 2021
F4: ADMK | G4: 0.52826706
F5: DMK | G5: 0.40626503
A6: Consider | B6: Yes | F6: NTK | G6: 0.036371062
F7: Others | G7: =1-SUM(G4:G6) -> 0.02909685
A8: Row Labels | B8: Count | C8: %
A9: அதிமுக கூட்டணி / AIADMK Alliance | B9: 333 | C9: 333 | F9: 2021 Ae | G9: TBT | H9: Collected | I9: Collected % | J9: Factor
A10: திமுக கூட்டணி / DMK Alliance | B10: 456 | C10: 456 | F10: அதிமுக கூட்டணி / AIADMK Alliance | G10: 0.52826706 | H10: =VLOOKUP(F10,$A$8:$B$14,2,0) -> 333 | I10: =H10/SUM($H$10:$H$12) -> 0.40266022 | J10: =G10/I10 -> 1.3119425 | L10: increase to 40%
A11: பிற கட்சிகள் / Others | B11: 38 | C11: 38 | F11: திமுக கூட்டணி / DMK Alliance | G11: 0.40626503 | H11: =VLOOKUP(F11,$A$8:$B$14,2,0) -> 456 | I11: =H11/SUM($H$10:$H$12) -> 0.55139057 | J11: =G11/I11 -> 0.73680082
A12: நினைவில் இல்லை / Don’t Remember | B12: 154 | C12: 154 | F12: பிற கட்சிகள் / Others | G12: =1-SUM(G10:G11) -> 0.065467912 | H12: =VLOOKUP(F12,$A$8:$B$14,2,0) -> 38 | I12: =H12/SUM($H$10:$H$12) -> 0.045949214 | J12: =G12/I12 -> 1.4247885
A13: வாக்களிக்கவில்லை / Did not Vote | B13: 43 | C13: 43 | F13: நினைவில் இல்லை / Don’t Remember | J13: 1
A14: Grand Total | B14: 1024 | C14: 1024 | F14: வாக்களிக்கவில்லை / Did not Vote | J14: 1
A25: Consider | B25: Yes
F26: Gender | G26: TBT | H26: Collected | I26: Factor
A27: Row Labels | B27: Count | C27: % | F27: ஆண்/Male | G27: 0.5 | H27: =VLOOKUP(F27,$A$28:$C$29,3,0) -> 0.52246094 | I27: =G27/H27 -> 0.95700935
A28: ஆண்/Male | B28: 535 | C28: 0.52246094 | F28: பெண்/Female | G28: 0.5 | H28: =VLOOKUP(F28,$A$28:$C$29,3,0) -> 0.47753906 | I28: =G28/H28 -> 1.0470348
A29: பெண்/Female | B29: 489 | C29: 0.47753906
A30: Grand Total | B30: 1024 | C30: 1
A33: Consider | B33: Yes
A35: Row Labels | B35: Count | C35: % | F35: Age | G35: TBT | H35: Collected | I35: Factor
A36: 18-30 | B36: 210 | C36: 0.20507812 | F36: 18-30 | G36: 0.2 | H36: =VLOOKUP(F36,$A$35:$C$40,3,0) -> 0.20507812 | I36: =G36/H36 -> 0.9752381
A37: 31-45 | B37: 374 | C37: 0.36523438 | F37: 31-45 | G37: 0.4 | H37: =VLOOKUP(F37,$A$35:$C$40,3,0) -> 0.36523438 | I37: =G37/H37 -> 1.0951872
A38: 46-60 | B38: 291 | C38: 0.28417969 | F38: 46-60 | G38: 0.25 | H38: =VLOOKUP(F38,$A$35:$C$40,3,0) -> 0.28417969 | I38: =G38/H38 -> 0.87972509
A39: 60+ | B39: 149 | C39: 0.14550781 | F39: 60+ | G39: 0.15 | H39: =VLOOKUP(F39,$A$35:$C$40,3,0) -> 0.14550781 | I39: =G39/H39 -> 1.0308725
A40: Grand Total | B40: 1024 | C40: 1
B43: Consider | C43: Yes
B45: பதிலளித்தவரின் வயது/Age Group | C45: பாலினம்/Gender | D45: Count | E45: % | F45: TBT | G45: Factor
A46: =B46&C46 -> 18-30ஆண்/Male | B46: 18-30 | C46: ஆண்/Male | D46: 96 | E46: 0.09375 | F46: 0.1 | G46: =F46/E46 -> 1.0666667
A47: =B47&C47 -> 18-30பெண்/Female | B47: 18-30 | C47: பெண்/Female | D47: 114 | E47: 0.11132812 | F47: 0.1 | G47: =F47/E47 -> 0.89824561
A48: =B48&C48 -> 31-45ஆண்/Male | B48: 31-45 | C48: ஆண்/Male | D48: 189 | E48: 0.18457031 | F48: 0.2 | G48: =F48/E48 -> 1.0835979
A49: =B49&C49 -> 31-45பெண்/Female | B49: 31-45 | C49: பெண்/Female | D49: 185 | E49: 0.18066406 | F49: 0.2 | G49: =F49/E49 -> 1.107027
A50: =B50&C50 -> 46-60ஆண்/Male | B50: 46-60 | C50: ஆண்/Male | D50: 161 | E50: 0.15722656 | F50: 0.125 | G50: =F50/E50 -> 0.79503106
A51: =B51&C51 -> 46-60பெண்/Female | B51: 46-60 | C51: பெண்/Female | D51: 130 | E51: 0.12695312 | F51: 0.125 | G51: =F51/E51 -> 0.98461538
A52: =B52&C52 -> 60+ஆண்/Male | B52: 60+ | C52: ஆண்/Male | D52: 89 | E52: 0.086914062 | F52: 0.075 | G52: =F52/E52 -> 0.86292135
A53: =B53&C53 -> 60+பெண்/Female | B53: 60+ | C53: பெண்/Female | D53: 60 | E53: 0.05859375 | F53: 0.075 | G53: =F53/E53 -> 1.28
B54: Grand Total | D54: 1024 | E54: 1
B58: Consider | C58: Yes
F59: Caste | G59: TBT | H59: Collected | I59: Factor
B60: Row Labels | C60: Count | D60: % | F60: MUTTARAIYAR | G60: 0.28 | H60: =VLOOKUP(F60,$B$61:$D$70,3,0) -> 0.2265625 | I60: =G60/H60 -> 1.2358621
B61: CHOLIA VELLALAR | C61: 96 | D61: 0.09375 | F61: DEVENDRA KULA VELLALAR | G61: 0.16 | H61: =VLOOKUP(F61,$B$61:$D$70,3,0) -> 0.16015625 | I61: =G61/H61 -> 0.99902439
...

Sheet PPT Pviots
A1: Consider | B1: Yes
I2: Age-Gender & 21 AeFactor | J2: 2021 Ae and Caste
A3: Row Labels | B3: Count | C3: Raw % | D3: Gender | E3: Age | F3: Age & Gender | G3: 2021 Ae | H3: Caste | I3: Multi Facto | J3: Sum of Multi Factor 2
A4: DMK | B4: 397 | C4: 0.38769531 | D4: 0.38711656 | E4: 0.38430942 | F4: 0.38530576 | G4: 0.31609844 | H4: 0.38892515 | I4: 0.31513381 | J4: 0.31352695 | K4: 0.32
A5: AIADMK | B5: 322 | C5: 0.31445312 | D5: 0.3135944 | E5: 0.31225091 | F5: 0.30939746 | G5: 0.35875957 | H5: 0.31526818 | I5: 0.35131283 | J5: 0.36392135 | K5: 0.35 | L5: -0.1
A6: TVK | B6: 229 | C6: 0.22363281 | D6: 0.22500812 | E6: 0.22820289 | F6: 0.23039608 | G6: 0.24576401 | H6: 0.22248309 | I6: 0.25294319 | J6: 0.24483304 | K6: 0.25 | L6: 0.15
A7: NTK | B7: 8 | C7: 0.0078125 | D7: 0.0079162128 | E7: 0.008439012 | F7: 0.0083761205 | G7: 0.0094718301 | H7: 0.0080718796 | I7: 0.010093741 | J7: 0.0093043308
A8: DMDK | B8: 13 | C8: 0.012695312 | D8: 0.012677025 | E8: 0.012873673 | F8: 0.01276921 | G8: 0.014354643 | H8: 0.013673207 | I8: 0.014356512 | J8: 0.015481501
A9: INC | B9: 9 | C9: 0.0087890625 | D9: 0.0084991304 | E9: 0.0085327905 | F9: 0.0075574577 | G9: 0.0070374503 | H9: 0.0088708703 | I9: 0.006170131 | J9: 0.0065150576
A10: BJP | B10: 7 | C10: 0.0068359375 | D10: 0.0070695488 | E10: 0.0072762188 | F10: 0.007262884 | G10: 0.0074452002 | H10: 0.0058681178 | I10: 0.0079117285 | J10: 0.0063360757
A11: CPM | B11: 4 | C11: 0.00390625 | D11: 0.0040899796 | E11: 0.0034364261 | F11: 0.0038461538 | G11: 0.0028781282 | H11: 0.003902439 | I11: 0.0028247002 | J11: 0.0028309926
A12: Others | B12: 35 | C12: 0.034179688 | D12: 0.034029012 | E12: 0.034678664 | F12: 0.035088874 | G12: 0.038190733 | H12: 0.032937071 | I12: 0.039253359 | J12: 0.037250705
A13: Grand Total | B13: 1024 | C13: 1 | D13: 1 | E13: 1 | F13: 1 | G13: 1 | H13: 1 | I13: 1 | J13: 1
A17: Consider | B17: Yes
A19: 2021 Ae | B19: Column Labels
A20: Row Labels | B20: DMK | C20: AIADMK | D20: TVK | E20: NTK | F20: DMDK | G20: INC | H20: BJP | I20: CPM | J20: Others | K20: Grand Total
A21: ஆண்/Male | B21: 0.32010819 | C21: 0.38696825 | D21: 0.21584999 | E21: 0.005571737 | F21: 0.01300072 | G21: 0.010947361 | H21: 0.0018572457 | I21: 0 | J21: 0.045696504 | K21: 1
A22: பெண்/Female | B22: 0.31165214 | C22: 0.32747983 | D22: 0.27893475 | E22: 0.013796523 | F22: 0.015855966 | G22: 0.0027018704 | H22: 0.013641511 | I22: 0.0060695961 | J22: 0.029867814 | K22: 1
A23: Grand Total | B23: 0.31609844 | C23: 0.35875957 | D23: 0.24576401 | E23: 0.0094718301 | F23: 0.014354643 | G23: 0.0070374503 | H23: 0.0074452002 | I23: 0.0028781282 | J23: 0.038190733 | K23: 1
C24: 34-35
B25: TVK Differnce female to male | D25: =D22-D21 -> 0.063084766
A26: Consider | B26: Yes
A28: 2021 Ae | B28: Column Labels
A29: Row Labels | B29: DMK | C29: AIADMK | D29: TVK | E29: NTK | F29: DMDK | G29: INC | H29: BJP | I29: CPM | J29: Others | K29: Grand Total
A30: 18-30 | B30: 0.30680541 | C30: 0.25755913 | D30: 0.39044867 | E30: 0.0068972833 | F30: 0 | G30: 0 | H30: 0 | I30: 0 | J30: 0.038289509 | K30: 1
A31: 31-45 | B31: 0.25378067 | C31: 0.33278653 | D31: 0.30785358 | E31: 0.021125923 | F31: 0.015319065 | G31: 0.003349622 | H31: 0.016911954 | I31: 0 | J31: 0.048872661 | K31: 1
A32: 46-60 | B32: 0.34474073 | C32: 0.45452574 | D32: 0.12789126 | E32: 0 | F32: 0.020311051 | G32: 0.010503453 | H32: 0.0035638713 | I32: 0.010503453 | J32: 0.027960437 | K32: 1
A33: 60+ | B33: 0.44209822 | C33: 0.38773805 | D33: 0.10019139 | E33: 0 | F33: 0.020666137 | G33: 0.020302436 | H33: 0 | I33: 0 | J33: 0.029003771 | K33: 1
A34: Grand Total | B34: 0.31609844 | C34: 0.35875957 | D34: 0.24576401 | E34: 0.0094718301 | F34: 0.014354643 | G34: 0.0070374503 | H34: 0.0074452002 | I34: 0.0028781282 | J34: 0.038190733 | K34: 1
A37: Consider | B37: Yes
A39: 2021 Ae | B39: Column Labels
A40: Row Labels | B40: DMK | C40: AIADMK | D40: TVK | E40: NTK | F40: DMDK | G40: INC | H40: BJP | I40: CPM | J40: Others | K40: Grand Total
A41: ஆண்/Male | B41: 0.32010819 | C41: 0.38696825 | D41: 0.21584999 | E41: 0.005571737 | F41: 0.01300072 | G41: 0.010947361 | H41: 0.0018572457 | I41: 0 | J41: 0.045696504 | K41: 1
A42: 18-30 | B42: 0.2887643 | C42: 0.27893334 | D42: 0.36633345 | E42: 0 | F42: 0 | G42: 0 | H42: 0 | I42: 0 | J42: 0.065968902 | K42: 1
A43: 31-45 | B43: 0.2925065 | C43: 0.30041927 | D43: 0.32308379 | E43: 0.015147075 | F43: 0.0201961 | G43: 0 | H43: 0 | I43: 0 | J43: 0.048647263 | K43: 1
A44: 46-60 | B44: 0.33660535 | C44: 0.52716569 | D44: 0.0655171 | E44: 0 | F44: 0 | G44: 0.01884982 | H44: 0.0063958328 | I44: 0 | J44: 0.045466203 | K44: 1
A45: 60+ | B45: 0.38887062 | C45: 0.45360527 | D45: 0.072260763 | E45: 0 | F45: 0.034697546 | G45: 0.034086907 | H45: 0 | I45: 0 | J45: 0.016478888 | K45: 1
A46: பெண்/Female | B46: 0.31165214 | C46: 0.32747983 | D46: 0.27893475 | E46: 0.013796523 | F46: 0.015855966 | G46: 0.0027018704 | H46: 0.013641511 | I46: 0.0060695961 | J46: 0.029867814 | K46: 1
A47: 18-30 | B47: 0.32295133 | C47: 0.23843024 | D47: 0.41203062 | E47: 0.013070017 | F47: 0 | G47: 0 | H47: 0 | I47: 0 | J47: 0.013517795 | K47: 1
A48: 31-45 | B48: 0.2141653 | C48: 0.36589727 | D48: 0.29227353 | E48: 0.027242106 | F48: 0.010330003 | G48: 0.0067761852 | H48: 0.034212377 | I48: 0 | J48: 0.049103236 | K48: 1
...

Sheet Location and Caste
B1: Caste | C1: Required | D1: Collected | E1: Pending | F1: Collected % | K1: Date | L1: (All) | Q1: Consider | R1: All
A2: VIRALIMALAI | B2: MUTTARAIYAR | C2: 280 | D2: =VLOOKUP(B2,$K$5:$L$15,2,0) -> 232 | E2: =C2-D2 -> 48 | F2: =D2/C2 -> 0.82857143 | K2: Surveyor Vendor Name | L2: (All) | Q2: Date | R2: All
A3: VIRALIMALAI | B3: DEVENDRA KULA VELLALAR | C3: 160 | D3: =VLOOKUP(B3,$K$5:$L$15,2,0) -> 164 | E3: =C3-D3 -> -4 | F3: =D3/C3 -> 1.025 | K3: Surveyor Name | L3: (All)
A4: VIRALIMALAI | B4: MUKKULATHOR | C4: 129 | D4: =VLOOKUP(B4,$K$5:$L$15,2,0) -> 98 | E4: =C4-D4 -> 31 | F4: =D4/C4 -> 0.75968992 | K4: Consider | L4: Yes | Q4: Row Labels | R4: Distinct Count of Surveyor Name | S4: Count of Sample ID
A5: VIRALIMALAI | B5: PALLAR SC | C5: 100 | D5: =VLOOKUP(B5,$K$5:$L$15,2,0) -> 80 | E5: =C5-D5 -> 20 | F5: =D5/C5 -> 0.8 | Q5: Subramanian | R5: 7 | S5: 1107
A6: VIRALIMALAI | B6: CHOLIA VELLALAR | C6: 100 | D6: =VLOOKUP(B6,$K$5:$L$15,2,0) -> 96 | E6: =C6-D6 -> 4 | F6: =D6/C6 -> 0.96 | K6: Row Labels | L6: Count of Sample ID | Q6: Grand Total | R6: 7 | S6: 1107
A7: VIRALIMALAI | B7: URALI GOUNDER | C7: 90 | D7: =VLOOKUP(B7,$K$5:$L$15,2,0) -> 87 | E7: =C7-D7 -> 3 | F7: =D7/C7 -> 0.96666667 | K7: CHOLIA VELLALAR | L7: 96
A8: VIRALIMALAI | B8: MUSLIM | C8: 81 | D8: =VLOOKUP(B8,$K$5:$L$15,2,0) -> 81 | E8: =C8-D8 -> 0 | F8: =D8/C8 -> 1 | K8: CHRISTIAN | L8: 44
A9: VIRALIMALAI | B9: CHRISTIAN | C9: 40 | D9: =VLOOKUP(B9,$K$5:$L$15,2,0) -> 44 | E9: =C9-D9 -> -4 | F9: =D9/C9 -> 1.1 | K9: DEVENDRA KULA VELLALAR | L9: 164
A10: VIRALIMALAI | B10: OTHERS | C10: 20 | D10: =VLOOKUP(B10,$K$5:$L$15,2,0) -> 142 | E10: =C10-D10 -> -122 | F10: =D10/C10 -> 7.1 | K10: MUKKULATHOR | L10: 98
B11: Total | C11: 1000 | D11: =SUM(D2:D10) -> 1024 | E11: =C11-D11 -> -24 | F11: =D11/C11 -> 1.024 | K11: MUSLIM | L11: 81
A12: AC NAME | B12: TALUKA/BLOCK | C12: LOCALITY | D12: Required | E12: Collected | F12: Pending | K12: MUTTARAIYAR | L12: 232 | N12: Block | O12: Required | P12: Collected | Q12: Pedning | R12: Collected %
A13: VIRALIMALAI | B13: ILLUPUR | C13: METTUPATTI | D13: 40 | E13: =IFERROR(VLOOKUP(C13,$K$23:$L$46,2,0),0) -> 0 | F13: =D13-E13 -> 40 | K13: Others | L13: 142 | N13: ILLUPUR | O13: 571 | P13: 172 | Q13: =O13-P13 -> 399 | R13: =P13/O13 -> 0.30122592
A14: VIRALIMALAI | B14: ILLUPUR | C14: ELUVAMPATTI | D14: 40 | E14: =IFERROR(VLOOKUP(C14,$K$23:$L$46,2,0),0) -> 0 | F14: =D14-E14 -> 40 | K14: PALLAR SC | L14: 80 | N14: VIRALIMALAI | O14: 332 | P14: 224 | Q14: =O14-P14 -> 108 | R14: =P14/O14 -> 0.6746988
A15: VIRALIMALAI | B15: ILLUPUR | C15: MANGUDI | D15: 40 | E15: =IFERROR(VLOOKUP(C15,$K$23:$L$46,2,0),0) -> 86 | F15: =D15-E15 -> -46 | K15: URALI GOUNDER | L15: 87 | N15: KULATHUR | O15: 97 | P15: 24 | Q15: =O15-P15 -> 73 | R15: =P15/O15 -> 0.24742268
A16: VIRALIMALAI | B16: ILLUPUR | C16: KULATHUR | D16: 40 | E16: =IFERROR(VLOOKUP(C16,$K$23:$L$46,2,0),0) -> 0 | F16: =D16-E16 -> 40 | K16: Grand Total | L16: 1024
A17: VIRALIMALAI | B17: ILLUPUR | C17: MALAIKUDIPATTI | D17: 40 | E17: =IFERROR(VLOOKUP(C17,$K$23:$L$46,2,0),0) -> 0 | F17: =D17-E17 -> 40 | K17: Date | L17: (All)
A18: VIRALIMALAI | B18: ILLUPUR | C18: AGARAPATTI | D18: 40 | E18: =IFERROR(VLOOKUP(C18,$K$23:$L$46,2,0),0) -> 0 | F18: =D18-E18 -> 40 | K18: Surveyor Vendor Name | L18: (All)
A19: VIRALIMALAI | B19: ILLUPUR | C19: MEENAVELI | D19: 40 | E19: =IFERROR(VLOOKUP(C19,$K$23:$L$46,2,0),0) -> 0 | F19: =D19-E19 -> 40 | K19: Surveyor Name | L19: (All)
A20: VIRALIMALAI | B20: ILLUPUR | C20: ILLUPUR | D20: 40 | E20: =IFERROR(VLOOKUP(C20,$K$23:$L$46,2,0),0) -> 0 | F20: =D20-E20 -> 40 | K20: Consider | L20: Yes | R20: Consider | S20: Yes
A21: VIRALIMALAI | B21: ILLUPUR | C21: ANNAVASAL | D21: 40 | E21: =IFERROR(VLOOKUP(C21,$K$23:$L$46,2,0),0) -> 142 | F21: =D21-E21 -> -102
A22: VIRALIMALAI | B22: ILLUPUR | C22: MUKKANNAMALAIPATTI | D22: 40 | E22: =IFERROR(VLOOKUP(C22,$K$23:$L$46,2,0),0) -> 58 | F22: =D22-E22 -> -18 | K22: Row Labels | L22: Count of Sample ID | R22: Row Labels | S22: Count of Sample ID
A23: VIRALIMALAI | B23: ILLUPUR | C23: VEERAPATTI | D23: 40 | E23: =IFERROR(VLOOKUP(C23,$K$23:$L$46,2,0),0) -> 0 | F23: =D23-E23 -> 40 | K23: ANNAVASAL | L23: 142 | R23: ஆண்/Male | S23: 0.52246094
A24: VIRALIMALAI | B24: ILLUPUR | C24: KILIKUDI | D24: 40 | E24: =IFERROR(VLOOKUP(C24,$K$23:$L$46,2,0),0) -> 62 | F24: =D24-E24 -> -22 | K24: KILIKUDI | L24: 62 | R24: பெண்/Female | S24: 0.47753906
A25: VIRALIMALAI | B25: ILLUPUR | C25: PARAMBUR | D25: 40 | E25: =IFERROR(VLOOKUP(C25,$K$23:$L$46,2,0),0) -> 71 | F25: =D25-E25 -> -31 | K25: KUDUMIYANMALAI | L25: 91 | R25: Grand Total | S25: 1
A26: VIRALIMALAI | B26: ILLUPUR | C26: KUDUMIYANMALAI | D26: 40 | E26: =IFERROR(VLOOKUP(C26,$K$23:$L$46,2,0),0) -> 91 | F26: =D26-E26 -> -51 | K26: MANGUDI | L26: 86
A27: VIRALIMALAI | B27: VIRALIMALAI | C27: KALKUDI | D27: 40 | E27: =IFERROR(VLOOKUP(C27,$K$23:$L$46,2,0),0) -> 0 | F27: =D27-E27 -> 40 | K27: MUKKANNAMALAIPATTI | L27: 58
A28: VIRALIMALAI | B28: VIRALIMALAI | C28: VELUR | D28: 40 | E28: =IFERROR(VLOOKUP(C28,$K$23:$L$46,2,0),0) -> 0 | F28: =D28-E28 -> 40 | K28: PARAMBUR | L28: 71 | R28: Consider | S28: Yes
A29: VIRALIMALAI | B29: VIRALIMALAI | C29: VIRALIMALAI | D29: 40 | E29: =IFERROR(VLOOKUP(C29,$K$23:$L$46,2,0),0) -> 444 | F29: =D29-E29 -> -404 | K29: VIRALIMALAI | L29: 444
A30: VIRALIMALAI | B30: VIRALIMALAI | C30: ATHIPALLAM | D30: 40 | E30: =IFERROR(VLOOKUP(C30,$K$23:$L$46,2,0),0) -> 0 | F30: =D30-E30 -> 40 | K30: RAJALIPATTI | L30: 40 | R30: Row Labels | S30: Count of Sample ID
A31: VIRALIMALAI | B31: VIRALIMALAI | C31: NAMBANPATTI | D31: 40 | E31: =IFERROR(VLOOKUP(C31,$K$23:$L$46,2,0),0) -> 0 | F31: =D31-E31 -> 40 | K31: MATHUR | L31: 30 | R31: 18-30 | S31: 0.20507812
A32: VIRALIMALAI | B32: VIRALIMALAI | C32: RAJALIPATTI | D32: 40 | E32: =IFERROR(VLOOKUP(C32,$K$23:$L$46,2,0),0) -> 40 | F32: =D32-E32 -> 0 | K32: Grand Total | L32: 1024 | R32: 31-45 | S32: 0.36523438
A33: VIRALIMALAI | B33: VIRALIMALAI | C33: KODUMBALUR | D33: 40 | E33: =IFERROR(VLOOKUP(C33,$K$23:$L$46,2,0),0) -> 0 | F33: =D33-E33 -> 40 | R33: 46-60 | S33: 0.28417969
A34: VIRALIMALAI | B34: VIRALIMALAI | C34: RAJAGIRI | D34: 40 | E34: =IFERROR(VLOOKUP(C34,$K$23:$L$46,2,0),0) -> 0 | F34: =D34-E34 -> 40 | R34: 60+ | S34: 0.14550781
A35: VIRALIMALAI | B35: KULATHUR | C35: KUMARAMANGALAM | D35: 40 | E35: =IFERROR(VLOOKUP(C35,$K$23:$L$46,2,0),0) -> 0 | F35: =D35-E35 -> 40 | R35: Grand Total | S35: 1
A36: VIRALIMALAI | B36: KULATHUR | C36: MATHUR | D36: 40 | E36: =IFERROR(VLOOKUP(C36,$K$23:$L$46,2,0),0) -> 30 | F36: =D36-E36 -> 10
A37: VIRALIMALAI | B37: KULATHUR | C37: MANDAIYUR | D37: 40 | E37: =IFERROR(VLOOKUP(C37,$K$23:$L$46,2,0),0) -> 0 | F37: =D37-E37 -> 40
D38: =SUM(D13:D37) -> 1000 | E38: =SUM(E13:E37) -> 1024 | F38: =SUM(F13:F37) -> -24 | R38: Consider | S38: Yes
R39: Rev Caste | S39: Others
R41: Row Labels | S41: Count of Sample ID
...

Sheet Data
A1: Sample ID | B1: Timestamp | C1: Date | D1: Location | E1: Address | F1: Audio Url | G1: Audio Duration (in secs) | H1: Offline Mode | I1: Surveyor Name | J1: Surveyor Phone Number | K1: Surveyor Vendor Name | L1: TALUKA/BLOCK | M1: LOCALITY | N1: பதிலளிப்பவர் பெயர்/Respondent Name | O1: பாலினம்/Gender | P1: பதிலளித்தவரின் மொபைல் எண்/Mobile Number | Q1: பதிலளித்தவரின் வயது/Age Group | R1: தொழில்/Occupation | S1: மாத வருமானம்/Monthly Income | T1: தமிழக முதல்வர் மு.க. ஸ்டாலின் தலைமையிலான தற்போதைய திமுக அரசின் செயல்திறனை நீங்கள் எப்படி மதிப்பீடு செய்கிறீர்கள்?/ How would you rate the performance of the current DMK-led government under Chief Minister M.K. Stalin? | U1: 2026 சட்டமன்றத் தேர்தலில் ஆட்சி மாற்றம் தேவை என நீங்கள் கருதுகிறீர்களா?/ Do you feel a change in government is needed in the 2026 assembly Elections? | V1: 2021 சட்டமன்றத் தேர்தலில் நீங்கள் எந்தக் கட்சிக்கு வாக்களித்தீர்கள்?/ Which party did you vote in 2021 Assembly Elections? | W1: தமிழகத்தின் அடுத்த முதல்வராக யாருக்கு நீங்கள் ஆதரவு அளிக்க விரும்புகிறீர்கள்?/ Who would you support as Tamil Nadu’s next Chief Minister? | X1: உங்கள் தொகுதியில் வெற்றி பெற வாய்ப்புள்ள கட்சி/கூட்டணி எது என நீங்கள் கருதுகிறீர்கள்?/ Which party/alliance do you think will win in your constituency? | Y1: Rev Party | Z1: நீங்கள் விரும்பும் கட்சி (வினா 13 இல் தெரிவுசெய்தது) தமிழக வெற்றி கழகத்துடன் கூட்டணி அமைத்தால், நீங்கள் அந்த கூட்டணிக்கு வாக்களிக்கிறீர்களா? (இந்த வினா AIADMK, NTK, PMK, DMDK, அல்லது INC-ஐ தேர்ந்தெடுத்தவர்களுக்கே लागू) / If your preferred party (in quest | AA1: விஜயின் அரசியல் வருகை 2026 தேர்தலில் குறிப்பிடத்தக்க தாக்கத்தை ஏற்படுத்தும் என நீங்கள் நம்புகிறீர்களா?/ Do you believe Vijay’s political entry will significantly impact the 2026 elections? | AB1: உங்கள் பதில் "ஆமாம்" எனில், விஜயின் அரசியல் வருகையால் அதிகம் பாதிக்கப்படக்கூடிய கட்சி/கூட்டணி எது? / If yes, which party/alliance will be most affected by Vijay’s entry? | AC1: தமிழக வெற்றி கழகம் (TVK) தற்போது எப்படி செயல்படுகிறது என நீங்கள் மதிப்பீடு செய்கிறீர்கள்? / How would you rate Tamilaga Vettri Kazhagam’s (TVK) current performance? | AD1: சமூக பிரச்சனைகளைத் தீர்க்கும் முயற்சிகளில் விஜய் எவ்வளவு பயனுள்ளதாக இருந்துள்ளார்?/ How effective has Vijay been in addressing social issues? | AE1: திமுக அல்லது அதிமுக கூட்டணிகள் 2026க்கு முந்தைய காலத்தில் உடைந்துவிடும் என நீங்கள் கருதுகிறீர்களா? / Do you foresee the DMK or AIADMK alliances breaking apart before 2026? | AF1: எந்தக் கூட்டணியில் விஜயின் கட்சி (TVK) சேரவேண்டும் என நீங்கள் விரும்புகிறீர்கள்?/ Which alliance would you prefer Vijay’s party (TVK) to join, if any? | AG1: தற்போதைய தமிழகத்தில் மிக முக்கியமான பிரச்சனை எது என நீங்கள் கருதுகிறீர்கள்?/ What is the most critical issue facing Tamil Nadu today? | AH1: சாதி வகை/Caste Category | AI1: சாதி/Caste | AJ1: QC Comment | AK1: QC Remark | AL1: QC User Name | AM1: QC Date | AN1: App Version | AO1: Consider | AP1: Time | AQ1: Rev Caste | AR1: Gender Factor | AS1: Age Factor | AT1: Age & Gender Factor | AU1: 2021 Ae Factor | AV1: Caste Factor | AW1: Multi Factor | AX1: Multi Factor 2 | AY1: Long
A2: wCoRngjNmpdXwr8jpUtS | B2: 2025-07-30 11:50:28.774519 | C2: 45868 | D2: (10.4599207, 78.7030535) | E2: 55,,Annavasal,622101,Tamil Nadu,India. | F2: https://firebasestorage.googleapis.com/v0/b/mindbrink-survey-production.appspot.com/o/audioFiles%2FAtznECuQc6klLPsRR6u2%2FnV4IA56gMWWp4NfG0H1PGfyqfM92%2F2025-07-30%2011%3A50%3A15.491639.m4a?alt=media&token=23fd1b60-6ea5-4086-a9e0-12b2896623eb | G2: 474 | H2: false | I2: G.muthukumar | J2: +918940041476 | K2: Subramanian | L2: VIRALIMALAI | M2: ATHIPALLAM | N2: sinnathuri | O2: ஆண்/Male | P2: 9486664057 | Q2: 31-45 | R2: கூலி தொழில்/ Daily Wage | S2: 10,000 - 25,000 | T2: திருப்திகரமானது / Satisfactory | U2: இல்லை/ No | V2: திமுக கூட்டணி / DMK Alliance | W2: மு.க. ஸ்டாலின் (திமுக) / M.K. Stalin (DMK) | X2: திமுக / DMK | Y2: DMK | Z2: - | AA2: இல்லை / No | AB2: - | AC2: திருப்திகரமல்ல / Unsatisfactory | AD2: குறைவான ஈடுபாடு / Inadequate | AE2: • இல்லை: திமுக மற்றும் அதிமுக கூட்டணிகள் இரண்டும் உடையாது/ No: Both DMK & AIADMK alliances will not break up | AF2: தனித்துப் போட்டியிட வேண்டும் / Contest Independently | AG2: மதுபானம் / போதைப்பொருள் பழக்கம்/ Alcohol/Drug abuse | AH2: OBC | AI2: URALI GOUNDER | AJ2: =IFERROR(_xlfn.XLOOKUP(Table1[[#This Row],[Audio Url]],Qc!C:C,Qc!F:F),"") -> speaking among themselves | AK2: =IFERROR(_xlfn.XLOOKUP(Table1[[#This Row],[Audio Url]],Qc!C:C,Qc!E:E),"") -> Fake Audio/Empty Audio | AL2: - | AM2: - | AN2: =VLOOKUP(Table1[[#This Row],[LOCALITY]],Sheet2!$F:$H,3,0) -> Rural | AO2: No | AP2: =IF(Table1[[#This Row],[Audio Duration (in secs)]]>180,"Greater than 3 Minutes","Less than 3 Minutes") -> Greater than 3 Minutes | AQ2: =IFERROR(VLOOKUP(Table1[[#This Row],[சாதி/Caste]],MApping!$E$1:$F$10,2,0),"Others") -> URALI GOUNDER | AR2: =VLOOKUP(Table1[[#This Row],[பாலினம்/Gender]],Factor!$F$26:$I$28,4,0) -> 0.95700935 | AS2: =VLOOKUP(Table1[[#This Row],[பதிலளித்தவரின் வயது/Age Group]],Factor!$F$35:$I$39,4,0) -> 1.0951872 | AT2: =VLOOKUP(Table1[[#This Row],[பதிலளித்தவரின் வயது/Age Group]]&Table1[[#This Row],[பாலினம்/Gender]],Factor!$A$45:$G$53,7,0) -> 1.0835979 | AU2: =VLOOKUP(Table1[[#This Row],[2021 சட்டமன்றத் தேர்தலில் நீங்கள் எந்தக் கட்சிக்கு வாக்களித்தீர்கள்?/ Which party did you vote in 2021 Assembly Elections? ]],Factor!$F$9:$J$14,5,0) -> 0.73680082 | AV2: =VLOOKUP(Table1[[#This Row],[Rev Caste]],Factor!$F$59:$I$68,4,0) -> 1.0593103 | AW2: =Table1[[#This Row],[2021 Ae Factor]]*Table1[[#This Row],[Age & Gender Factor]] -> 0.79839581 | AX2: =Table1[[#This Row],[2021 Ae Factor]]*Table1[[#This Row],[Caste Factor]] -> 0.78050074 | AY2: =VALUE(MID(D2, FIND(",",D2)+2, FIND(")",D2)-FIND(",",D2)-2)) -> 78.703053
A3: DK5RFIfUeSBZOmSRQwlG | B3: 2025-07-30 13:47:12.018718 | C3: 45868 | D3: (10.4596218, 78.7023729) | E3: FP52+XV3,,Annavasal,622101,Tamil Nadu,India. | F3: https://firebasestorage.googleapis.com/v0/b/mindbrink-survey-production.appspot.com/o/audioFiles%2FAtznECuQc6klLPsRR6u2%2Fe5risFoEPidDckOLperfsZqxzae2%2F2025-07-30%2013%3A47%3A06.589839.m4a?alt=media&token=491fc27d-ed7b-4fbf-88ba-a7af8002c801 | G3: 675 | H3: false | I3: Sinthanai selvi | J3: +918508766594 | K3: Subramanian | L3: ILLUPUR | M3: ANNAVASAL | N3: raja | O3: ஆண்/Male | P3: 8675641312 | Q3: 18-30 | R3: மாணவர்/ Student | S3: 10,000 - 25,000 | T3: திருப்திகரமானது / Satisfactory | U3: ஆம் / Yes | V3: திமுக கூட்டணி / DMK Alliance | W3: மு.க. ஸ்டாலின் (திமுக) / M.K. Stalin (DMK) | X3: திமுக / DMK | Y3: Others | Z3: - | AA3: இல்லை / No | AB3: - | AC3: வேகம் குறைபாடுடன் செயல்படுகிறது / Needs more momentum | AD3: பயனில்லை / Not effective | AE3: • ஆமாம்: அதிமுக கூட்டணி உடையும்/ Yes: AIADMK alliance will break up | AF3: நாம் தமிழர் கட்சி / NTK | AG3: மதுபானம் / போதைப்பொருள் பழக்கம்/ Alcohol/Drug abuse | AH3: BC | AI3: MUKKULATHOR | AJ3: =IFERROR(_xlfn.XLOOKUP(Table1[[#This Row],[Audio Url]],Qc!C:C,Qc!F:F),"") -> they only speaking amkn6them but questions are only read | AK3: =IFERROR(_xlfn.XLOOKUP(Table1[[#This Row],[Audio Url]],Qc!C:C,Qc!E:E),"") -> Not Doing It Properly | AL3: - | AM3: - | AN3: =VLOOKUP(Table1[[#This Row],[LOCALITY]],Sheet2!$F:$H,3,0) -> Urban | AO3: Yes | AP3: =IF(Table1[[#This Row],[Audio Duration (in secs)]]>180,"Greater than 3 Minutes","Less than 3 Minutes") -> Greater than 3 Minutes | AQ3: =IFERROR(VLOOKUP(Table1[[#This Row],[சாதி/Caste]],MApping!$E$1:$F$10,2,0),"Others") -> MUKKULATHOR | AR3: =VLOOKUP(Table1[[#This Row],[பாலினம்/Gender]],Factor!$F$26:$I$28,4,0) -> 0.95700935 | AS3: =VLOOKUP(Table1[[#This Row],[பதிலளித்தவரின் வயது/Age Group]],Factor!$F$35:$I$39,4,0) -> 0.9752381 | AT3: =VLOOKUP(Table1[[#This Row],[பதிலளித்தவரின் வயது/Age Group]]&Table1[[#This Row],[பாலினம்/Gender]],Factor!$A$45:$G$53,7,0) -> 1.0666667 | AU3: =VLOOKUP(Table1[[#This Row],[2021 சட்டமன்றத் தேர்தலில் நீங்கள் எந்தக் கட்சிக்கு வாக்களித்தீர்கள்?/ Which party did you vote in 2021 Assembly Elections? ]],Factor!$F$9:$J$14,5,0) -> 0.73680082 | AV3: =VLOOKUP(Table1[[#This Row],[Rev Caste]],Factor!$F$59:$I$68,4,0) -> 1.3479184 | AW3: =Table1[[#This Row],[2021 Ae Factor]]*Table1[[#This Row],[Age & Gender Factor]] -> 0.78592088 | AX3: =Table1[[#This Row],[2021 Ae Factor]]*Table1[[#This Row],[Caste Factor]] -> 0.99314736 | AY3: =VALUE(MID(D3, FIND(",",D3)+2, FIND(")",D3)-FIND(",",D3)-2)) -> 78.702373
A4: RdafTkFtqCYc1Xw504xM | B4: 2025-07-30 14:00:49.781847 | C4: 45868 | D4: (10.4595158, 78.7023314) | E4: FP53+P33,,Purakarai Natham Pannai,622005,Tamil Nadu,India. | F4: https://firebasestorage.googleapis.com/v0/b/mindbrink-survey-production.appspot.com/o/audioFiles%2FAtznECuQc6klLPsRR6u2%2Fe5risFoEPidDckOLperfsZqxzae2%2F2025-07-30%2014%3A00%3A45.291038.m4a?alt=media&token=cecc8db3-cd5a-48ee-a3e6-d691de1219b0 | G4: 427 | H4: false | I4: Sinthanai selvi | J4: +918508766594 | K4: Subramanian | L4: ILLUPUR | M4: ANNAVASAL | N4: முருகேசன் | O4: ஆண்/Male | P4: 8012825692 | Q4: 46-60 | R4: சொந்த தொழில் / சுயதொழில் செய்பவர்/ Self Employed/Business | S4: 50,000 - 1,00,000 | T4: திருப்திகரமல்ல/ Unsatisfactory | U4: ஆம் / Yes | V4: அதிமுக கூட்டணி / AIADMK Alliance | W4: எடப்பாடி பழனிசாமி (அதிமுக) / Edappadi K. Palaniswami (AIADMK) | X4: அதிமுக / AIADMK | Y4: AIADMK | Z4: ஆம், TVK கூட்டணிக்கு வாக்களிப்பேன் / Yes, I will shift my vote to the TVK alliance | AA4: இல்லை / No | AB4: - | AC4: திருப்திகரமல்ல / Unsatisfactory | AD4: பயனில்லை / Not effective | AE4: • ஆமாம்: திமுக கூட்டணி உடையும் / Yes: DMK Alliance will break up | AF4: அதிமுக / AIADMK | AG4: விவசாய நெருக்கடி / Agricultural crisis | AH4: BC | AI4: - | AJ4: =IFERROR(_xlfn.XLOOKUP(Table1[[#This Row],[Audio Url]],Qc!C:C,Qc!F:F),"") -> same voice | AK4: =IFERROR(_xlfn.XLOOKUP(Table1[[#This Row],[Audio Url]],Qc!C:C,Qc!E:E),"") -> Taking From Friends And Family | AL4: - | AM4: - | AN4: =VLOOKUP(Table1[[#This Row],[LOCALITY]],Sheet2!$F:$H,3,0) -> Urban | AO4: No | AP4: =IF(Table1[[#This Row],[Audio Duration (in secs)]]>180,"Greater than 3 Minutes","Less than 3 Minutes") -> Greater than 3 Minutes | AQ4: =IFERROR(VLOOKUP(Table1[[#This Row],[சாதி/Caste]],MApping!$E$1:$F$10,2,0),"Others") -> Others | AR4: =VLOOKUP(Table1[[#This Row],[பாலினம்/Gender]],Factor!$F$26:$I$28,4,0) -> 0.95700935 | AS4: =VLOOKUP(Table1[[#This Row],[பதிலளித்தவரின் வயது/Age Group]],Factor!$F$35:$I$39,4,0) -> 0.87972509 | AT4: =VLOOKUP(Table1[[#This Row],[பதிலளித்தவரின் வயது/Age Group]]&Table1[[#This Row],[பாலினம்/Gender]],Factor!$A$45:$G$53,7,0) -> 0.79503106 | AU4: =VLOOKUP(Table1[[#This Row],[2021 சட்டமன்றத் தேர்தலில் நீங்கள் எந்தக் கட்சிக்கு வாக்களித்தீர்கள்?/ Which party did you vote in 2021 Assembly Elections? ]],Factor!$F$9:$J$14,5,0) -> 1.3119425 | AV4: =VLOOKUP(Table1[[#This Row],[Rev Caste]],Factor!$F$59:$I$68,4,0) -> 0.14422535 | AW4: =Table1[[#This Row],[2021 Ae Factor]]*Table1[[#This Row],[Age & Gender Factor]] -> 1.0430351 | AX4: =Table1[[#This Row],[2021 Ae Factor]]*Table1[[#This Row],[Caste Factor]] -> 0.18921537 | AY4: =VALUE(MID(D4, FIND(",",D4)+2, FIND(")",D4)-FIND(",",D4)-2)) -> 78.702331
A5: jXAWjqyIxq87qPMieuPS | B5: 2025-07-30 14:19:29.593894 | C5: 45868 | D5: (10.4623883, 78.6815105) | E5: FM6J+JHW,,Pudukkottai,622103,Tamil Nadu,India. | F5: https://firebasestorage.googleapis.com/v0/b/mindbrink-survey-production.appspot.com/o/audioFiles%2FAtznECuQc6klLPsRR6u2%2F2ukCmICpvKWhqTT6dgmjG6nFGjc2%2F2025-07-30%2014%3A19%3A23.528277.m4a?alt=media&token=2a8a1c48-d5a0-40e2-b2c9-f58e1c5cbbb7 | G5: 347 | H5: false | I5: U.Amir nisha | J5: +919698565662 | K5: Subramanian | L5: ILLUPUR | M5: MUKKANNAMALAIPATTI | N5: Rathinam | O5: ஆண்/Male | P5: 8012352247 | Q5: 31-45 | R5: கூலி தொழில்/ Daily Wage | S5: 10,000க்கும் குறைவானது/Less than 10,000 | T5: திருப்திகரமல்ல/ Unsatisfactory | U5: ஆம் / Yes | V5: திமுக கூட்டணி / DMK Alliance | W5: விஜய் (தமிழக வெற்றி கழகம்) / Vijay (TVK) | X5: தமிழக வெற்றி கழகம் / TVK | Y5: TVK | Z5: - | AA5: இல்லை / No | AB5: - | AC5: வேகம் குறைபாடுடன் செயல்படுகிறது / Needs more momentum | AD5: குறைவான ஈடுபாடு / Inadequate | AE5: • ஆமாம்: திமுக மற்றும் அதிமுக கூட்டணிகள் இரண்டும் உடையும்/ Yes: Both DMK & AIADMK alliances will break up | AF5: தனித்துப் போட்டியிட வேண்டும் / Contest Independently | AG5: வேலைவாய்ப்பு குறைபாடு / Unemployment | AH5: SC | AI5: PALLAR SC | AJ5: =IFERROR(_xlfn.XLOOKUP(Table1[[#This Row],[Audio Url]],Qc!C:C,Qc!F:F),"") -> same voice | AK5: =IFERROR(_xlfn.XLOOKUP(Table1[[#This Row],[Audio Url]],Qc!C:C,Qc!E:E),"") -> Taking From Friends And Family | AL5: - | AM5: - | AN5: =VLOOKUP(Table1[[#This Row],[LOCALITY]],Sheet2!$F:$H,3,0) -> Rural | AO5: No | AP5: =IF(Table1[[#This Row],[Audio Duration (in secs)]]>180,"Greater than 3 Minutes","Less than 3 Minutes") -> Greater than 3 Minutes | AQ5: =IFERROR(VLOOKUP(Table1[[#This Row],[சாதி/Caste]],MApping!$E$1:$F$10,2,0),"Others") -> PALLAR SC | AR5: =VLOOKUP(Table1[[#This Row],[பாலினம்/Gender]],Factor!$F$26:$I$28,4,0) -> 0.95700935 | AS5: =VLOOKUP(Table1[[#This Row],[பதிலளித்தவரின் வயது/Age Group]],Factor!$F$35:$I$39,4,0) -> 1.0951872 | AT5: =VLOOKUP(Table1[[#This Row],[பதிலளித்தவரின் வயது/Age Group]]&Table1[[#This Row],[பாலினம்/Gender]],Factor!$A$45:$G$53,7,0) -> 1.0835979 | AU5: =VLOOKUP(Table1[[#This Row],[2021 சட்டமன்றத் தேர்தலில் நீங்கள் எந்தக் கட்சிக்கு வாக்களித்தீர்கள்?/ Which party did you vote in 2021 Assembly Elections? ]],Factor!$F$9:$J$14,5,0) -> 0.73680082 | AV5: =VLOOKUP(Table1[[#This Row],[Rev Caste]],Factor!$F$59:$I$68,4,0) -> 1.28 | AW5: =Table1[[#This Row],[2021 Ae Factor]]*Table1[[#This Row],[Age & Gender Factor]] -> 0.79839581 | AX5: =Table1[[#This Row],[2021 Ae Factor]]*Table1[[#This Row],[Caste Factor]] -> 0.94310506 | AY5: =VALUE(MID(D5, FIND(",",D5)+2, FIND(")",D5)-FIND(",",D5)-2)) -> 78.681511
A6: inwjrr2qGauklkuB5CLS | B6: 2025-07-30 14:26:30.602916 | C6: 45868 | D6: (10.4623704, 78.681544) | E6: FM6J+JHW,,Pudukkottai,622103,Tamil Nadu,India. | F6: https://firebasestorage.googleapis.com/v0/b/mindbrink-survey-production.appspot.com/o/audioFiles%2FAtznECuQc6klLPsRR6u2%2F2ukCmICpvKWhqTT6dgmjG6nFGjc2%2F2025-07-30%2014%3A26%3A24.415606.m4a?alt=media&token=94a2343f-ce0d-4c6c-812f-f12d4d988ffa | G6: 301 | H6: false | I6: U.Amir nisha | J6: +919698565662 | K6: Subramanian | L6: ILLUPUR | M6: MUKKANNAMALAIPATTI | N6: Albert Xavier | O6: ஆண்/Male | P6: 7708200630 | Q6: 31-45 | R6: விவசாயி/ Farmer | S6: 10,000க்கும் குறைவானது/Less than 10,000 | T6: திருப்திகரமல்ல/ Unsatisfactory | U6: ஆம் / Yes | V6: திமுக கூட்டணி / DMK Alliance | W6: விஜய் (தமிழக வெற்றி கழகம்) / Vijay (TVK) | X6: அதிமுக / AIADMK | Y6: TVK | Z6: ஆம், TVK கூட்டணிக்கு வாக்களிப்பேன் / Yes, I will shift my vote to the TVK alliance | AA6: ஆமாம் / Yes | AB6: திமுக கூட்டணி / DMK Alliance | AC6: வேகம் குறைபாடுடன் செயல்படுகிறது / Needs more momentum | AD6: போதுமான ஈடுபாடு / Adequate | AE6: • ஆமாம்: திமுக மற்றும் அதிமுக கூட்டணிகள் இரண்டும் உடையும்/ Yes: Both DMK & AIADMK alliances will break up | AF6: தே.மு.தி.க / DMDK | AG6: விவசாய நெருக்கடி / Agricultural crisis | AH6: BC | AI6: CHRISTIAN | AJ6: =IFERROR(_xlfn.XLOOKUP(Table1[[#This Row],[Audio Url]],Qc!C:C,Qc!F:F),"") -> same voice | AK6: =IFERROR(_xlfn.XLOOKUP(Table1[[#This Row],[Audio Url]],Qc!C:C,Qc!E:E),"") -> Taking From Friends And Family | AL6: - | AM6: - | AN6: =VLOOKUP(Table1[[#This Row],[LOCALITY]],Sheet2!$F:$H,3,0) -> Rural | AO6: No | AP6: =IF(Table1[[#This Row],[Audio Duration (in secs)]]>180,"Greater than 3 Minutes","Less than 3 Minutes") -> Greater than 3 Minutes | AQ6: =IFERROR(VLOOKUP(Table1[[#This Row],[சாதி/Caste]],MApping!$E$1:$F$10,2,0),"Others") -> CHRISTIAN | AR6: =VLOOKUP(Table1[[#This Row],[பாலினம்/Gender]],Factor!$F$26:$I$28,4,0) -> 0.95700935 | AS6: =VLOOKUP(Table1[[#This Row],[பதிலளித்தவரின் வயது/Age Group]],Factor!$F$35:$I$39,4,0) -> 1.0951872 | AT6: =VLOOKUP(Table1[[#This Row],[பதிலளித்தவரின் வயது/Age Group]]&Table1[[#This Row],[பாலினம்/Gender]],Factor!$A$45:$G$53,7,0) -> 1.0835979 | AU6: =VLOOKUP(Table1[[#This Row],[2021 சட்டமன்றத் தேர்தலில் நீங்கள் எந்தக் கட்சிக்கு வாக்களித்தீர்கள்?/ Which party did you vote in 2021 Assembly Elections? ]],Factor!$F$9:$J$14,5,0) -> 0.73680082 | AV6: =VLOOKUP(Table1[[#This Row],[Rev Caste]],Factor!$F$59:$I$68,4,0) -> 0.93090909 | AW6: =Table1[[#This Row],[2021 Ae Factor]]*Table1[[#This Row],[Age & Gender Factor]] -> 0.79839581 | AX6: =Table1[[#This Row],[2021 Ae Factor]]*Table1[[#This Row],[Caste Factor]] -> 0.68589459 | AY6: =VALUE(MID(D6, FIND(",",D6)+2, FIND(")",D6)-FIND(",",D6)-2)) -> 78.681544
A7: oYxHjk6VwK6zG0z9HzLl | B7: 2025-07-30 14:35:10.789469 | C7: 45868 | D7: (10.4623843, 78.6815277) | E7: FM6J+JHW,,Pudukkottai,622103,Tamil Nadu,India. | F7: https://firebasestorage.googleapis.com/v0/b/mindbrink-survey-production.appspot.com/o/audioFiles%2FAtznECuQc6klLPsRR6u2%2F2ukCmICpvKWhqTT6dgmjG6nFGjc2%2F2025-07-30%2014%3A35%3A02.869454.m4a?alt=media&token=66fec1a3-fae7-4769-b641-1ce8faff9d0d | G7: 269 | H7: false | I7: U.Amir nisha | J7: +919698565662 | K7: Subramanian | L7: ILLUPUR | M7: MUKKANNAMALAIPATTI | N7: Jaya | O7: பெண்/Female | P7: 8807414653 | Q7: 31-45 | R7: இல்லத்தரசி/ Housewife | S7: 10,000க்கும் குறைவானது/Less than 10,000 | T7: மேம்பாடு தேவை / Needs improvement | U7: ஆம் / Yes | V7: அதிமுக கூட்டணி / AIADMK Alliance | W7: மு.க. ஸ்டாலின் (திமுக) / M.K. Stalin (DMK) | X7: திமுக / DMK | Y7: DMK | Z7: - | AA7: ஆமாம் / Yes | AB7: பிறவை / Others | AC7: திருப்திகரமானது / Satisfactory | AD7: போதுமான ஈடுபாடு / Adequate | AE7: • ஆமாம்: திமுக கூட்டணி உடையும் / Yes: DMK Alliance will break up | AF7: தனித்துப் போட்டியிட வேண்டும் / Contest Independently | AG7: மதுபானம் / போதைப்பொருள் பழக்கம்/ Alcohol/Drug abuse | AH7: BC | AI7: CHRISTIAN | AJ7: =IFERROR(_xlfn.XLOOKUP(Table1[[#This Row],[Audio Url]],Qc!C:C,Qc!F:F),"") -> 0 | AK7: =IFERROR(_xlfn.XLOOKUP(Table1[[#This Row],[Audio Url]],Qc!C:C,Qc!E:E),"") -> Correctly Done | AL7: - | AM7: - | AN7: =VLOOKUP(Table1[[#This Row],[LOCALITY]],Sheet2!$F:$H,3,0) -> Rural | AO7: Yes | AP7: =IF(Table1[[#This Row],[Audio Duration (in secs)]]>180,"Greater than 3 Minutes","Less than 3 Minutes") -> Greater than 3 Minutes | AQ7: =IFERROR(VLOOKUP(Table1[[#This Row],[சாதி/Caste]],MApping!$E$1:$F$10,2,0),"Others") -> CHRISTIAN | AR7: =VLOOKUP(Table1[[#This Row],[பாலினம்/Gender]],Factor!$F$26:$I$28,4,0) -> 1.0470348 | AS7: =VLOOKUP(Table1[[#This Row],[பதிலளித்தவரின் வயது/Age Group]],Factor!$F$35:$I$39,4,0) -> 1.0951872 | AT7: =VLOOKUP(Table1[[#This Row],[பதிலளித்தவரின் வயது/Age Group]]&Table1[[#This Row],[பாலினம்/Gender]],Factor!$A$45:$G$53,7,0) -> 1.107027 | AU7: =VLOOKUP(Table1[[#This Row],[2021 சட்டமன்றத் தேர்தலில் நீங்கள் எந்தக் கட்சிக்கு வாக்களித்தீர்கள்?/ Which party did you vote in 2021 Assembly Elections? ]],Factor!$F$9:$J$14,5,0) -> 1.3119425 | AV7: =VLOOKUP(Table1[[#This Row],[Rev Caste]],Factor!$F$59:$I$68,4,0) -> 0.93090909 | AW7: =Table1[[#This Row],[2021 Ae Factor]]*Table1[[#This Row],[Age & Gender Factor]] -> 1.4523558 | AX7: =Table1[[#This Row],[2021 Ae Factor]]*Table1[[#This Row],[Caste Factor]] -> 1.2212992 | AY7: =VALUE(MID(D7, FIND(",",D7)+2, FIND(")",D7)-FIND(",",D7)-2)) -> 78.681528
A8: wEykrB7PWmMFbpcLSh29 | B8: 2025-07-30 14:42:51.078465 | C8: 45868 | D8: (10.462279, 78.6809876) | E8: FM6J+JHW,,Pudukkottai,622103,Tamil Nadu,India. | F8: https://firebasestorage.googleapis.com/v0/b/mindbrink-survey-production.appspot.com/o/audioFiles%2FAtznECuQc6klLPsRR6u2%2F2ukCmICpvKWhqTT6dgmjG6nFGjc2%2F2025-07-30%2014%3A42%3A42.625814.m4a?alt=media&token=aa21e8ba-da98-4d18-8f39-886502c10bef | G8: 331 | H8: false | I8: U.Amir nisha | J8: +919698565662 | K8: Subramanian | L8: ILLUPUR | M8: MUKKANNAMALAIPATTI | N8: Jesuthas | O8: ஆண்/Male | P8: 8973759103 | Q8: 46-60 | R8: கூலி தொழில்/ Daily Wage | S8: 10,000க்கும் குறைவானது/Less than 10,000 | T8: திருப்திகரமல்ல/ Unsatisfactory | U8: ஆம் / Yes | V8: திமுக கூட்டணி / DMK Alliance | W8: எடப்பாடி பழனிசாமி (அதிமுக) / Edappadi K. Palaniswami (AIADMK) | X8: திமுக / DMK | Y8: DMK | Z8: - | AA8: ஆமாம் / Yes | AB8: அதிமுக கூட்டணி / AIADMK Alliance | AC8: திருப்திகரமல்ல / Unsatisfactory | AD8: குறைவான ஈடுபாடு / Inadequate | AE8: • ஆமாம்: திமுக மற்றும் அதிமுக கூட்டணிகள் இரண்டும் உடையும்/ Yes: Both DMK & AIADMK alliances will break up | AF8: அதிமுக / AIADMK | AG8: விவசாய நெருக்கடி / Agricultural crisis | AH8: SC | AI8: CHRISTIAN | AJ8: =IFERROR(_xlfn.XLOOKUP(Table1[[#This Row],[Audio Url]],Qc!C:C,Qc!F:F),"") -> 0 | AK8: =IFERROR(_xlfn.XLOOKUP(Table1[[#This Row],[Audio Url]],Qc!C:C,Qc!E:E),"") -> Correctly Done | AL8: - | AM8: - | AN8: =VLOOKUP(Table1[[#This Row],[LOCALITY]],Sheet2!$F:$H,3,0) -> Rural | AO8: Yes | AP8: =IF(Table1[[#This Row],[Audio Duration (in secs)]]>180,"Greater than 3 Minutes","Less than 3 Minutes") -> Greater than 3 Minutes | AQ8: =IFERROR(VLOOKUP(Table1[[#This Row],[சாதி/Caste]],MApping!$E$1:$F$10,2,0),"Others") -> CHRISTIAN | AR8: =VLOOKUP(Table1[[#This Row],[பாலினம்/Gender]],Factor!$F$26:$I$28,4,0) -> 0.95700935 | AS8: =VLOOKUP(Table1[[#This Row],[பதிலளித்தவரின் வயது/Age Group]],Factor!$F$35:$I$39,4,0) -> 0.87972509 | AT8: =VLOOKUP(Table1[[#This Row],[பதிலளித்தவரின் வயது/Age Group]]&Table1[[#This Row],[பாலினம்/Gender]],Factor!$A$45:$G$53,7,0) -> 0.79503106 | AU8: =VLOOKUP(Table1[[#This Row],[2021 சட்டமன்றத் தேர்தலில் நீங்கள் எந்தக் கட்சிக்கு வாக்களித்தீர்கள்?/ Which party did you vote in 2021 Assembly Elections? ]],Factor!$F$9:$J$14,5,0) -> 0.73680082 | AV8: =VLOOKUP(Table1[[#This Row],[Rev Caste]],Factor!$F$59:$I$68,4,0) -> 0.93090909 | AW8: =Table1[[#This Row],[2021 Ae Factor]]*Table1[[#This Row],[Age & Gender Factor]] -> 0.58577954 | AX8: =Table1[[#This Row],[2021 Ae Factor]]*Table1[[#This Row],[Caste Factor]] -> 0.68589459 | AY8: =VALUE(MID(D8, FIND(",",D8)+2, FIND(")",D8)-FIND(",",D8)-2)) -> 78.680988
A9: u9XGRvPU08lptw83iYlu | B9: 2025-07-30 14:51:49.473078 | C9: 45868 | D9: (10.4623531, 78.6809325) | E9: FM6J+JHW,,Pudukkottai,622103,Tamil Nadu,India. | F9: https://firebasestorage.googleapis.com/v0/b/mindbrink-survey-production.appspot.com/o/audioFiles%2FAtznECuQc6klLPsRR6u2%2F2ukCmICpvKWhqTT6dgmjG6nFGjc2%2F2025-07-30%2014%3A51%3A43.908029.m4a?alt=media&token=483045d4-e721-4bd9-870a-817b0e8046be | G9: 274 | H9: false | I9: U.Amir nisha | J9: +919698565662 | K9: Subramanian | L9: ILLUPUR | M9: MUKKANNAMALAIPATTI | N9: Jayamary | O9: பெண்/Female | P9: 9578493153 | Q9: 31-45 | R9: கூலி தொழில்/ Daily Wage | S9: 10,000க்கும் குறைவானது/Less than 10,000 | T9: திருப்திகரமானது / Satisfactory | U9: ஆம் / Yes | V9: அதிமுக கூட்டணி / AIADMK Alliance | W9: மு.க. ஸ்டாலின் (திமுக) / M.K. Stalin (DMK) | X9: அதிமுக / AIADMK | Y9: AIADMK | Z9: ஆம், TVK கூட்டணிக்கு வாக்களிப்பேன் / Yes, I will shift my vote to the TVK alliance | AA9: இல்லை / No | AB9: - | AC9: வேகம் குறைபாடுடன் செயல்படுகிறது / Needs more momentum | AD9: போதுமான ஈடுபாடு / Adequate | AE9: • ஆமாம்: திமுக மற்றும் அதிமுக கூட்டணிகள் இரண்டும் உடையும்/ Yes: Both DMK & AIADMK alliances will break up | AF9: அதிமுக / AIADMK | AG9: விவசாய நெருக்கடி / Agricultural crisis | AH9: SC | AI9: CHRISTIAN | AJ9: =IFERROR(_xlfn.XLOOKUP(Table1[[#This Row],[Audio Url]],Qc!C:C,Qc!F:F),"") -> 0 | AK9: =IFERROR(_xlfn.XLOOKUP(Table1[[#This Row],[Audio Url]],Qc!C:C,Qc!E:E),"") -> Correctly Done | AL9: - | AM9: - | AN9: =VLOOKUP(Table1[[#This Row],[LOCALITY]],Sheet2!$F:$H,3,0) -> Rural | AO9: Yes | AP9: =IF(Table1[[#This Row],[Audio Duration (in secs)]]>180,"Greater than 3 Minutes","Less than 3 Minutes") -> Greater than 3 Minutes | AQ9: =IFERROR(VLOOKUP(Table1[[#This Row],[சாதி/Caste]],MApping!$E$1:$F$10,2,0),"Others") -> CHRISTIAN | AR9: =VLOOKUP(Table1[[#This Row],[பாலினம்/Gender]],Factor!$F$26:$I$28,4,0) -> 1.0470348 | AS9: =VLOOKUP(Table1[[#This Row],[பதிலளித்தவரின் வயது/Age Group]],Factor!$F$35:$I$39,4,0) -> 1.0951872 | AT9: =VLOOKUP(Table1[[#This Row],[பதிலளித்தவரின் வயது/Age Group]]&Table1[[#This Row],[பாலினம்/Gender]],Factor!$A$45:$G$53,7,0) -> 1.107027 | AU9: =VLOOKUP(Table1[[#This Row],[2021 சட்டமன்றத் தேர்தலில் நீங்கள் எந்தக் கட்சிக்கு வாக்களித்தீர்கள்?/ Which party did you vote in 2021 Assembly Elections? ]],Factor!$F$9:$J$14,5,0) -> 1.3119425 | AV9: =VLOOKUP(Table1[[#This Row],[Rev Caste]],Factor!$F$59:$I$68,4,0) -> 0.93090909 | AW9: =Table1[[#This Row],[2021 Ae Factor]]*Table1[[#This Row],[Age & Gender Factor]] -> 1.4523558 | AX9: =Table1[[#This Row],[2021 Ae Factor]]*Table1[[#This Row],[Caste Factor]] -> 1.2212992 | AY9: =VALUE(MID(D9, FIND(",",D9)+2, FIND(")",D9)-FIND(",",D9)-2)) -> 78.680932
A10: e6ac5EItzYfOFpBKRvtE | B10: 2025-07-30 14:56:26.558863 | C10: 45868 | D10: (10.4621783, 78.6809415) | E10: FM6J+JHW,,Pudukkottai,622103,Tamil Nadu,India. | F10: https://firebasestorage.googleapis.com/v0/b/mindbrink-survey-production.appspot.com/o/audioFiles%2FAtznECuQc6klLPsRR6u2%2F2ukCmICpvKWhqTT6dgmjG6nFGjc2%2F2025-07-30%2014%3A56%3A20.571686.m4a?alt=media&token=09e17480-5dfc-4cff-9135-47f53823b27a | G10: 233 | H10: false | I10: U.Amir nisha | J10: +919698565662 | K10: Subramanian | L10: ILLUPUR | M10: MUKKANNAMALAIPATTI | N10: Arokiya shalini | O10: பெண்/Female | P10: 6384537452 | Q10: 18-30 | R10: இல்லத்தரசி/ Housewife | S10: 10,000க்கும் குறைவானது/Less than 10,000 | T10: மேம்பாடு தேவை / Needs improvement | U10: ஆம் / Yes | V10: திமுக கூட்டணி / DMK Alliance | W10: விஜய் (தமிழக வெற்றி கழகம்) / Vijay (TVK) | X10: திமுக / DMK | Y10: DMK | Z10: - | AA10: ஆமாம் / Yes | AB10: திமுக கூட்டணி / DMK Alliance | AC10: வேகம் குறைபாடுடன் செயல்படுகிறது / Needs more momentum | AD10: போதுமான ஈடுபாடு / Adequate | AE10: • ஆமாம்: திமுக மற்றும் அதிமுக கூட்டணிகள் இரண்டும் உடையும்/ Yes: Both DMK & AIADMK alliances will break up | AF10: தனித்துப் போட்டியிட வேண்டும் / Contest Independently | AG10: விவசாய நெருக்கடி / Agricultural crisis | AH10: SC | AI10: CHRISTIAN | AJ10: =IFERROR(_xlfn.XLOOKUP(Table1[[#This Row],[Audio Url]],Qc!C:C,Qc!F:F),"") | AK10: =IFERROR(_xlfn.XLOOKUP(Table1[[#This Row],[Audio Url]],Qc!C:C,Qc!E:E),"") | AL10: - | AM10: - | AN10: =VLOOKUP(Table1[[#This Row],[LOCALITY]],Sheet2!$F:$H,3,0) -> Rural | AO10: Yes | AP10: =IF(Table1[[#This Row],[Audio Duration (in secs)]]>180,"Greater than 3 Minutes","Less than 3 Minutes") -> Greater than 3 Minutes | AQ10: =IFERROR(VLOOKUP(Table1[[#This Row],[சாதி/Caste]],MApping!$E$1:$F$10,2,0),"Others") -> CHRISTIAN | AR10: =VLOOKUP(Table1[[#This Row],[பாலினம்/Gender]],Factor!$F$26:$I$28,4,0) -> 1.0470348 | AS10: =VLOOKUP(Table1[[#This Row],[பதிலளித்தவரின் வயது/Age Group]],Factor!$F$35:$I$39,4,0) -> 0.9752381 | AT10: =VLOOKUP(Table1[[#This Row],[பதிலளித்தவரின் வயது/Age Group]]&Table1[[#This Row],[பாலினம்/Gender]],Factor!$A$45:$G$53,7,0) -> 0.89824561 | AU10: =VLOOKUP(Table1[[#This Row],[2021 சட்டமன்றத் தேர்தலில் நீங்கள் எந்தக் கட்சிக்கு வாக்களித்தீர்கள்?/ Which party did you vote in 2021 Assembly Elections? ]],Factor!$F$9:$J$14,5,0) -> 0.73680082 | AV10: =VLOOKUP(Table1[[#This Row],[Rev Caste]],Factor!$F$59:$I$68,4,0) -> 0.93090909 | AW10: =Table1[[#This Row],[2021 Ae Factor]]*Table1[[#This Row],[Age & Gender Factor]] -> 0.66182811 | AX10: =Table1[[#This Row],[2021 Ae Factor]]*Table1[[#This Row],[Caste Factor]] -> 0.68589459 | AY10: =VALUE(MID(D10, FIND(",",D10)+2, FIND(")",D10)-FIND(",",D10)-2)) -> 78.680942
A11: E0uszhEvnSbx6OhSMH4r | B11: 2025-07-30 15:02:09.334115 | C11: 45868 | D11: (10.462594, 78.6806822) | E11: FM7J+89V,,Madakoil,622103,Tamil Nadu,India. | F11: https://firebasestorage.googleapis.com/v0/b/mindbrink-survey-production.appspot.com/o/audioFiles%2FAtznECuQc6klLPsRR6u2%2F2ukCmICpvKWhqTT6dgmjG6nFGjc2%2F2025-07-30%2015%3A02%3A02.380467.m4a?alt=media&token=81f317a8-fb8d-43d3-859d-4d0a1d121306 | G11: 187 | H11: false | I11: U.Amir nisha | J11: +919698565662 | K11: Subramanian | L11: ILLUPUR | M11: MUKKANNAMALAIPATTI | N11: sivanthai | O11: பெண்/Female | P11: 9715185244 | Q11: 46-60 | R11: இல்லத்தரசி/ Housewife | S11: 10,000க்கும் குறைவானது/Less than 10,000 | T11: மேம்பாடு தேவை / Needs improvement | U11: ஆம் / Yes | V11: திமுக கூட்டணி / DMK Alliance | W11: விஜய் (தமிழக வெற்றி கழகம்) / Vijay (TVK) | X11: திமுக / DMK | Y11: DMK | Z11: - | AA11: ஆமாம் / Yes | AB11: திமுக கூட்டணி / DMK Alliance | AC11: வேகம் குறைபாடுடன் செயல்படுகிறது / Needs more momentum | AD11: குறைவான ஈடுபாடு / Inadequate | AE11: • ஆமாம்: திமுக மற்றும் அதிமுக கூட்டணிகள் இரண்டும் உடையும்/ Yes: Both DMK & AIADMK alliances will break up | AF11: தனித்துப் போட்டியிட வேண்டும் / Contest Independently | AG11: வேலைவாய்ப்பு குறைபாடு / Unemployment | AH11: SC | AI11: CHRISTIAN | AJ11: =IFERROR(_xlfn.XLOOKUP(Table1[[#This Row],[Audio Url]],Qc!C:C,Qc!F:F),"") | AK11: =IFERROR(_xlfn.XLOOKUP(Table1[[#This Row],[Audio Url]],Qc!C:C,Qc!E:E),"") | AL11: - | AM11: - | AN11: =VLOOKUP(Table1[[#This Row],[LOCALITY]],Sheet2!$F:$H,3,0) -> Rural | AO11: Yes | AP11: =IF(Table1[[#This Row],[Audio Duration (in secs)]]>180,"Greater than 3 Minutes","Less than 3 Minutes") -> Greater than 3 Minutes | AQ11: =IFERROR(VLOOKUP(Table1[[#This Row],[சாதி/Caste]],MApping!$E$1:$F$10,2,0),"Others") -> CHRISTIAN | AR11: =VLOOKUP(Table1[[#This Row],[பாலினம்/Gender]],Factor!$F$26:$I$28,4,0) -> 1.0470348 | AS11: =VLOOKUP(Table1[[#This Row],[பதிலளித்தவரின் வயது/Age Group]],Factor!$F$35:$I$39,4,0) -> 0.87972509 | AT11: =VLOOKUP(Table1[[#This Row],[பதிலளித்தவரின் வயது/Age Group]]&Table1[[#This Row],[பாலினம்/Gender]],Factor!$A$45:$G$53,7,0) -> 0.98461538 | AU11: =VLOOKUP(Table1[[#This Row],[2021 சட்டமன்றத் தேர்தலில் நீங்கள் எந்தக் கட்சிக்கு வாக்களித்தீர்கள்?/ Which party did you vote in 2021 Assembly Elections? ]],Factor!$F$9:$J$14,5,0) -> 0.73680082 | AV11: =VLOOKUP(Table1[[#This Row],[Rev Caste]],Factor!$F$59:$I$68,4,0) -> 0.93090909 | AW11: =Table1[[#This Row],[2021 Ae Factor]]*Table1[[#This Row],[Age & Gender Factor]] -> 0.72546543 | AX11: =Table1[[#This Row],[2021 Ae Factor]]*Table1[[#This Row],[Caste Factor]] -> 0.68589459 | AY11: =VALUE(MID(D11, FIND(",",D11)+2, FIND(")",D11)-FIND(",",D11)-2)) -> 78.680682
A12: BhxdqOskEmCZ304Pnoub | B12: 2025-07-30 15:10:51.958258 | C12: 45868 | D12: (10.4629467, 78.6810732) | E12: FM7J+89V,,Madakoil,622103,Tamil Nadu,India. | F12: https://firebasestorage.googleapis.com/v0/b/mindbrink-survey-production.appspot.com/o/audioFiles%2FAtznECuQc6klLPsRR6u2%2F2ukCmICpvKWhqTT6dgmjG6nFGjc2%2F2025-07-30%2015%3A10%3A39.624126.m4a?alt=media&token=d885f812-189d-4fd3-8103-6594736f083c | G12: 437 | H12: false | I12: U.Amir nisha | J12: +919698565662 | K12: Subramanian | L12: ILLUPUR | M12: MUKKANNAMALAIPATTI | N12: jansi rani | O12: பெண்/Female | P12: 8012952924 | Q12: 18-30 | R12: இல்லத்தரசி/ Housewife | S12: 10,000க்கும் குறைவானது/Less than 10,000 | T12: மேம்பாடு தேவை / Needs improvement | U12: ஆம் / Yes | V12: நினைவில் இல்லை / Don’t Remember | W12: விஜய் (தமிழக வெற்றி கழகம்) / Vijay (TVK) | X12: திமுக / DMK | Y12: DMK | Z12: - | AA12: ஆமாம் / Yes | AB12: திமுக கூட்டணி / DMK Alliance | AC12: வேகம் குறைபாடுடன் செயல்படுகிறது / Needs more momentum | AD12: குறைவான ஈடுபாடு / Inadequate | AE12: • ஆமாம்: திமுக மற்றும் அதிமுக கூட்டணிகள் இரண்டும் உடையும்/ Yes: Both DMK & AIADMK alliances will break up | AF12: தனித்துப் போட்டியிட வேண்டும் / Contest Independently | AG12: மதுபானம் / போதைப்பொருள் பழக்கம்/ Alcohol/Drug abuse | AH12: SC | AI12: CHRISTIAN | AJ12: =IFERROR(_xlfn.XLOOKUP(Table1[[#This Row],[Audio Url]],Qc!C:C,Qc!F:F),"") -> 0 | AK12: =IFERROR(_xlfn.XLOOKUP(Table1[[#This Row],[Audio Url]],Qc!C:C,Qc!E:E),"") -> Correctly Done | AL12: - | AM12: - | AN12: =VLOOKUP(Table1[[#This Row],[LOCALITY]],Sheet2!$F:$H,3,0) -> Rural | AO12: Yes | AP12: =IF(Table1[[#This Row],[Audio Duration (in secs)]]>180,"Greater than 3 Minutes","Less than 3 Minutes") -> Greater than 3 Minutes | AQ12: =IFERROR(VLOOKUP(Table1[[#This Row],[சாதி/Caste]],MApping!$E$1:$F$10,2,0),"Others") -> CHRISTIAN | AR12: =VLOOKUP(Table1[[#This Row],[பாலினம்/Gender]],Factor!$F$26:$I$28,4,0) -> 1.0470348 | AS12: =VLOOKUP(Table1[[#This Row],[பதிலளித்தவரின் வயது/Age Group]],Factor!$F$35:$I$39,4,0) -> 0.9752381 | AT12: =VLOOKUP(Table1[[#This Row],[பதிலளித்தவரின் வயது/Age Group]]&Table1[[#This Row],[பாலினம்/Gender]],Factor!$A$45:$G$53,7,0) -> 0.89824561 | AU12: =VLOOKUP(Table1[[#This Row],[2021 சட்டமன்றத் தேர்தலில் நீங்கள் எந்தக் கட்சிக்கு வாக்களித்தீர்கள்?/ Which party did you vote in 2021 Assembly Elections? ]],Factor!$F$9:$J$14,5,0) -> 1 | AV12: =VLOOKUP(Table1[[#This Row],[Rev Caste]],Factor!$F$59:$I$68,4,0) -> 0.93090909 | AW12: =Table1[[#This Row],[2021 Ae Factor]]*Table1[[#This Row],[Age & Gender Factor]] -> 0.89824561 | AX12: =Table1[[#This Row],[2021 Ae Factor]]*Table1[[#This Row],[Caste Factor]] -> 0.93090909 | AY12: =VALUE(MID(D12, FIND(",",D12)+2, FIND(")",D12)-FIND(",",D12)-2)) -> 78.681073
A13: LtwsC8GYqQizC0FxeuxW | B13: 2025-07-30 15:14:56.602348 | C13: 45868 | D13: (10.4628599, 78.6808137) | E13: FM7J+89V,,Madakoil,622103,Tamil Nadu,India. | F13: https://firebasestorage.googleapis.com/v0/b/mindbrink-survey-production.appspot.com/o/audioFiles%2FAtznECuQc6klLPsRR6u2%2F2ukCmICpvKWhqTT6dgmjG6nFGjc2%2F2025-07-30%2015%3A14%3A48.563168.m4a?alt=media&token=e6b48caf-67ad-4c1d-aadf-d84204f505a0 | G13: 203 | H13: false | I13: U.Amir nisha | J13: +919698565662 | K13: Subramanian | L13: ILLUPUR | M13: MUKKANNAMALAIPATTI | N13: Arulselvi | O13: பெண்/Female | P13: 9843601161 | Q13: 18-30 | R13: இல்லத்தரசி/ Housewife | S13: 10,000க்கும் குறைவானது/Less than 10,000 | T13: திருப்திகரமானது / Satisfactory | U13: ஆம் / Yes | V13: திமுக கூட்டணி / DMK Alliance | W13: மு.க. ஸ்டாலின் (திமுக) / M.K. Stalin (DMK) | X13: திமுக / DMK | Y13: DMK | Z13: - | AA13: ஆமாம் / Yes | AB13: அதிமுக கூட்டணி / AIADMK Alliance | AC13: திருப்திகரமல்ல / Unsatisfactory | AD13: குறைவான ஈடுபாடு / Inadequate | AE13: • ஆமாம்: அதிமுக கூட்டணி உடையும்/ Yes: AIADMK alliance will break up | AF13: தனித்துப் போட்டியிட வேண்டும் / Contest Independently | AG13: விவசாய நெருக்கடி / Agricultural crisis | AH13: SC | AI13: CHRISTIAN | AJ13: =IFERROR(_xlfn.XLOOKUP(Table1[[#This Row],[Audio Url]],Qc!C:C,Qc!F:F),"") -> same voice | AK13: =IFERROR(_xlfn.XLOOKUP(Table1[[#This Row],[Audio Url]],Qc!C:C,Qc!E:E),"") -> Taking From Friends And Family | AL13: - | AM13: - | AN13: =VLOOKUP(Table1[[#This Row],[LOCALITY]],Sheet2!$F:$H,3,0) -> Rural | AO13: No | AP13: =IF(Table1[[#This Row],[Audio Duration (in secs)]]>180,"Greater than 3 Minutes","Less than 3 Minutes") -> Greater than 3 Minutes | AQ13: =IFERROR(VLOOKUP(Table1[[#This Row],[சாதி/Caste]],MApping!$E$1:$F$10,2,0),"Others") -> CHRISTIAN | AR13: =VLOOKUP(Table1[[#This Row],[பாலினம்/Gender]],Factor!$F$26:$I$28,4,0) -> 1.0470348 | AS13: =VLOOKUP(Table1[[#This Row],[பதிலளித்தவரின் வயது/Age Group]],Factor!$F$35:$I$39,4,0) -> 0.9752381 | AT13: =VLOOKUP(Table1[[#This Row],[பதிலளித்தவரின் வயது/Age Group]]&Table1[[#This Row],[பாலினம்/Gender]],Factor!$A$45:$G$53,7,0) -> 0.89824561 | AU13: =VLOOKUP(Table1[[#This Row],[2021 சட்டமன்றத் தேர்தலில் நீங்கள் எந்தக் கட்சிக்கு வாக்களித்தீர்கள்?/ Which party did you vote in 2021 Assembly Elections? ]],Factor!$F$9:$J$14,5,0) -> 0.73680082 | AV13: =VLOOKUP(Table1[[#This Row],[Rev Caste]],Factor!$F$59:$I$68,4,0) -> 0.93090909 | AW13: =Table1[[#This Row],[2021 Ae Factor]]*Table1[[#This Row],[Age & Gender Factor]] -> 0.66182811 | AX13: =Table1[[#This Row],[2021 Ae Factor]]*Table1[[#This Row],[Caste Factor]] -> 0.68589459 | AY13: =VALUE(MID(D13, FIND(",",D13)+2, FIND(")",D13)-FIND(",",D13)-2)) -> 78.680814
... A41: kTVsPMA8T7faxSj38lEY | B41: 2025-07-30 17:34:59.329295 | C41: 45868 | D41: (10.4598067, 78.6825817) | E41: 1/38a,,Vilampatti,622103,Tamil Nadu,India. | F41: https://firebasestorage.googleapis.com/v0/b/mindbrink-survey-production.appspot.com/o/audioFiles%2FAtznECuQc6klLPsRR6u2%2FfYiv0HvGk4VbFlXYwsKbSZ6fwXI2%2F2025-07-30%2017%3A34%3A53.880757.m4a?alt=media&token=d8a52737-f4fc-42e4-91b9-7b5b541457a6 | G41: 190 | H41: false | I41: A.Banu | J41: +919443892814 | K41: Subramanian | L41: ILLUPUR | M41: MUKKANNAMALAIPATTI | N41: Prathiba | O41: பெண்/Female | P41: 8072379197 | Q41: 31-45 | R41: இல்லத்தரசி/ Housewife | S41: 10,000க்கும் குறைவானது/Less than 10,000 | T41: திருப்திகரமானது / Satisfactory | U41: உறுதியாக தெரியவில்லை / Not Sure | V41: திமுக கூட்டணி / DMK Alliance | W41: விஜய் (தமிழக வெற்றி கழகம்) / Vijay (TVK) | X41: அதிமுக / AIADMK | Y41: TVK | Z41: ஆம், TVK கூட்டணிக்கு வாக்களிப்பேன் / Yes, I will shift my vote to the TVK alliance | AA41: ஆமாம் / Yes | AB41: அதிமுக கூட்டணி / AIADMK Alliance | AC41: திருப்திகரமானது / Satisfactory | AD41: போதுமான ஈடுபாடு / Adequate | AE41: • ஆமாம்: அதிமுக கூட்டணி உடையும்/ Yes: AIADMK alliance will break up | AF41: தனித்துப் போட்டியிட வேண்டும் / Contest Independently | AG41: உட்கட்டமைப்பு மேம்பாடு / Infrastructure development | AH41: BC | AI41: MUTTARAIYAR | AJ41: =IFERROR(_xlfn.XLOOKUP(Table1[[#This Row],[Audio Url]],Qc!C:C,Qc!F:F),"") -> correctly done | AK41: =IFERROR(_xlfn.XLOOKUP(Table1[[#This Row],[Audio Url]],Qc!C:C,Qc!E:E),"") -> Correctly Done | AL41: - | AM41: - | AN41: =VLOOKUP(Table1[[#This Row],[LOCALITY]],Sheet2!$F:$H,3,0) -> Rural | AO41: Yes | AP41: =IF(Table1[[#This Row],[Audio Duration (in secs)]]>180,"Greater than 3 Minutes","Less than 3 Minutes") -> Greater than 3 Minutes | AQ41: =IFERROR(VLOOKUP(Table1[[#This Row],[சாதி/Caste]],MApping!$E$1:$F$10,2,0),"Others") -> MUTTARAIYAR | AR41: =VLOOKUP(Table1[[#This Row],[பாலினம்/Gender]],Factor!$F$26:$I$28,4,0) -> 1.0470348 | AS41: =VLOOKUP(Table1[[#This Row],[பதிலளித்தவரின் வயது/Age Group]],Factor!$F$35:$I$39,4,0) -> 1.0951872 | AT41: =VLOOKUP(Table1[[#This Row],[பதிலளித்தவரின் வயது/Age Group]]&Table1[[#This Row],[பாலினம்/Gender]],Factor!$A$45:$G$53,7,0) -> 1.107027 | AU41: =VLOOKUP(Table1[[#This Row],[2021 சட்டமன்றத் தேர்தலில் நீங்கள் எந்தக் கட்சிக்கு வாக்களித்தீர்கள்?/ Which party did you vote in 2021 Assembly Elections? ]],Factor!$F$9:$J$14,5,0) -> 0.73680082 | AV41: =VLOOKUP(Table1[[#This Row],[Rev Caste]],Factor!$F$59:$I$68,4,0) -> 1.2358621 | AW41: =Table1[[#This Row],[2021 Ae Factor]]*Table1[[#This Row],[Age & Gender Factor]] -> 0.81565843 | AX41: =Table1[[#This Row],[2021 Ae Factor]]*Table1[[#This Row],[Caste Factor]] -> 0.91058419 | AY41: =VALUE(MID(D41, FIND(",",D41)+2, FIND(")",D41)-FIND(",",D41)-2)) -> 78.682582
