Workbook

Sheet Pviots
A3: Count of Sample ID | B3: Column Labels
A4: Row Labels | B4: 45868 | C4: 45869 | D4: 45873 | E4: 45874 | F4: 45875 | G4: 45876 | H4: 45877 | I4: Grand Total
A5: Subramanian | B5: 54 | C5: 153 | D5: 67 | E5: 26 | F5: 66 | G5: 95 | H5: 42 | I5: 503
A6: A.Banu | B6: 21 | C6: 49 | D6: 8 | I6: 78
A7: G.muthukumar | B7: 1 | C7: 2 | F7: 16 | G7: 23 | I7: 42
A8: Sinthanai selvi | B8: 12 | C8: 42 | I8: 54
A9: U.Amir nisha | B9: 20 | C9: 60 | D9: 20 | I9: 100
A10: priya | D10: 20 | E10: 13 | F10: 20 | G10: 29 | H10: 21 | I10: 103
A11: Immaculatebanumathi | D11: 19 | E11: 13 | F11: 20 | G11: 30 | H11: 21 | I11: 103
A12: pantyan | F12: 10 | G12: 13 | I12: 23
A13: Grand Total | B13: 54 | C13: 153 | D13: 67 | E13: 26 | F13: 66 | G13: 95 | H13: 42 | I13: 503
A21: Date | B21: 45877 | G21: Date | H21: 45876
A22: Surveyor Vendor Name | B22: (All) | G22: Surveyor Vendor Name | H22: (All)
A24: Count of Sample ID | B24: Column Labels | G24: Count of Sample ID | H24: Column Labels
A25: Row Labels | B25: Greater than 3 Minutes | C25: Grand Total | G25: Row Labels | H25: 18-30 | I25: 31-45 | J25: 46-60 | K25: 60+ | L25: Grand Total
A26: priya | B26: 21 | C26: 21 | G26: G.muthukumar | H26: 8 | I26: 4 | J26: 8 | K26: 3 | L26: 23
A27: Immaculatebanumathi | B27: 21 | C27: 21 | G27: priya | H27: 7 | I27: 11 | J27: 8 | K27: 3 | L27: 29
A28: Grand Total | B28: 42 | C28: 42 | G28: Immaculatebanumathi | H28: 8 | I28: 10 | J28: 9 | K28: 3 | L28: 30
G29: pantyan | H29: 2 | I29: 4 | J29: 5 | K29: 2 | L29: 13
G30: Grand Total | H30: 25 | I30: 29 | J30: 30 | K30: 11 | L30: 95
A37: Date | B37: 45877
A39: Count of Sample ID | B39: Column Labels
A40: Row Labels | B40: ஆண்/Male | C40: பெண்/Female | D40: Grand Total
A41: Subramanian | B41: 0.35714286 | C41: 0.64285714 | D41: 1 | E41: Sample Count
A42: priya | B42: 0.33333333 | C42: 0.66666667 | D42: 1 | E42: 23
A43: Immaculatebanumathi | B43: 0.38095238 | C43: 0.61904762 | D43: 1 | E43: 29
A44: Grand Total | B44: 0.35714286 | C44: 0.64285714 | D44: 1 | E44: 30
E45: 13
E46: 95

Sheet Data Updation
A1: Date | B1: 45877 | D1: Date | E1: (All) | I1: DMK | J1: TVK | K1: AIADMK | L1: INC | M1: BJP | N1: NTK | O1: DMDK | P1: VCK | Q1: PMK | R1: CPI | S1: CPM | T1: Others
A2: Consider | B2: Yes | D2: Consider | E2: Yes | I2: =IFERROR(VLOOKUP(I1,$A$4:$B$15,2,0),0%) -> 0.375 | J2: =IFERROR(VLOOKUP(J1,$A$4:$B$15,2,0),0%) -> 0 | K2: =IFERROR(VLOOKUP(K1,$A$4:$B$15,2,0),0%) -> 0.45833333 | L2: =IFERROR(VLOOKUP(L1,$A$4:$B$15,2,0),0%) -> 0 | M2: =IFERROR(VLOOKUP(M1,$A$4:$B$15,2,0),0%) -> 0 | N2: =IFERROR(VLOOKUP(N1,$A$4:$B$15,2,0),0%) -> 0 | O2: =IFERROR(VLOOKUP(O1,$A$4:$B$15,2,0),0%) -> 0 | P2: =IFERROR(VLOOKUP(P1,$A$4:$B$15,2,0),0%) -> 0 | ... T2: =IFERROR(VLOOKUP(T1,$A$4:$B$15,2,0),0%) -> 0.16666667
I3: =IFERROR(VLOOKUP(I$1,$D$4:$E$19,2,0),0%) -> 0.30714286 | J3: =IFERROR(VLOOKUP(J$1,$D$4:$E$19,2,0),0%) -> 0.069047619 | K3: =IFERROR(VLOOKUP(K$1,$D$4:$E$19,2,0),0%) -> 0.5 | L3: =IFERROR(VLOOKUP(L$1,$D$4:$E$19,2,0),0%) -> 0.0071428571 | M3: =IFERROR(VLOOKUP(M$1,$D$4:$E$19,2,0),0%) -> 0.0095238095 | N3: =IFERROR(VLOOKUP(N$1,$D$4:$E$19,2,0),0%) -> 0.0071428571 | O3: =IFERROR(VLOOKUP(O$1,$D$4:$E$19,2,0),0%) -> 0.0095238095 | P3: =IFERROR(VLOOKUP(P$1,$D$4:$E$19,2,0),0%) -> 0 | ... T3: =IFERROR(VLOOKUP(T$1,$D$4:$E$19,2,0),0%) -> 0.088095238
A4: Row Labels | B4: Count of Sample ID | D4: Row Labels | E4: Count of Sample ID
A5: DMK | B5: 0.375 | D5: INC | E5: 0.0071428571
A6: AIADMK | B6: 0.45833333 | D6: DMK | E6: 0.30714286
A7: Others | B7: 0.16666667 | D7: AIADMK | E7: 0.5
A8: Grand Total | B8: 1 | D8: TVK | E8: 0.069047619
D9: DMDK | E9: 0.0095238095
D10: BJP | E10: 0.0095238095
D11: CPM | E11: 0.0023809524
D12: Others | E12: 0.088095238
D13: NTK | E13: 0.0071428571
D14: Grand Total | E14: 1 | I14: Consider | J14: Yes
I16: Row Labels | J16: Count of Sample ID | L16: Count of Sample ID | M16: Column Labels
I17: 45868 | J17: 30 | L17: Row Labels | M17: AIADMK | N17: BJP | O17: CPM | P17: DMDK | Q17: DMK | R17: INC | S17: NTK | T17: Others | U17: TVK | V17: Grand Total
I18: 45869 | J18: 117 | L18: ANNAVASAL | M18: 31 | N18: 1 | O18: 1 | P18: 1 | Q18: 11 | R18: 2 | T18: 1 | U18: 6 | V18: 54
I19: 45873 | J19: 64 | L19: ATHIPALLAM | Q19: 1 | V19: 1
I20: 45874 | J20: 26 | L20: KILIKUDI | M20: 25 | Q20: 4 | V20: 29
I21: 45875 | J21: 64 | L21: KUDUMIYANMALAI | M21: 23 | Q21: 16 | U21: 4 | V21: 43
I22: 45876 | J22: 95 | L22: MANGUDI | M22: 19 | Q22: 5 | S22: 1 | U22: 3 | V22: 28
I23: 45877 | J23: 24 | L23: MUKKANNAMALAIPATTI | M23: 11 | P23: 3 | Q23: 21 | U23: 5 | V23: 40
I24: Grand Total | J24: 420 | L24: PARAMBUR | M24: 23 | Q24: 12 | U24: 2 | V24: 37
L25: RAJALIPATTI | M25: 5 | Q25: 10 | S25: 1 | V25: 16
L26: VEERAPATTI | U26: 1 | V26: 1
L27: VIRALIMALAI | M27: 93 | N27: 3 | P27: 1 | Q27: 65 | R27: 1 | S27: 2 | T27: 33 | U27: 14 | V27: 212
L28: MATHUR | M28: 11 | Q28: 22 | T28: 6 | U28: 3 | V28: 42
L29: Grand Total | M29: 241 | N29: 4 | O29: 1 | P29: 5 | Q29: 167 | R29: 3 | S29: 4 | T29: 40 | U29: 38 | V29: 503

Sheet Location and Caste
B1: Caste | C1: Required | D1: Collected | E1: Pending | F1: Collected % | K1: Date | L1: (All) | Q1: Consider | R1: All
A2: VIRALIMALAI | B2: MUTTARAIYAR | C2: =H2/2 -> 140 | D2: =VLOOKUP(B2,$K$5:$L$15,2,0) -> 58 | E2: =C2-D2 -> 82 | F2: =D2/C2 -> 0.41428571 | H2: 280 | K2: Surveyor Vendor Name | L2: (All) | Q2: Date | R2: All
A3: VIRALIMALAI | B3: DEVENDRA KULA VELLALAR | C3: =H3/2 -> 80 | D3: =VLOOKUP(B3,$K$5:$L$15,2,0) -> 41 | E3: =C3-D3 -> 39 | F3: =D3/C3 -> 0.5125 | H3: 160 | K3: Surveyor Name | L3: (All)
A4: VIRALIMALAI | B4: MUKKULATHOR | C4: 65 | D4: =VLOOKUP(B4,$K$5:$L$15,2,0) -> 49 | E4: =C4-D4 -> 16 | F4: =D4/C4 -> 0.75384615 | H4: 129 | K4: Consider | L4: Yes | Q4: Row Labels | R4: Distinct Count of Surveyor Name | S4: Count of Sample ID
A5: VIRALIMALAI | B5: PALLAR SC | C5: =H5/2 -> 50 | D5: =VLOOKUP(B5,$K$5:$L$15,2,0) -> 20 | E5: =C5-D5 -> 30 | F5: =D5/C5 -> 0.4 | H5: 100 | Q5: Subramanian | R5: 7 | S5: 503
A6: VIRALIMALAI | B6: CHOLIA VELLALAR | C6: =H6/2 -> 50 | D6: =VLOOKUP(B6,$K$5:$L$15,2,0) -> 32 | E6: =C6-D6 -> 18 | F6: =D6/C6 -> 0.64 | H6: 100 | K6: Row Labels | L6: Count of Sample ID | Q6: Grand Total | R6: 7 | S6: 503
A7: VIRALIMALAI | B7: URALI GOUNDER | C7: =H7/2 -> 45 | D7: =VLOOKUP(B7,$K$5:$L$15,2,0) -> 29 | E7: =C7-D7 -> 16 | F7: =D7/C7 -> 0.64444444 | H7: 90 | K7: CHOLIA VELLALAR | L7: 32
A8: VIRALIMALAI | B8: MUSLIM | C8: 40 | D8: =VLOOKUP(B8,$K$5:$L$15,2,0) -> 27 | E8: =C8-D8 -> 13 | F8: =D8/C8 -> 0.675 | H8: 81 | K8: CHRISTIAN | L8: 22
A9: VIRALIMALAI | B9: CHRISTIAN | C9: =H9/2 -> 20 | D9: =VLOOKUP(B9,$K$5:$L$15,2,0) -> 22 | E9: =C9-D9 -> -2 | F9: =D9/C9 -> 1.1 | H9: 40 | K9: DEVENDRA KULA VELLALAR | L9: 41
A10: VIRALIMALAI | B10: OTHERS | C10: =H10/2 -> 10 | D10: =VLOOKUP(B10,$K$5:$L$15,2,0) -> 142 | E10: =C10-D10 -> -132 | F10: =D10/C10 -> 14.2 | H10: 20 | K10: MUKKULATHOR | L10: 49
B11: Total | C11: =H11/2 -> 500 | D11: =SUM(D2:D10) -> 420 | E11: =C11-D11 -> 80 | F11: =D11/C11 -> 0.84 | H11: 1000 | K11: MUSLIM | L11: 27
A12: AC NAME | B12: TALUKA/BLOCK | C12: LOCALITY | D12: Required | E12: Collected | F12: Pending | K12: MUTTARAIYAR | L12: 58 | N12: Block | O12: Required | P12: Collected | Q12: Pedning | R12: Collected %
A13: VIRALIMALAI | B13: ILLUPUR | C13: METTUPATTI | D13: 40 | E13: =IFERROR(VLOOKUP(C13,$K$23:$L$46,2,0),0) -> 0 | F13: =D13-E13 -> 40 | K13: Others | L13: 142 | N13: ILLUPUR | O13: 571 | P13: 172 | Q13: =O13-P13 -> 399 | R13: =P13/O13 -> 0.30122592
A14: VIRALIMALAI | B14: ILLUPUR | C14: ELUVAMPATTI | D14: 40 | E14: =IFERROR(VLOOKUP(C14,$K$23:$L$46,2,0),0) -> 0 | F14: =D14-E14 -> 40 | K14: PALLAR SC | L14: 20 | N14: VIRALIMALAI | O14: 332 | P14: 224 | Q14: =O14-P14 -> 108 | R14: =P14/O14 -> 0.6746988
A15: VIRALIMALAI | B15: ILLUPUR | C15: MANGUDI | D15: 40 | E15: =IFERROR(VLOOKUP(C15,$K$23:$L$46,2,0),0) -> 27 | F15: =D15-E15 -> 13 | K15: URALI GOUNDER | L15: 29 | N15: KULATHUR | O15: 97 | P15: 24 | Q15: =O15-P15 -> 73 | R15: =P15/O15 -> 0.24742268
A16: VIRALIMALAI | B16: ILLUPUR | C16: KULATHUR | D16: 40 | E16: =IFERROR(VLOOKUP(C16,$K$23:$L$46,2,0),0) -> 0 | F16: =D16-E16 -> 40 | K16: Grand Total | L16: 420
A17: VIRALIMALAI | B17: ILLUPUR | C17: MALAIKUDIPATTI | D17: 40 | E17: =IFERROR(VLOOKUP(C17,$K$23:$L$46,2,0),0) -> 0 | F17: =D17-E17 -> 40 | K17: Date | L17: (All)
A18: VIRALIMALAI | B18: ILLUPUR | C18: AGARAPATTI | D18: 40 | E18: =IFERROR(VLOOKUP(C18,$K$23:$L$46,2,0),0) -> 0 | F18: =D18-E18 -> 40 | K18: Surveyor Vendor Name | L18: (All)
A19: VIRALIMALAI | B19: ILLUPUR | C19: MEENAVELI | D19: 40 | E19: =IFERROR(VLOOKUP(C19,$K$23:$L$46,2,0),0) -> 0 | F19: =D19-E19 -> 40 | K19: Surveyor Name | L19: (All)
A20: VIRALIMALAI | B20: ILLUPUR | C20: ILLUPUR | D20: 40 | E20: =IFERROR(VLOOKUP(C20,$K$23:$L$46,2,0),0) -> 0 | F20: =D20-E20 -> 40 | K20: Consider | L20: Yes | R20: Consider | S20: Yes
A21: VIRALIMALAI | B21: ILLUPUR | C21: ANNAVASAL | D21: 40 | E21: =IFERROR(VLOOKUP(C21,$K$23:$L$46,2,0),0) -> 49 | F21: =D21-E21 -> -9
A22: VIRALIMALAI | B22: ILLUPUR | C22: MUKKANNAMALAIPATTI | D22: 40 | E22: =IFERROR(VLOOKUP(C22,$K$23:$L$46,2,0),0) -> 23 | F22: =D22-E22 -> 17 | K22: Row Labels | L22: Count of Sample ID | R22: Row Labels | S22: Count of Sample ID
A23: VIRALIMALAI | B23: ILLUPUR | C23: VEERAPATTI | D23: 40 | E23: =IFERROR(VLOOKUP(C23,$K$23:$L$46,2,0),0) -> 0 | F23: =D23-E23 -> 40 | K23: ANNAVASAL | L23: 49 | R23: ஆண்/Male | S23: 0.44047619
A24: VIRALIMALAI | B24: ILLUPUR | C24: KILIKUDI | D24: 40 | E24: =IFERROR(VLOOKUP(C24,$K$23:$L$46,2,0),0) -> 20 | F24: =D24-E24 -> 20 | K24: KILIKUDI | L24: 20 | R24: பெண்/Female | S24: 0.55952381
A25: VIRALIMALAI | B25: ILLUPUR | C25: PARAMBUR | D25: 40 | E25: =IFERROR(VLOOKUP(C25,$K$23:$L$46,2,0),0) -> 23 | F25: =D25-E25 -> 17 | K25: KUDUMIYANMALAI | L25: 30 | R25: Grand Total | S25: 1
A26: VIRALIMALAI | B26: ILLUPUR | C26: KUDUMIYANMALAI | D26: 40 | E26: =IFERROR(VLOOKUP(C26,$K$23:$L$46,2,0),0) -> 30 | F26: =D26-E26 -> 10 | K26: MANGUDI | L26: 27
A27: VIRALIMALAI | B27: VIRALIMALAI | C27: KALKUDI | D27: 40 | E27: =IFERROR(VLOOKUP(C27,$K$23:$L$46,2,0),0) -> 0 | F27: =D27-E27 -> 40 | K27: MUKKANNAMALAIPATTI | L27: 23
A28: VIRALIMALAI | B28: VIRALIMALAI | C28: VELUR | D28: 40 | E28: =IFERROR(VLOOKUP(C28,$K$23:$L$46,2,0),0) -> 0 | F28: =D28-E28 -> 40 | K28: PARAMBUR | L28: 23 | R28: Consider | S28: Yes
A29: VIRALIMALAI | B29: VIRALIMALAI | C29: VIRALIMALAI | D29: 40 | E29: =IFERROR(VLOOKUP(C29,$K$23:$L$46,2,0),0) -> 208 | F29: =D29-E29 -> -168 | K29: VIRALIMALAI | L29: 208
A30: VIRALIMALAI | B30: VIRALIMALAI | C30: ATHIPALLAM | D30: 40 | E30: =IFERROR(VLOOKUP(C30,$K$23:$L$46,2,0),0) -> 0 | F30: =D30-E30 -> 40 | K30: RAJALIPATTI | L30: 16 | R30: Row Labels | S30: Count of Sample ID
A31: VIRALIMALAI | B31: VIRALIMALAI | C31: NAMBANPATTI | D31: 40 | E31: =IFERROR(VLOOKUP(C31,$K$23:$L$46,2,0),0) -> 0 | F31: =D31-E31 -> 40 | K31: MATHUR | L31: 24 | R31: 18-30 | S31: 0.23571429
A32: VIRALIMALAI | B32: VIRALIMALAI | C32: RAJALIPATTI | D32: 40 | E32: =IFERROR(VLOOKUP(C32,$K$23:$L$46,2,0),0) -> 16 | F32: =D32-E32 -> 24 | K32: Grand Total | L32: 420 | R32: 31-45 | S32: 0.31190476
A33: VIRALIMALAI | B33: VIRALIMALAI | C33: KODUMBALUR | D33: 40 | E33: =IFERROR(VLOOKUP(C33,$K$23:$L$46,2,0),0) -> 0 | F33: =D33-E33 -> 40 | R33: 46-60 | S33: 0.29761905
A34: VIRALIMALAI | B34: VIRALIMALAI | C34: RAJAGIRI | D34: 40 | E34: =IFERROR(VLOOKUP(C34,$K$23:$L$46,2,0),0) -> 0 | F34: =D34-E34 -> 40 | R34: 60+ | S34: 0.1547619
A35: VIRALIMALAI | B35: KULATHUR | C35: KUMARAMANGALAM | D35: 40 | E35: =IFERROR(VLOOKUP(C35,$K$23:$L$46,2,0),0) -> 0 | F35: =D35-E35 -> 40 | R35: Grand Total | S35: 1
A36: VIRALIMALAI | B36: KULATHUR | C36: MATHUR | D36: 40 | E36: =IFERROR(VLOOKUP(C36,$K$23:$L$46,2,0),0) -> 24 | F36: =D36-E36 -> 16
A37: VIRALIMALAI | B37: KULATHUR | C37: MANDAIYUR | D37: 40 | E37: =IFERROR(VLOOKUP(C37,$K$23:$L$46,2,0),0) -> 0 | F37: =D37-E37 -> 40
D38: =SUM(D13:D37) -> 1000 | E38: =SUM(E13:E37) -> 420 | F38: =SUM(F13:F37) -> 580 | R38: Consider | S38: Yes
R39: Rev Caste | S39: Others
R41: Row Labels | S41: Count of Sample ID
...

Sheet PPT Pviots
A1: Consider | B1: Yes
I2: Age-Gender & Multi Factor
A3: Row Labels | B3: Count | C3: Raw % | D3: Gender | E3: Age | F3: Age & Gender | G3: 2021 Ae | H3: Caste | I3: Multi Facto
A4: DMK | B4: 129 | C4: 0.30714286 | D4: 0.30724554 | E4: 0.29636953 | F4: 0.3006262 | G4: 0.2156331 | H4: 0.27540574 | I4: 0.21045508
A5: AIADMK | B5: 210 | C5: 0.5 | D5: 0.50776308 | E5: 0.50709017 | F5: 0.50880341 | G5: 0.57843651 | H5: 0.56227123 | I5: 0.59004309
A6: TVK | B6: 29 | C6: 0.069047619 | D6: 0.069752731 | E6: 0.06709881 | F6: 0.071912834 | G6: 0.084441076 | H6: 0.050458263 | I6: 0.0817778
A7: NTK | B7: 3 | C7: 0.0071428571 | D7: 0.0063829787 | E7: 0.0081270722 | F7: 0.0062121212 | G7: 0.0086549606 | H7: 0.0080718796 | I7: 0.0074631049
A8: DMDK | B8: 4 | C8: 0.0095238095 | D8: 0.0096607246 | E8: 0.010414563 | F8: 0.010980908 | G8: 0.010279861 | H8: 0.013673207 | I8: 0.011642549
A9: INC | B9: 3 | C9: 0.0071428571 | D9: 0.007533065 | E9: 0.0073611274 | F9: 0.0061694884 | G9: 0.0075834934 | H9: 0.0088708703 | I9: 0.0068548624
A10: BJP | B10: 4 | C10: 0.0095238095 | D10: 0.0090856814 | E10: 0.011160305 | F10: 0.0087412587 | G10: 0.011907619 | H10: 0.0067772087 | I10: 0.011016804
A11: CPM | B11: 1 | C11: 0.0023809524 | D11: 0.0021276596 | E11: 0.002 | F11: 0.0020833333 | G11: 0.0014093658 | H11: 0.003902439 | I11: 0.0012332053
A12: Others | B12: 37 | C12: 0.088095238 | D12: 0.080448534 | E12: 0.090378417 | F12: 0.084470454 | G12: 0.081654021 | H12: 0.070569165 | I12: 0.079513502
A13: Grand Total | B13: 420 | C13: 1 | D13: 1 | E13: 1 | F13: 1 | G13: 1 | H13: 1 | I13: 1
A17: Consider | B17: Yes
A19: 2021 Ae | B19: Column Labels
A20: Row Labels | B20: DMK | C20: AIADMK | D20: TVK | E20: NTK | F20: DMDK | G20: INC | H20: BJP | I20: CPM | J20: Others | K20: Grand Total
A21: ஆண்/Male | B21: 0.20027175 | C21: 0.68409924 | D21: 0.071041757 | E21: 0 | F21: 0.010487899 | G21: 0.0062081401 | H21: 0.0052439493 | I21: 0 | J21: 0.022647262 | K21: 1
A22: பெண்/Female | B22: 0.22840804 | C22: 0.49056427 | D22: 0.095584343 | E22: 0.01585268 | F22: 0.010106851 | G22: 0.0087272777 | H22: 0.017449322 | I22: 0.0025814359 | J22: 0.13072578 | K22: 1
A23: Grand Total | B23: 0.2156331 | C23: 0.57843651 | D23: 0.084441076 | E23: 0.0086549606 | F23: 0.010279861 | G23: 0.0075834934 | H23: 0.011907619 | I23: 0.0014093658 | J23: 0.081654021 | K23: 1
A26: Consider | B26: Yes
A28: 2021 Ae | B28: Column Labels
A29: Row Labels | B29: DMK | C29: AIADMK | D29: TVK | E29: NTK | F29: DMDK | G29: INC | H29: BJP | I29: CPM | J29: Others | K29: Grand Total
A30: 18-30 | B30: 0.22860506 | C30: 0.43399925 | D30: 0.22555541 | E30: 0.01390823 | F30: 0 | G30: 0 | H30: 0 | I30: 0 | J30: 0.097932053 | K30: 1
A31: 31-45 | B31: 0.15263748 | C31: 0.60542663 | D31: 0.069645063 | E31: 0.016504625 | F31: 0.014243217 | G31: 0.014251762 | H31: 0.028494979 | I31: 0 | J31: 0.098796247 | K31: 1
A32: 46-60 | B32: 0.2438656 | C32: 0.67389673 | D32: 0.025005379 | E32: 0 | F32: 0.010977486 | G32: 0.0049318691 | H32: 0.0083317937 | I32: 0.0049318691 | J32: 0.02805927 | K32: 1
A33: 60+ | B33: 0.28085582 | C33: 0.55430324 | D33: 0.020323333 | E33: 0 | F33: 0.015425191 | G33: 0.0091306896 | H33: 0 | I33: 0 | J33: 0.11996172 | K33: 1
A34: Grand Total | B34: 0.2156331 | C34: 0.57843651 | D34: 0.084441076 | E34: 0.0086549606 | F34: 0.010279861 | G34: 0.0075834934 | H34: 0.011907619 | I34: 0.0014093658 | J34: 0.081654021 | K34: 1
A37: Consider | B37: Yes
A39: 2021 Ae | B39: Column Labels
A40: Row Labels | B40: DMK | C40: AIADMK | D40: TVK | E40: NTK | F40: DMDK | G40: INC | H40: BJP | I40: CPM | J40: Others | K40: Grand Total
A41: ஆண்/Male | B41: 0.20027175 | C41: 0.68409924 | D41: 0.071041757 | E41: 0 | F41: 0.010487899 | G41: 0.0062081401 | H41: 0.0052439493 | I41: 0 | J41: 0.022647262 | K41: 1
A42: 18-30 | B42: 0.14743184 | C42: 0.60150088 | D42: 0.25106729 | E42: 0 | F42: 0 | G42: 0 | H42: 0 | I42: 0 | J42: 0 | K42: 1
A43: 31-45 | B43: 0.196773 | C43: 0.66237419 | D43: 0.064165004 | E43: 0 | F43: 0.023115852 | G43: 0 | H43: 0 | I43: 0 | J43: 0.053571951 | K43: 1
A44: 46-60 | B44: 0.18601681 | C44: 0.790918 | D44: 0 | E44: 0 | F44: 0 | G44: 0.0085764011 | H44: 0.014488788 | I44: 0 | J44: 0 | K44: 1
A45: 60+ | B45: 0.27693567 | C45: 0.60259051 | D45: 0.032323311 | E45: 0 | F45: 0.024533046 | G45: 0.014521935 | H45: 0 | I45: 0 | J45: 0.049095529 | K45: 1
A46: பெண்/Female | B46: 0.22840804 | C46: 0.49056427 | D46: 0.095584343 | E46: 0.01585268 | F46: 0.010106851 | G46: 0.0087272777 | H46: 0.017449322 | I46: 0.0025814359 | J46: 0.13072578 | K46: 1
A47: 18-30 | B47: 0.28215863 | C47: 0.32349099 | D47: 0.20872409 | E47: 0.023084107 | F47: 0 | G47: 0 | H47: 0 | I47: 0 | J47: 0.16254218 | K47: 1
A48: 31-45 | B48: 0.13298567 | C48: 0.58007011 | D48: 0.072085118 | E48: 0.023853486 | F48: 0.010292581 | G48: 0.020597512 | H48: 0.041182674 | I48: 0 | J48: 0.11893285 | K48: 1
A49: 46-60 | B49: 0.32214799 | C49: 0.5155407 | D49: 0.058843264 | E49: 0 | F49: 0.025832486 | G49: 0 | H49: 0 | I49: 0.011605794 | J49: 0.066029756 | K49: 1
A50: 60+ | B50: 0.28749505 | C50: 0.47252324 | D50: 0 | E50: 0 | F50: 0 | G50: 0 | H50: 0 | I50: 0 | J50: 0.23998171 | K50: 1
...

Sheet Factor
F3: Party | G3: 2021
F4: ADMK | G4: 0.52826706
F5: DMK | G5: 0.40626503
A6: Consider | B6: Yes | F6: NTK | G6: 0.036371062
F7: Others | G7: =1-SUM(G4:G6) -> 0.02909685
A8: Row Labels | B8: Count | C8: %
A9: அதிமுக கூட்டணி / AIADMK Alliance | B9: 85 | C9: 85 | F9: 2021 Ae | G9: TBT | H9: Collected | I9: Collected % | J9: Factor
A10: திமுக கூட்டணி / DMK Alliance | B10: 221 | C10: 221 | F10: அதிமுக கூட்டணி / AIADMK Alliance | G10: 0.52826706 | H10: =VLOOKUP(F10,$A$8:$B$14,2,0) -> 85 | I10: =H10/SUM($H$10:$H$12) -> 0.26397516 | J10: =G10/I10 -> 2.0011999
A11: பிற கட்சிகள் / Others | B11: 16 | C11: 16 | F11: திமுக கூட்டணி / DMK Alliance | G11: 0.40626503 | H11: =VLOOKUP(F11,$A$8:$B$14,2,0) -> 221 | I11: =H11/SUM($H$10:$H$12) -> 0.6863354 | J11: =G11/I11 -> 0.59193366
A12: நினைவில் இல்லை / Don’t Remember | B12: 75 | C12: 75 | F12: பிற கட்சிகள் / Others | G12: =1-SUM(G10:G11) -> 0.065467912 | H12: =VLOOKUP(F12,$A$8:$B$14,2,0) -> 16 | I12: =H12/SUM($H$10:$H$12) -> 0.049689441 | J12: =G12/I12 -> 1.3175417
A13: வாக்களிக்கவில்லை / Did not Vote | B13: 23 | C13: 23 | F13: நினைவில் இல்லை / Don’t Remember | J13: 1
A14: Grand Total | B14: 420 | C14: 420 | F14: வாக்களிக்கவில்லை / Did not Vote | J14: 1
A25: Consider | B25: Yes
F26: Gender | G26: TBT | H26: Collected | I26: Factor
A27: Row Labels | B27: Count | C27: % | F27: ஆண்/Male | G27: 0.5 | H27: =VLOOKUP(F27,$A$28:$C$29,3,0) -> 0.44047619 | I27: =G27/H27 -> 1.1351351
A28: ஆண்/Male | B28: 185 | C28: 0.44047619 | F28: பெண்/Female | G28: 0.5 | H28: =VLOOKUP(F28,$A$28:$C$29,3,0) -> 0.55952381 | I28: =G28/H28 -> 0.89361702
A29: பெண்/Female | B29: 235 | C29: 0.55952381
A30: Grand Total | B30: 420 | C30: 1
A33: Consider | B33: Yes
A35: Row Labels | B35: Count | C35: % | F35: Age | G35: TBT | H35: Collected | I35: Factor
A36: 18-30 | B36: 99 | C36: 0.23571429 | F36: 18-30 | G36: 0.2 | H36: =VLOOKUP(F36,$A$35:$C$40,3,0) -> 0.23571429 | I36: =G36/H36 -> 0.84848485
A37: 31-45 | B37: 131 | C37: 0.31190476 | F37: 31-45 | G37: 0.4 | H37: =VLOOKUP(F37,$A$35:$C$40,3,0) -> 0.31190476 | I37: =G37/H37 -> 1.2824427
A38: 46-60 | B38: 125 | C38: 0.29761905 | F38: 46-60 | G38: 0.25 | H38: =VLOOKUP(F38,$A$35:$C$40,3,0) -> 0.29761905 | I38: =G38/H38 -> 0.84
A39: 60+ | B39: 65 | C39: 0.1547619 | F39: 60+ | G39: 0.15 | H39: =VLOOKUP(F39,$A$35:$C$40,3,0) -> 0.1547619 | I39: =G39/H39 -> 0.96923077
A40: Grand Total | B40: 420 | C40: 1
B43: Consider | C43: Yes
B45: பதிலளித்தவரின் வயது/Age Group | C45: பாலினம்/Gender | D45: Count | E45: % | F45: TBT | G45: Factor
A46: =B46&C46 -> 18-30ஆண்/Male | B46: 18-30 | C46: ஆண்/Male | D46: 39 | E46: 0.092857143 | F46: 0.1 | G46: =F46/E46 -> 1.0769231
A47: =B47&C47 -> 18-30பெண்/Female | B47: 18-30 | C47: பெண்/Female | D47: 60 | E47: 0.14285714 | F47: 0.1 | G47: =F47/E47 -> 0.7
A48: =B48&C48 -> 31-45ஆண்/Male | B48: 31-45 | C48: ஆண்/Male | D48: 43 | E48: 0.10238095 | F48: 0.2 | G48: =F48/E48 -> 1.9534884
A49: =B49&C49 -> 31-45பெண்/Female | B49: 31-45 | C49: பெண்/Female | D49: 88 | E49: 0.20952381 | F49: 0.2 | G49: =F49/E49 -> 0.95454545
A50: =B50&C50 -> 46-60ஆண்/Male | B50: 46-60 | C50: ஆண்/Male | D50: 65 | E50: 0.1547619 | F50: 0.125 | G50: =F50/E50 -> 0.80769231
A51: =B51&C51 -> 46-60பெண்/Female | B51: 46-60 | C51: பெண்/Female | D51: 60 | E51: 0.14285714 | F51: 0.125 | G51: =F51/E51 -> 0.875
A52: =B52&C52 -> 60+ஆண்/Male | B52: 60+ | C52: ஆண்/Male | D52: 38 | E52: 0.09047619 | F52: 0.075 | G52: =F52/E52 -> 0.82894737
A53: =B53&C53 -> 60+பெண்/Female | B53: 60+ | C53: பெண்/Female | D53: 27 | E53: 0.064285714 | F53: 0.075 | G53: =F53/E53 -> 1.1666667
B54: Grand Total | D54: 420 | E54: 1
B58: Consider | C58: Yes
F59: Caste | G59: TBT | H59: Collected | I59: Factor
B60: Row Labels | C60: Count | D60: % | F60: MUTTARAIYAR | G60: 0.28 | H60: =VLOOKUP(F60,$B$61:$D$70,3,0) -> 0.13809524 | I60: =G60/H60 -> 2.0275862
B61: CHOLIA VELLALAR | C61: 32 | D61: 0.076190476 | F61: DEVENDRA KULA VELLALAR | G61: 0.16 | H61: =VLOOKUP(F61,$B$61:$D$70,3,0) -> 0.097619048 | I61: =G61/H61 -> 1.6390244
...

Sheet Data
A1: Sample ID | B1: Timestamp | C1: Date | D1: Location | E1: Address | F1: Audio Url | G1: Audio Duration (in secs) | H1: Offline Mode | I1: Surveyor Name | J1: Surveyor Phone Number | K1: Surveyor Vendor Name | L1: TALUKA/BLOCK | M1: LOCALITY | N1: பதிலளிப்பவர் பெயர்/Respondent Name | O1: பாலினம்/Gender | P1: பதிலளித்தவரின் மொபைல் எண்/Mobile Number | Q1: பதிலளித்தவரின் வயது/Age Group | R1: தொழில்/Occupation | S1: மாத வருமானம்/Monthly Income | T1: தமிழக முதல்வர் மு.க. ஸ்டாலின் தலைமையிலான தற்போதைய திமுக அரசின் செயல்திறனை நீங்கள் எப்படி மதிப்பீடு செய்கிறீர்கள்?/ How would you rate the performance of the current DMK-led government under Chief Minister M.K. Stalin? | U1: 2026 சட்டமன்றத் தேர்தலில் ஆட்சி மாற்றம் தேவை என நீங்கள் கருதுகிறீர்களா?/ Do you feel a change in government is needed in the 2026 assembly Elections? | V1: 2021 சட்டமன்றத் தேர்தலில் நீங்கள் எந்தக் கட்சிக்கு வாக்களித்தீர்கள்?/ Which party did you vote in 2021 Assembly Elections? | W1: தமிழகத்தின் அடுத்த முதல்வராக யாருக்கு நீங்கள் ஆதரவு அளிக்க விரும்புகிறீர்கள்?/ Who would you support as Tamil Nadu’s next Chief Minister? | X1: உங்கள் தொகுதியில் வெற்றி பெற வாய்ப்புள்ள கட்சி/கூட்டணி எது என நீங்கள் கருதுகிறீர்கள்?/ Which party/alliance do you think will win in your constituency? | Y1: நீங்கள் விரும்பும் கட்சி (வினா 13 இல் தெரிவுசெய்தது) தமிழக வெற்றி கழகத்துடன் கூட்டணி அமைத்தால், நீங்கள் அந்த கூட்டணிக்கு வாக்களிக்கிறீர்களா? (இந்த வினா AIADMK, NTK, PMK, DMDK, அல்லது INC-ஐ தேர்ந்தெடுத்தவர்களுக்கே लागू) / If your preferred party (in quest | Z1: விஜயின் அரசியல் வருகை 2026 தேர்தலில் குறிப்பிடத்தக்க தாக்கத்தை ஏற்படுத்தும் என நீங்கள் நம்புகிறீர்களா?/ Do you believe Vijay’s political entry will significantly impact the 2026 elections? | AA1: உங்கள் பதில் "ஆமாம்" எனில், விஜயின் அரசியல் வருகையால் அதிகம் பாதிக்கப்படக்கூடிய கட்சி/கூட்டணி எது? / If yes, which party/alliance will be most affected by Vijay’s entry? | AB1: தமிழக வெற்றி கழகம் (TVK) தற்போது எப்படி செயல்படுகிறது என நீங்கள் மதிப்பீடு செய்கிறீர்கள்? / How would you rate Tamilaga Vettri Kazhagam’s (TVK) current performance? | AC1: சமூக பிரச்சனைகளைத் தீர்க்கும் முயற்சிகளில் விஜய் எவ்வளவு பயனுள்ளதாக இருந்துள்ளார்?/ How effective has Vijay been in addressing social issues? | AD1: திமுக அல்லது அதிமுக கூட்டணிகள் 2026க்கு முந்தைய காலத்தில் உடைந்துவிடும் என நீங்கள் கருதுகிறீர்களா? / Do you foresee the DMK or AIADMK alliances breaking apart before 2026? | AE1: எந்தக் கூட்டணியில் விஜயின் கட்சி (TVK) சேரவேண்டும் என நீங்கள் விரும்புகிறீர்கள்?/ Which alliance would you prefer Vijay’s party (TVK) to join, if any? | AF1: தற்போதைய தமிழகத்தில் மிக முக்கியமான பிரச்சனை எது என நீங்கள் கருதுகிறீர்கள்?/ What is the most critical issue facing Tamil Nadu today? | AG1: சாதி வகை/Caste Category | AH1: சாதி/Caste | AI1: QC Comment | AJ1: QC Remark | AK1: QC User Name | AL1: QC Date | AM1: App Version | AN1: Consider | AO1: Time | AP1: Rev Party | AQ1: Rev Caste | AR1: Gender Factor | AS1: Age Factor | AT1: Age & Gender Factor | AU1: 2021 Ae Factor | AV1: Caste Factor | AW1: Multi Factor | AX1: Lat | AY1: Long
A2: wCoRngjNmpdXwr8jpUtS | B2: 2025-07-30 11:50:28.774519 | C2: 45868 | D2: (10.4599207, 78.7030535) | E2: 55,,Annavasal,622101,Tamil Nadu,India. | F2: https://firebasestorage.googleapis.com/v0/b/mindbrink-survey-production.appspot.com/o/audioFiles%2FAtznECuQc6klLPsRR6u2%2FnV4IA56gMWWp4NfG0H1PGfyqfM92%2F2025-07-30%2011%3A50%3A15.491639.m4a?alt=media&token=23fd1b60-6ea5-4086-a9e0-12b2896623eb | G2: 474 | H2: false | I2: G.muthukumar | J2: +918940041476 | K2: Subramanian | L2: VIRALIMALAI | M2: ATHIPALLAM | N2: sinnathuri | O2: ஆண்/Male | P2: 9486664057 | Q2: 31-45 | R2: கூலி தொழில்/ Daily Wage | S2: 10,000 - 25,000 | T2: திருப்திகரமானது / Satisfactory | U2: இல்லை/ No | V2: திமுக கூட்டணி / DMK Alliance | W2: மு.க. ஸ்டாலின் (திமுக) / M.K. Stalin (DMK) | X2: திமுக / DMK | Y2: - | Z2: இல்லை / No | AA2: - | AB2: திருப்திகரமல்ல / Unsatisfactory | AC2: குறைவான ஈடுபாடு / Inadequate | AD2: • இல்லை: திமுக மற்றும் அதிமுக கூட்டணிகள் இரண்டும் உடையாது/ No: Both DMK & AIADMK alliances will not break up | AE2: தனித்துப் போட்டியிட வேண்டும் / Contest Independently | AF2: மதுபானம் / போதைப்பொருள் பழக்கம்/ Alcohol/Drug abuse | AG2: OBC | AH2: URALI GOUNDER | AI2: =IFERROR(_xlfn.XLOOKUP(Table1[[#This Row],[Audio Url]],Qc!C:C,Qc!F:F),"") -> speaking among themselves | AJ2: =IFERROR(_xlfn.XLOOKUP(Table1[[#This Row],[Audio Url]],Qc!C:C,Qc!E:E),"") -> Fake Audio/Empty Audio | AK2: - | AL2: - | AM2: 0.1.12 (60) | AN2: No | AO2: =IF(Table1[[#This Row],[Audio Duration (in secs)]]>180,"Greater than 3 Minutes","Less than 3 Minutes") -> Greater than 3 Minutes | AP2: =VLOOKUP(Table1[[#This Row],[உங்கள் தொகுதியில் வெற்றி பெற வாய்ப்புள்ள கட்சி/கூட்டணி எது என நீங்கள் கருதுகிறீர்கள்?/ Which party/alliance do you think will win in your constituency? ]],MApping!$A$1:$B$13,2,0) -> DMK | AQ2: =IFERROR(VLOOKUP(Table1[[#This Row],[சாதி/Caste]],MApping!$E$1:$F$10,2,0),"Others") -> URALI GOUNDER | AR2: =VLOOKUP(Table1[[#This Row],[பாலினம்/Gender]],Factor!$F$26:$I$28,4,0) -> 1.1351351 | AS2: =VLOOKUP(Table1[[#This Row],[பதிலளித்தவரின் வயது/Age Group]],Factor!$F$35:$I$39,4,0) -> 1.2824427 | AT2: =VLOOKUP(Table1[[#This Row],[பதிலளித்தவரின் வயது/Age Group]]&Table1[[#This Row],[பாலினம்/Gender]],Factor!$A$45:$G$53,7,0) -> 1.9534884 | AU2: =VLOOKUP(Table1[[#This Row],[2021 சட்டமன்றத் தேர்தலில் நீங்கள் எந்தக் கட்சிக்கு வாக்களித்தீர்கள்?/ Which party did you vote in 2021 Assembly Elections? ]],Factor!$F$9:$J$14,5,0) -> 0.59193366 | AV2: =VLOOKUP(Table1[[#This Row],[Rev Caste]],Factor!$F$59:$I$68,4,0) -> 1.3034483 | AW2: =Table1[[#This Row],[2021 Ae Factor]]*Table1[[#This Row],[Age & Gender Factor]] -> 1.1563355 | AX2: =VALUE(MID(D2,2,FIND(",",D2)-2)) -> 10.459921 | AY2: =VALUE(MID(D2, FIND(",",D2)+2, FIND(")",D2)-FIND(",",D2)-2)) -> 78.703053
A3: DK5RFIfUeSBZOmSRQwlG | B3: 2025-07-30 13:47:12.018718 | C3: 45868 | D3: (10.4596218, 78.7023729) | E3: FP52+XV3,,Annavasal,622101,Tamil Nadu,India. | F3: https://firebasestorage.googleapis.com/v0/b/mindbrink-survey-production.appspot.com/o/audioFiles%2FAtznECuQc6klLPsRR6u2%2Fe5risFoEPidDckOLperfsZqxzae2%2F2025-07-30%2013%3A47%3A06.589839.m4a?alt=media&token=491fc27d-ed7b-4fbf-88ba-a7af8002c801 | G3: 675 | H3: false | I3: Sinthanai selvi | J3: +918508766594 | K3: Subramanian | L3: ILLUPUR | M3: ANNAVASAL | N3: raja | O3: ஆண்/Male | P3: 8675641312 | Q3: 18-30 | R3: மாணவர்/ Student | S3: 10,000 - 25,000 | T3: திருப்திகரமானது / Satisfactory | U3: ஆம் / Yes | V3: திமுக கூட்டணி / DMK Alliance | W3: மு.க. ஸ்டாலின் (திமுக) / M.K. Stalin (DMK) | X3: திமுக / DMK | Y3: - | Z3: இல்லை / No | AA3: - | AB3: வேகம் குறைபாடுடன் செயல்படுகிறது / Needs more momentum | AC3: பயனில்லை / Not effective | AD3: • ஆமாம்: அதிமுக கூட்டணி உடையும்/ Yes: AIADMK alliance will break up | AE3: நாம் தமிழர் கட்சி / NTK | AF3: மதுபானம் / போதைப்பொருள் பழக்கம்/ Alcohol/Drug abuse | AG3: BC | AH3: MUKKULATHOR | AI3: =IFERROR(_xlfn.XLOOKUP(Table1[[#This Row],[Audio Url]],Qc!C:C,Qc!F:F),"") -> they only speaking amkn6them but questions are only read | AJ3: =IFERROR(_xlfn.XLOOKUP(Table1[[#This Row],[Audio Url]],Qc!C:C,Qc!E:E),"") -> Not Doing It Properly | AK3: - | AL3: - | AM3: 0.1.12 (60) | AN3: Yes | AO3: =IF(Table1[[#This Row],[Audio Duration (in secs)]]>180,"Greater than 3 Minutes","Less than 3 Minutes") -> Greater than 3 Minutes | AP3: =VLOOKUP(Table1[[#This Row],[உங்கள் தொகுதியில் வெற்றி பெற வாய்ப்புள்ள கட்சி/கூட்டணி எது என நீங்கள் கருதுகிறீர்கள்?/ Which party/alliance do you think will win in your constituency? ]],MApping!$A$1:$B$13,2,0) -> DMK | AQ3: =IFERROR(VLOOKUP(Table1[[#This Row],[சாதி/Caste]],MApping!$E$1:$F$10,2,0),"Others") -> MUKKULATHOR | AR3: =VLOOKUP(Table1[[#This Row],[பாலினம்/Gender]],Factor!$F$26:$I$28,4,0) -> 1.1351351 | AS3: =VLOOKUP(Table1[[#This Row],[பதிலளித்தவரின் வயது/Age Group]],Factor!$F$35:$I$39,4,0) -> 0.84848485 | AT3: =VLOOKUP(Table1[[#This Row],[பதிலளித்தவரின் வயது/Age Group]]&Table1[[#This Row],[பாலினம்/Gender]],Factor!$A$45:$G$53,7,0) -> 1.0769231 | AU3: =VLOOKUP(Table1[[#This Row],[2021 சட்டமன்றத் தேர்தலில் நீங்கள் எந்தக் கட்சிக்கு வாக்களித்தீர்கள்?/ Which party did you vote in 2021 Assembly Elections? ]],Factor!$F$9:$J$14,5,0) -> 0.59193366 | AV3: =VLOOKUP(Table1[[#This Row],[Rev Caste]],Factor!$F$59:$I$68,4,0) -> 1.1057143 | AW3: =Table1[[#This Row],[2021 Ae Factor]]*Table1[[#This Row],[Age & Gender Factor]] -> 0.63746702 | AX3: =VALUE(MID(D3,2,FIND(",",D3)-2)) -> 10.459622 | AY3: =VALUE(MID(D3, FIND(",",D3)+2, FIND(")",D3)-FIND(",",D3)-2)) -> 78.702373
A4: RdafTkFtqCYc1Xw504xM | B4: 2025-07-30 14:00:49.781847 | C4: 45868 | D4: (10.4595158, 78.7023314) | E4: FP53+P33,,Purakarai Natham Pannai,622005,Tamil Nadu,India. | F4: https://firebasestorage.googleapis.com/v0/b/mindbrink-survey-production.appspot.com/o/audioFiles%2FAtznECuQc6klLPsRR6u2%2Fe5risFoEPidDckOLperfsZqxzae2%2F2025-07-30%2014%3A00%3A45.291038.m4a?alt=media&token=cecc8db3-cd5a-48ee-a3e6-d691de1219b0 | G4: 427 | H4: false | I4: Sinthanai selvi | J4: +918508766594 | K4: Subramanian | L4: ILLUPUR | M4: ANNAVASAL | N4: முருகேசன் | O4: ஆண்/Male | P4: 8012825692 | Q4: 46-60 | R4: சொந்த தொழில் / சுயதொழில் செய்பவர்/ Self Employed/Business | S4: 50,000 - 1,00,000 | T4: திருப்திகரமல்ல/ Unsatisfactory | U4: ஆம் / Yes | V4: அதிமுக கூட்டணி / AIADMK Alliance | W4: எடப்பாடி பழனிசாமி (அதிமுக) / Edappadi K. Palaniswami (AIADMK) | X4: அதிமுக / AIADMK | Y4: ஆம், TVK கூட்டணிக்கு வாக்களிப்பேன் / Yes, I will shift my vote to the TVK alliance | Z4: இல்லை / No | AA4: - | AB4: திருப்திகரமல்ல / Unsatisfactory | AC4: பயனில்லை / Not effective | AD4: • ஆமாம்: திமுக கூட்டணி உடையும் / Yes: DMK Alliance will break up | AE4: அதிமுக / AIADMK | AF4: விவசாய நெருக்கடி / Agricultural crisis | AG4: BC | AH4: - | AI4: =IFERROR(_xlfn.XLOOKUP(Table1[[#This Row],[Audio Url]],Qc!C:C,Qc!F:F),"") -> same voice | AJ4: =IFERROR(_xlfn.XLOOKUP(Table1[[#This Row],[Audio Url]],Qc!C:C,Qc!E:E),"") -> Taking From Friends And Family | AK4: - | AL4: - | AM4: 0.1.12 (60) | AN4: No | AO4: =IF(Table1[[#This Row],[Audio Duration (in secs)]]>180,"Greater than 3 Minutes","Less than 3 Minutes") -> Greater than 3 Minutes | AP4: =VLOOKUP(Table1[[#This Row],[உங்கள் தொகுதியில் வெற்றி பெற வாய்ப்புள்ள கட்சி/கூட்டணி எது என நீங்கள் கருதுகிறீர்கள்?/ Which party/alliance do you think will win in your constituency? ]],MApping!$A$1:$B$13,2,0) -> AIADMK | AQ4: =IFERROR(VLOOKUP(Table1[[#This Row],[சாதி/Caste]],MApping!$E$1:$F$10,2,0),"Others") -> Others | AR4: =VLOOKUP(Table1[[#This Row],[பாலினம்/Gender]],Factor!$F$26:$I$28,4,0) -> 1.1351351 | AS4: =VLOOKUP(Table1[[#This Row],[பதிலளித்தவரின் வயது/Age Group]],Factor!$F$35:$I$39,4,0) -> 0.84 | AT4: =VLOOKUP(Table1[[#This Row],[பதிலளித்தவரின் வயது/Age Group]]&Table1[[#This Row],[பாலினம்/Gender]],Factor!$A$45:$G$53,7,0) -> 0.80769231 | AU4: =VLOOKUP(Table1[[#This Row],[2021 சட்டமன்றத் தேர்தலில் நீங்கள் எந்தக் கட்சிக்கு வாக்களித்தீர்கள்?/ Which party did you vote in 2021 Assembly Elections? ]],Factor!$F$9:$J$14,5,0) -> 2.0011999 | AV4: =VLOOKUP(Table1[[#This Row],[Rev Caste]],Factor!$F$59:$I$68,4,0) -> 0.05915493 | AW4: =Table1[[#This Row],[2021 Ae Factor]]*Table1[[#This Row],[Age & Gender Factor]] -> 1.6163538 | AX4: =VALUE(MID(D4,2,FIND(",",D4)-2)) -> 10.459516 | AY4: =VALUE(MID(D4, FIND(",",D4)+2, FIND(")",D4)-FIND(",",D4)-2)) -> 78.702331
A5: jXAWjqyIxq87qPMieuPS | B5: 2025-07-30 14:19:29.593894 | C5: 45868 | D5: (10.4623883, 78.6815105) | E5: FM6J+JHW,,Pudukkottai,622103,Tamil Nadu,India. | F5: https://firebasestorage.googleapis.com/v0/b/mindbrink-survey-production.appspot.com/o/audioFiles%2FAtznECuQc6klLPsRR6u2%2F2ukCmICpvKWhqTT6dgmjG6nFGjc2%2F2025-07-30%2014%3A19%3A23.528277.m4a?alt=media&token=2a8a1c48-d5a0-40e2-b2c9-f58e1c5cbbb7 | G5: 347 | H5: false | I5: U.Amir nisha | J5: +919698565662 | K5: Subramanian | L5: ILLUPUR | M5: MUKKANNAMALAIPATTI | N5: Rathinam | O5: ஆண்/Male | P5: 8012352247 | Q5: 31-45 | R5: கூலி தொழில்/ Daily Wage | S5: 10,000க்கும் குறைவானது/Less than 10,000 | T5: திருப்திகரமல்ல/ Unsatisfactory | U5: ஆம் / Yes | V5: திமுக கூட்டணி / DMK Alliance | W5: Others | X5: தமிழக வெற்றி கழகம் / TVK | Y5: - | Z5: இல்லை / No | AA5: - | AB5: வேகம் குறைபாடுடன் செயல்படுகிறது / Needs more momentum | AC5: குறைவான ஈடுபாடு / Inadequate | AD5: • ஆமாம்: திமுக மற்றும் அதிமுக கூட்டணிகள் இரண்டும் உடையும்/ Yes: Both DMK & AIADMK alliances will break up | AE5: தனித்துப் போட்டியிட வேண்டும் / Contest Independently | AF5: வேலைவாய்ப்பு குறைபாடு / Unemployment | AG5: SC | AH5: PALLAR SC | AI5: =IFERROR(_xlfn.XLOOKUP(Table1[[#This Row],[Audio Url]],Qc!C:C,Qc!F:F),"") -> same voice | AJ5: =IFERROR(_xlfn.XLOOKUP(Table1[[#This Row],[Audio Url]],Qc!C:C,Qc!E:E),"") -> Taking From Friends And Family | AK5: - | AL5: - | AM5: 0.1.12 (60) | AN5: No | AO5: =IF(Table1[[#This Row],[Audio Duration (in secs)]]>180,"Greater than 3 Minutes","Less than 3 Minutes") -> Greater than 3 Minutes | AP5: =VLOOKUP(Table1[[#This Row],[உங்கள் தொகுதியில் வெற்றி பெற வாய்ப்புள்ள கட்சி/கூட்டணி எது என நீங்கள் கருதுகிறீர்கள்?/ Which party/alliance do you think will win in your constituency? ]],MApping!$A$1:$B$13,2,0) -> TVK | AQ5: =IFERROR(VLOOKUP(Table1[[#This Row],[சாதி/Caste]],MApping!$E$1:$F$10,2,0),"Others") -> PALLAR SC | AR5: =VLOOKUP(Table1[[#This Row],[பாலினம்/Gender]],Factor!$F$26:$I$28,4,0) -> 1.1351351 | AS5: =VLOOKUP(Table1[[#This Row],[பதிலளித்தவரின் வயது/Age Group]],Factor!$F$35:$I$39,4,0) -> 1.2824427 | AT5: =VLOOKUP(Table1[[#This Row],[பதிலளித்தவரின் வயது/Age Group]]&Table1[[#This Row],[பாலினம்/Gender]],Factor!$A$45:$G$53,7,0) -> 1.9534884 | AU5: =VLOOKUP(Table1[[#This Row],[2021 சட்டமன்றத் தேர்தலில் நீங்கள் எந்தக் கட்சிக்கு வாக்களித்தீர்கள்?/ Which party did you vote in 2021 Assembly Elections? ]],Factor!$F$9:$J$14,5,0) -> 0.59193366 | AV5: =VLOOKUP(Table1[[#This Row],[Rev Caste]],Factor!$F$59:$I$68,4,0) -> 2.1 | AW5: =Table1[[#This Row],[2021 Ae Factor]]*Table1[[#This Row],[Age & Gender Factor]] -> 1.1563355 | AX5: =VALUE(MID(D5,2,FIND(",",D5)-2)) -> 10.462388 | AY5: =VALUE(MID(D5, FIND(",",D5)+2, FIND(")",D5)-FIND(",",D5)-2)) -> 78.681511
A6: inwjrr2qGauklkuB5CLS | B6: 2025-07-30 14:26:30.602916 | C6: 45868 | D6: (10.4623704, 78.681544) | E6: FM6J+JHW,,Pudukkottai,622103,Tamil Nadu,India. | F6: https://firebasestorage.googleapis.com/v0/b/mindbrink-survey-production.appspot.com/o/audioFiles%2FAtznECuQc6klLPsRR6u2%2F2ukCmICpvKWhqTT6dgmjG6nFGjc2%2F2025-07-30%2014%3A26%3A24.415606.m4a?alt=media&token=94a2343f-ce0d-4c6c-812f-f12d4d988ffa | G6: 301 | H6: false | I6: U.Amir nisha | J6: +919698565662 | K6: Subramanian | L6: ILLUPUR | M6: MUKKANNAMALAIPATTI | N6: Albert Xavier | O6: ஆண்/Male | P6: 7708200630 | Q6: 31-45 | R6: விவசாயி/ Farmer | S6: 10,000க்கும் குறைவானது/Less than 10,000 | T6: திருப்திகரமல்ல/ Unsatisfactory | U6: ஆம் / Yes | V6: திமுக கூட்டணி / DMK Alliance | W6: விஜய் (தமிழக வெற்றி கழகம்) / Vijay (TVK) | X6: அதிமுக / AIADMK | Y6: ஆம், TVK கூட்டணிக்கு வாக்களிப்பேன் / Yes, I will shift my vote to the TVK alliance | Z6: ஆமாம் / Yes | AA6: திமுக கூட்டணி / DMK Alliance | AB6: வேகம் குறைபாடுடன் செயல்படுகிறது / Needs more momentum | AC6: போதுமான ஈடுபாடு / Adequate | AD6: • ஆமாம்: திமுக மற்றும் அதிமுக கூட்டணிகள் இரண்டும் உடையும்/ Yes: Both DMK & AIADMK alliances will break up | AE6: தே.மு.தி.க / DMDK | AF6: விவசாய நெருக்கடி / Agricultural crisis | AG6: BC | AH6: CHRISTIAN | AI6: =IFERROR(_xlfn.XLOOKUP(Table1[[#This Row],[Audio Url]],Qc!C:C,Qc!F:F),"") -> same voice | AJ6: =IFERROR(_xlfn.XLOOKUP(Table1[[#This Row],[Audio Url]],Qc!C:C,Qc!E:E),"") -> Taking From Friends And Family | AK6: - | AL6: - | AM6: 0.1.12 (60) | AN6: No | AO6: =IF(Table1[[#This Row],[Audio Duration (in secs)]]>180,"Greater than 3 Minutes","Less than 3 Minutes") -> Greater than 3 Minutes | AP6: =VLOOKUP(Table1[[#This Row],[உங்கள் தொகுதியில் வெற்றி பெற வாய்ப்புள்ள கட்சி/கூட்டணி எது என நீங்கள் கருதுகிறீர்கள்?/ Which party/alliance do you think will win in your constituency? ]],MApping!$A$1:$B$13,2,0) -> AIADMK | AQ6: =IFERROR(VLOOKUP(Table1[[#This Row],[சாதி/Caste]],MApping!$E$1:$F$10,2,0),"Others") -> CHRISTIAN | AR6: =VLOOKUP(Table1[[#This Row],[பாலினம்/Gender]],Factor!$F$26:$I$28,4,0) -> 1.1351351 | AS6: =VLOOKUP(Table1[[#This Row],[பதிலளித்தவரின் வயது/Age Group]],Factor!$F$35:$I$39,4,0) -> 1.2824427 | AT6: =VLOOKUP(Table1[[#This Row],[பதிலளித்தவரின் வயது/Age Group]]&Table1[[#This Row],[பாலினம்/Gender]],Factor!$A$45:$G$53,7,0) -> 1.9534884 | AU6: =VLOOKUP(Table1[[#This Row],[2021 சட்டமன்றத் தேர்தலில் நீங்கள் எந்தக் கட்சிக்கு வாக்களித்தீர்கள்?/ Which party did you vote in 2021 Assembly Elections? ]],Factor!$F$9:$J$14,5,0) -> 0.59193366 | AV6: =VLOOKUP(Table1[[#This Row],[Rev Caste]],Factor!$F$59:$I$68,4,0) -> 0.76363636 | AW6: =Table1[[#This Row],[2021 Ae Factor]]*Table1[[#This Row],[Age & Gender Factor]] -> 1.1563355 | AX6: =VALUE(MID(D6,2,FIND(",",D6)-2)) -> 10.46237 | AY6: =VALUE(MID(D6, FIND(",",D6)+2, FIND(")",D6)-FIND(",",D6)-2)) -> 78.681544
A7: oYxHjk6VwK6zG0z9HzLl | B7: 2025-07-30 14:35:10.789469 | C7: 45868 | D7: (10.4623843, 78.6815277) | E7: FM6J+JHW,,Pudukkottai,622103,Tamil Nadu,India. | F7: https://firebasestorage.googleapis.com/v0/b/mindbrink-survey-production.appspot.com/o/audioFiles%2FAtznECuQc6klLPsRR6u2%2F2ukCmICpvKWhqTT6dgmjG6nFGjc2%2F2025-07-30%2014%3A35%3A02.869454.m4a?alt=media&token=66fec1a3-fae7-4769-b641-1ce8faff9d0d | G7: 269 | H7: false | I7: U.Amir nisha | J7: +919698565662 | K7: Subramanian | L7: ILLUPUR | M7: MUKKANNAMALAIPATTI | N7: Jaya | O7: பெண்/Female | P7: 8807414653 | Q7: 31-45 | R7: இல்லத்தரசி/ Housewife | S7: 10,000க்கும் குறைவானது/Less than 10,000 | T7: மேம்பாடு தேவை / Needs improvement | U7: ஆம் / Yes | V7: அதிமுக கூட்டணி / AIADMK Alliance | W7: மு.க. ஸ்டாலின் (திமுக) / M.K. Stalin (DMK) | X7: திமுக / DMK | Y7: - | Z7: ஆமாம் / Yes | AA7: பிறவை / Others | AB7: திருப்திகரமானது / Satisfactory | AC7: போதுமான ஈடுபாடு / Adequate | AD7: • ஆமாம்: திமுக கூட்டணி உடையும் / Yes: DMK Alliance will break up | AE7: தனித்துப் போட்டியிட வேண்டும் / Contest Independently | AF7: மதுபானம் / போதைப்பொருள் பழக்கம்/ Alcohol/Drug abuse | AG7: BC | AH7: CHRISTIAN | AI7: =IFERROR(_xlfn.XLOOKUP(Table1[[#This Row],[Audio Url]],Qc!C:C,Qc!F:F),"") -> 0 | AJ7: =IFERROR(_xlfn.XLOOKUP(Table1[[#This Row],[Audio Url]],Qc!C:C,Qc!E:E),"") -> Correctly Done | AK7: - | AL7: - | AM7: 0.1.12 (60) | AN7: Yes | AO7: =IF(Table1[[#This Row],[Audio Duration (in secs)]]>180,"Greater than 3 Minutes","Less than 3 Minutes") -> Greater than 3 Minutes | AP7: =VLOOKUP(Table1[[#This Row],[உங்கள் தொகுதியில் வெற்றி பெற வாய்ப்புள்ள கட்சி/கூட்டணி எது என நீங்கள் கருதுகிறீர்கள்?/ Which party/alliance do you think will win in your constituency? ]],MApping!$A$1:$B$13,2,0) -> DMK | AQ7: =IFERROR(VLOOKUP(Table1[[#This Row],[சாதி/Caste]],MApping!$E$1:$F$10,2,0),"Others") -> CHRISTIAN | AR7: =VLOOKUP(Table1[[#This Row],[பாலினம்/Gender]],Factor!$F$26:$I$28,4,0) -> 0.89361702 | AS7: =VLOOKUP(Table1[[#This Row],[பதிலளித்தவரின் வயது/Age Group]],Factor!$F$35:$I$39,4,0) -> 1.2824427 | AT7: =VLOOKUP(Table1[[#This Row],[பதிலளித்தவரின் வயது/Age Group]]&Table1[[#This Row],[பாலினம்/Gender]],Factor!$A$45:$G$53,7,0) -> 0.95454545 | AU7: =VLOOKUP(Table1[[#This Row],[2021 சட்டமன்றத் தேர்தலில் நீங்கள் எந்தக் கட்சிக்கு வாக்களித்தீர்கள்?/ Which party did you vote in 2021 Assembly Elections? ]],Factor!$F$9:$J$14,5,0) -> 2.0011999 | AV7: =VLOOKUP(Table1[[#This Row],[Rev Caste]],Factor!$F$59:$I$68,4,0) -> 0.76363636 | AW7: =Table1[[#This Row],[2021 Ae Factor]]*Table1[[#This Row],[Age & Gender Factor]] -> 1.9102363 | AX7: =VALUE(MID(D7,2,FIND(",",D7)-2)) -> 10.462384 | AY7: =VALUE(MID(D7, FIND(",",D7)+2, FIND(")",D7)-FIND(",",D7)-2)) -> 78.681528
A8: wEykrB7PWmMFbpcLSh29 | B8: 2025-07-30 14:42:51.078465 | C8: 45868 | D8: (10.462279, 78.6809876) | E8: FM6J+JHW,,Pudukkottai,622103,Tamil Nadu,India. | F8: https://firebasestorage.googleapis.com/v0/b/mindbrink-survey-production.appspot.com/o/audioFiles%2FAtznECuQc6klLPsRR6u2%2F2ukCmICpvKWhqTT6dgmjG6nFGjc2%2F2025-07-30%2014%3A42%3A42.625814.m4a?alt=media&token=aa21e8ba-da98-4d18-8f39-886502c10bef | G8: 331 | H8: false | I8: U.Amir nisha | J8: +919698565662 | K8: Subramanian | L8: ILLUPUR | M8: MUKKANNAMALAIPATTI | N8: Jesuthas | O8: ஆண்/Male | P8: 8973759103 | Q8: 46-60 | R8: கூலி தொழில்/ Daily Wage | S8: 10,000க்கும் குறைவானது/Less than 10,000 | T8: திருப்திகரமல்ல/ Unsatisfactory | U8: ஆம் / Yes | V8: திமுக கூட்டணி / DMK Alliance | W8: எடப்பாடி பழனிசாமி (அதிமுக) / Edappadi K. Palaniswami (AIADMK) | X8: திமுக / DMK | Y8: - | Z8: ஆமாம் / Yes | AA8: அதிமுக கூட்டணி / AIADMK Alliance | AB8: திருப்திகரமல்ல / Unsatisfactory | AC8: குறைவான ஈடுபாடு / Inadequate | AD8: • ஆமாம்: திமுக மற்றும் அதிமுக கூட்டணிகள் இரண்டும் உடையும்/ Yes: Both DMK & AIADMK alliances will break up | AE8: அதிமுக / AIADMK | AF8: விவசாய நெருக்கடி / Agricultural crisis | AG8: SC | AH8: CHRISTIAN | AI8: =IFERROR(_xlfn.XLOOKUP(Table1[[#This Row],[Audio Url]],Qc!C:C,Qc!F:F),"") -> 0 | AJ8: =IFERROR(_xlfn.XLOOKUP(Table1[[#This Row],[Audio Url]],Qc!C:C,Qc!E:E),"") -> Correctly Done | AK8: - | AL8: - | AM8: 0.1.12 (60) | AN8: Yes | AO8: =IF(Table1[[#This Row],[Audio Duration (in secs)]]>180,"Greater than 3 Minutes","Less than 3 Minutes") -> Greater than 3 Minutes | AP8: =VLOOKUP(Table1[[#This Row],[உங்கள் தொகுதியில் வெற்றி பெற வாய்ப்புள்ள கட்சி/கூட்டணி எது என நீங்கள் கருதுகிறீர்கள்?/ Which party/alliance do you think will win in your constituency? ]],MApping!$A$1:$B$13,2,0) -> DMK | AQ8: =IFERROR(VLOOKUP(Table1[[#This Row],[சாதி/Caste]],MApping!$E$1:$F$10,2,0),"Others") -> CHRISTIAN | AR8: =VLOOKUP(Table1[[#This Row],[பாலினம்/Gender]],Factor!$F$26:$I$28,4,0) -> 1.1351351 | AS8: =VLOOKUP(Table1[[#This Row],[பதிலளித்தவரின் வயது/Age Group]],Factor!$F$35:$I$39,4,0) -> 0.84 | AT8: =VLOOKUP(Table1[[#This Row],[பதிலளித்தவரின் வயது/Age Group]]&Table1[[#This Row],[பாலினம்/Gender]],Factor!$A$45:$G$53,7,0) -> 0.80769231 | AU8: =VLOOKUP(Table1[[#This Row],[2021 சட்டமன்றத் தேர்தலில் நீங்கள் எந்தக் கட்சிக்கு வாக்களித்தீர்கள்?/ Which party did you vote in 2021 Assembly Elections? ]],Factor!$F$9:$J$14,5,0) -> 0.59193366 | AV8: =VLOOKUP(Table1[[#This Row],[Rev Caste]],Factor!$F$59:$I$68,4,0) -> 0.76363636 | AW8: =Table1[[#This Row],[2021 Ae Factor]]*Table1[[#This Row],[Age & Gender Factor]] -> 0.47810026 | AX8: =VALUE(MID(D8,2,FIND(",",D8)-2)) -> 10.462279 | AY8: =VALUE(MID(D8, FIND(",",D8)+2, FIND(")",D8)-FIND(",",D8)-2)) -> 78.680988
A9: u9XGRvPU08lptw83iYlu | B9: 2025-07-30 14:51:49.473078 | C9: 45868 | D9: (10.4623531, 78.6809325) | E9: FM6J+JHW,,Pudukkottai,622103,Tamil Nadu,India. | F9: https://firebasestorage.googleapis.com/v0/b/mindbrink-survey-production.appspot.com/o/audioFiles%2FAtznECuQc6klLPsRR6u2%2F2ukCmICpvKWhqTT6dgmjG6nFGjc2%2F2025-07-30%2014%3A51%3A43.908029.m4a?alt=media&token=483045d4-e721-4bd9-870a-817b0e8046be | G9: 274 | H9: false | I9: U.Amir nisha | J9: +919698565662 | K9: Subramanian | L9: ILLUPUR | M9: MUKKANNAMALAIPATTI | N9: Jayamary | O9: பெண்/Female | P9: 9578493153 | Q9: 31-45 | R9: கூலி தொழில்/ Daily Wage | S9: 10,000க்கும் குறைவானது/Less than 10,000 | T9: திருப்திகரமானது / Satisfactory | U9: ஆம் / Yes | V9: அதிமுக கூட்டணி / AIADMK Alliance | W9: மு.க. ஸ்டாலின் (திமுக) / M.K. Stalin (DMK) | X9: அதிமுக / AIADMK | Y9: ஆம், TVK கூட்டணிக்கு வாக்களிப்பேன் / Yes, I will shift my vote to the TVK alliance | Z9: இல்லை / No | AA9: - | AB9: வேகம் குறைபாடுடன் செயல்படுகிறது / Needs more momentum | AC9: போதுமான ஈடுபாடு / Adequate | AD9: • ஆமாம்: திமுக மற்றும் அதிமுக கூட்டணிகள் இரண்டும் உடையும்/ Yes: Both DMK & AIADMK alliances will break up | AE9: அதிமுக / AIADMK | AF9: விவசாய நெருக்கடி / Agricultural crisis | AG9: SC | AH9: CHRISTIAN | AI9: =IFERROR(_xlfn.XLOOKUP(Table1[[#This Row],[Audio Url]],Qc!C:C,Qc!F:F),"") -> 0 | AJ9: =IFERROR(_xlfn.XLOOKUP(Table1[[#This Row],[Audio Url]],Qc!C:C,Qc!E:E),"") -> Correctly Done | AK9: - | AL9: - | AM9: 0.1.12 (60) | AN9: Yes | AO9: =IF(Table1[[#This Row],[Audio Duration (in secs)]]>180,"Greater than 3 Minutes","Less than 3 Minutes") -> Greater than 3 Minutes | AP9: =VLOOKUP(Table1[[#This Row],[உங்கள் தொகுதியில் வெற்றி பெற வாய்ப்புள்ள கட்சி/கூட்டணி எது என நீங்கள் கருதுகிறீர்கள்?/ Which party/alliance do you think will win in your constituency? ]],MApping!$A$1:$B$13,2,0) -> AIADMK | AQ9: =IFERROR(VLOOKUP(Table1[[#This Row],[சாதி/Caste]],MApping!$E$1:$F$10,2,0),"Others") -> CHRISTIAN | AR9: =VLOOKUP(Table1[[#This Row],[பாலினம்/Gender]],Factor!$F$26:$I$28,4,0) -> 0.89361702 | AS9: =VLOOKUP(Table1[[#This Row],[பதிலளித்தவரின் வயது/Age Group]],Factor!$F$35:$I$39,4,0) -> 1.2824427 | AT9: =VLOOKUP(Table1[[#This Row],[பதிலளித்தவரின் வயது/Age Group]]&Table1[[#This Row],[பாலினம்/Gender]],Factor!$A$45:$G$53,7,0) -> 0.95454545 | AU9: =VLOOKUP(Table1[[#This Row],[2021 சட்டமன்றத் தேர்தலில் நீங்கள் எந்தக் கட்சிக்கு வாக்களித்தீர்கள்?/ Which party did you vote in 2021 Assembly Elections? ]],Factor!$F$9:$J$14,5,0) -> 2.0011999 | AV9: =VLOOKUP(Table1[[#This Row],[Rev Caste]],Factor!$F$59:$I$68,4,0) -> 0.76363636 | AW9: =Table1[[#This Row],[2021 Ae Factor]]*Table1[[#This Row],[Age & Gender Factor]] -> 1.9102363 | AX9: =VALUE(MID(D9,2,FIND(",",D9)-2)) -> 10.462353 | AY9: =VALUE(MID(D9, FIND(",",D9)+2, FIND(")",D9)-FIND(",",D9)-2)) -> 78.680932
A10: e6ac5EItzYfOFpBKRvtE | B10: 2025-07-30 14:56:26.558863 | C10: 45868 | D10: (10.4621783, 78.6809415) | E10: FM6J+JHW,,Pudukkottai,622103,Tamil Nadu,India. | F10: https://firebasestorage.googleapis.com/v0/b/mindbrink-survey-production.appspot.com/o/audioFiles%2FAtznECuQc6klLPsRR6u2%2F2ukCmICpvKWhqTT6dgmjG6nFGjc2%2F2025-07-30%2014%3A56%3A20.571686.m4a?alt=media&token=09e17480-5dfc-4cff-9135-47f53823b27a | G10: 233 | H10: false | I10: U.Amir nisha | J10: +919698565662 | K10: Subramanian | L10: ILLUPUR | M10: MUKKANNAMALAIPATTI | N10: Arokiya shalini | O10: பெண்/Female | P10: 6384537452 | Q10: 18-30 | R10: இல்லத்தரசி/ Housewife | S10: 10,000க்கும் குறைவானது/Less than 10,000 | T10: மேம்பாடு தேவை / Needs improvement | U10: ஆம் / Yes | V10: திமுக கூட்டணி / DMK Alliance | W10: விஜய் (தமிழக வெற்றி கழகம்) / Vijay (TVK) | X10: திமுக / DMK | Y10: - | Z10: ஆமாம் / Yes | AA10: திமுக கூட்டணி / DMK Alliance | AB10: வேகம் குறைபாடுடன் செயல்படுகிறது / Needs more momentum | AC10: போதுமான ஈடுபாடு / Adequate | AD10: • ஆமாம்: திமுக மற்றும் அதிமுக கூட்டணிகள் இரண்டும் உடையும்/ Yes: Both DMK & AIADMK alliances will break up | AE10: தனித்துப் போட்டியிட வேண்டும் / Contest Independently | AF10: விவசாய நெருக்கடி / Agricultural crisis | AG10: SC | AH10: CHRISTIAN | AI10: =IFERROR(_xlfn.XLOOKUP(Table1[[#This Row],[Audio Url]],Qc!C:C,Qc!F:F),"") | AJ10: =IFERROR(_xlfn.XLOOKUP(Table1[[#This Row],[Audio Url]],Qc!C:C,Qc!E:E),"") | AK10: - | AL10: - | AM10: 0.1.12 (60) | AN10: Yes | AO10: =IF(Table1[[#This Row],[Audio Duration (in secs)]]>180,"Greater than 3 Minutes","Less than 3 Minutes") -> Greater than 3 Minutes | AP10: =VLOOKUP(Table1[[#This Row],[உங்கள் தொகுதியில் வெற்றி பெற வாய்ப்புள்ள கட்சி/கூட்டணி எது என நீங்கள் கருதுகிறீர்கள்?/ Which party/alliance do you think will win in your constituency? ]],MApping!$A$1:$B$13,2,0) -> DMK | AQ10: =IFERROR(VLOOKUP(Table1[[#This Row],[சாதி/Caste]],MApping!$E$1:$F$10,2,0),"Others") -> CHRISTIAN | AR10: =VLOOKUP(Table1[[#This Row],[பாலினம்/Gender]],Factor!$F$26:$I$28,4,0) -> 0.89361702 | AS10: =VLOOKUP(Table1[[#This Row],[பதிலளித்தவரின் வயது/Age Group]],Factor!$F$35:$I$39,4,0) -> 0.84848485 | AT10: =VLOOKUP(Table1[[#This Row],[பதிலளித்தவரின் வயது/Age Group]]&Table1[[#This Row],[பாலினம்/Gender]],Factor!$A$45:$G$53,7,0) -> 0.7 | AU10: =VLOOKUP(Table1[[#This Row],[2021 சட்டமன்றத் தேர்தலில் நீங்கள் எந்தக் கட்சிக்கு வாக்களித்தீர்கள்?/ Which party did you vote in 2021 Assembly Elections? ]],Factor!$F$9:$J$14,5,0) -> 0.59193366 | AV10: =VLOOKUP(Table1[[#This Row],[Rev Caste]],Factor!$F$59:$I$68,4,0) -> 0.76363636 | AW10: =Table1[[#This Row],[2021 Ae Factor]]*Table1[[#This Row],[Age & Gender Factor]] -> 0.41435356 | AX10: =VALUE(MID(D10,2,FIND(",",D10)-2)) -> 10.462178 | AY10: =VALUE(MID(D10, FIND(",",D10)+2, FIND(")",D10)-FIND(",",D10)-2)) -> 78.680942
A11: E0uszhEvnSbx6OhSMH4r | B11: 2025-07-30 15:02:09.334115 | C11: 45868 | D11: (10.462594, 78.6806822) | E11: FM7J+89V,,Madakoil,622103,Tamil Nadu,India. | F11: https://firebasestorage.googleapis.com/v0/b/mindbrink-survey-production.appspot.com/o/audioFiles%2FAtznECuQc6klLPsRR6u2%2F2ukCmICpvKWhqTT6dgmjG6nFGjc2%2F2025-07-30%2015%3A02%3A02.380467.m4a?alt=media&token=81f317a8-fb8d-43d3-859d-4d0a1d121306 | G11: 187 | H11: false | I11: U.Amir nisha | J11: +919698565662 | K11: Subramanian | L11: ILLUPUR | M11: MUKKANNAMALAIPATTI | N11: sivanthai | O11: பெண்/Female | P11: 9715185244 | Q11: 46-60 | R11: இல்லத்தரசி/ Housewife | S11: 10,000க்கும் குறைவானது/Less than 10,000 | T11: மேம்பாடு தேவை / Needs improvement | U11: ஆம் / Yes | V11: திமுக கூட்டணி / DMK Alliance | W11: விஜய் (தமிழக வெற்றி கழகம்) / Vijay (TVK) | X11: திமுக / DMK | Y11: - | Z11: ஆமாம் / Yes | AA11: திமுக கூட்டணி / DMK Alliance | AB11: வேகம் குறைபாடுடன் செயல்படுகிறது / Needs more momentum | AC11: குறைவான ஈடுபாடு / Inadequate | AD11: • ஆமாம்: திமுக மற்றும் அதிமுக கூட்டணிகள் இரண்டும் உடையும்/ Yes: Both DMK & AIADMK alliances will break up | AE11: தனித்துப் போட்டியிட வேண்டும் / Contest Independently | AF11: வேலைவாய்ப்பு குறைபாடு / Unemployment | AG11: SC | AH11: CHRISTIAN | AI11: =IFERROR(_xlfn.XLOOKUP(Table1[[#This Row],[Audio Url]],Qc!C:C,Qc!F:F),"") | AJ11: =IFERROR(_xlfn.XLOOKUP(Table1[[#This Row],[Audio Url]],Qc!C:C,Qc!E:E),"") | AK11: - | AL11: - | AM11: 0.1.12 (60) | AN11: Yes | AO11: =IF(Table1[[#This Row],[Audio Duration (in secs)]]>180,"Greater than 3 Minutes","Less than 3 Minutes") -> Greater than 3 Minutes | AP11: =VLOOKUP(Table1[[#This Row],[உங்கள் தொகுதியில் வெற்றி பெற வாய்ப்புள்ள கட்சி/கூட்டணி எது என நீங்கள் கருதுகிறீர்கள்?/ Which party/alliance do you think will win in your constituency? ]],MApping!$A$1:$B$13,2,0) -> DMK | AQ11: =IFERROR(VLOOKUP(Table1[[#This Row],[சாதி/Caste]],MApping!$E$1:$F$10,2,0),"Others") -> CHRISTIAN | AR11: =VLOOKUP(Table1[[#This Row],[பாலினம்/Gender]],Factor!$F$26:$I$28,4,0) -> 0.89361702 | AS11: =VLOOKUP(Table1[[#This Row],[பதிலளித்தவரின் வயது/Age Group]],Factor!$F$35:$I$39,4,0) -> 0.84 | AT11: =VLOOKUP(Table1[[#This Row],[பதிலளித்தவரின் வயது/Age Group]]&Table1[[#This Row],[பாலினம்/Gender]],Factor!$A$45:$G$53,7,0) -> 0.875 | AU11: =VLOOKUP(Table1[[#This Row],[2021 சட்டமன்றத் தேர்தலில் நீங்கள் எந்தக் கட்சிக்கு வாக்களித்தீர்கள்?/ Which party did you vote in 2021 Assembly Elections? ]],Factor!$F$9:$J$14,5,0) -> 0.59193366 | AV11: =VLOOKUP(Table1[[#This Row],[Rev Caste]],Factor!$F$59:$I$68,4,0) -> 0.76363636 | AW11: =Table1[[#This Row],[2021 Ae Factor]]*Table1[[#This Row],[Age & Gender Factor]] -> 0.51794195 | AX11: =VALUE(MID(D11,2,FIND(",",D11)-2)) -> 10.462594 | AY11: =VALUE(MID(D11, FIND(",",D11)+2, FIND(")",D11)-FIND(",",D11)-2)) -> 78.680682
A12: BhxdqOskEmCZ304Pnoub | B12: 2025-07-30 15:10:51.958258 | C12: 45868 | D12: (10.4629467, 78.6810732) | E12: FM7J+89V,,Madakoil,622103,Tamil Nadu,India. | F12: https://firebasestorage.googleapis.com/v0/b/mindbrink-survey-production.appspot.com/o/audioFiles%2FAtznECuQc6klLPsRR6u2%2F2ukCmICpvKWhqTT6dgmjG6nFGjc2%2F2025-07-30%2015%3A10%3A39.624126.m4a?alt=media&token=d885f812-189d-4fd3-8103-6594736f083c | G12: 437 | H12: false | I12: U.Amir nisha | J12: +919698565662 | K12: Subramanian | L12: ILLUPUR | M12: MUKKANNAMALAIPATTI | N12: jansi rani | O12: பெண்/Female | P12: 8012952924 | Q12: 18-30 | R12: இல்லத்தரசி/ Housewife | S12: 10,000க்கும் குறைவானது/Less than 10,000 | T12: மேம்பாடு தேவை / Needs improvement | U12: ஆம் / Yes | V12: நினைவில் இல்லை / Don’t Remember | W12: விஜய் (தமிழக வெற்றி கழகம்) / Vijay (TVK) | X12: திமுக / DMK | Y12: - | Z12: ஆமாம் / Yes | AA12: திமுக கூட்டணி / DMK Alliance | AB12: வேகம் குறைபாடுடன் செயல்படுகிறது / Needs more momentum | AC12: குறைவான ஈடுபாடு / Inadequate | AD12: • ஆமாம்: திமுக மற்றும் அதிமுக கூட்டணிகள் இரண்டும் உடையும்/ Yes: Both DMK & AIADMK alliances will break up | AE12: தனித்துப் போட்டியிட வேண்டும் / Contest Independently | AF12: மதுபானம் / போதைப்பொருள் பழக்கம்/ Alcohol/Drug abuse | AG12: SC | AH12: CHRISTIAN | AI12: =IFERROR(_xlfn.XLOOKUP(Table1[[#This Row],[Audio Url]],Qc!C:C,Qc!F:F),"") -> 0 | AJ12: =IFERROR(_xlfn.XLOOKUP(Table1[[#This Row],[Audio Url]],Qc!C:C,Qc!E:E),"") -> Correctly Done | AK12: - | AL12: - | AM12: 0.1.12 (60) | AN12: Yes | AO12: =IF(Table1[[#This Row],[Audio Duration (in secs)]]>180,"Greater than 3 Minutes","Less than 3 Minutes") -> Greater than 3 Minutes | AP12: =VLOOKUP(Table1[[#This Row],[உங்கள் தொகுதியில் வெற்றி பெற வாய்ப்புள்ள கட்சி/கூட்டணி எது என நீங்கள் கருதுகிறீர்கள்?/ Which party/alliance do you think will win in your constituency? ]],MApping!$A$1:$B$13,2,0) -> DMK | AQ12: =IFERROR(VLOOKUP(Table1[[#This Row],[சாதி/Caste]],MApping!$E$1:$F$10,2,0),"Others") -> CHRISTIAN | AR12: =VLOOKUP(Table1[[#This Row],[பாலினம்/Gender]],Factor!$F$26:$I$28,4,0) -> 0.89361702 | AS12: =VLOOKUP(Table1[[#This Row],[பதிலளித்தவரின் வயது/Age Group]],Factor!$F$35:$I$39,4,0) -> 0.84848485 | AT12: =VLOOKUP(Table1[[#This Row],[பதிலளித்தவரின் வயது/Age Group]]&Table1[[#This Row],[பாலினம்/Gender]],Factor!$A$45:$G$53,7,0) -> 0.7 | AU12: =VLOOKUP(Table1[[#This Row],[2021 சட்டமன்றத் தேர்தலில் நீங்கள் எந்தக் கட்சிக்கு வாக்களித்தீர்கள்?/ Which party did you vote in 2021 Assembly Elections? ]],Factor!$F$9:$J$14,5,0) -> 1 | AV12: =VLOOKUP(Table1[[#This Row],[Rev Caste]],Factor!$F$59:$I$68,4,0) -> 0.76363636 | AW12: =Table1[[#This Row],[2021 Ae Factor]]*Table1[[#This Row],[Age & Gender Factor]] -> 0.7 | AX12: =VALUE(MID(D12,2,FIND(",",D12)-2)) -> 10.462947 | AY12: =VALUE(MID(D12, FIND(",",D12)+2, FIND(")",D12)-FIND(",",D12)-2)) -> 78.681073
A13: LtwsC8GYqQizC0FxeuxW | B13: 2025-07-30 15:14:56.602348 | C13: 45868 | D13: (10.4628599, 78.6808137) | E13: FM7J+89V,,Madakoil,622103,Tamil Nadu,India. | F13: https://firebasestorage.googleapis.com/v0/b/mindbrink-survey-production.appspot.com/o/audioFiles%2FAtznECuQc6klLPsRR6u2%2F2ukCmICpvKWhqTT6dgmjG6nFGjc2%2F2025-07-30%2015%3A14%3A48.563168.m4a?alt=media&token=e6b48caf-67ad-4c1d-aadf-d84204f505a0 | G13: 203 | H13: false | I13: U.Amir nisha | J13: +919698565662 | K13: Subramanian | L13: ILLUPUR | M13: MUKKANNAMALAIPATTI | N13: Arulselvi | O13: பெண்/Female | P13: 9843601161 | Q13: 18-30 | R13: இல்லத்தரசி/ Housewife | S13: 10,000க்கும் குறைவானது/Less than 10,000 | T13: திருப்திகரமானது / Satisfactory | U13: ஆம் / Yes | V13: திமுக கூட்டணி / DMK Alliance | W13: மு.க. ஸ்டாலின் (திமுக) / M.K. Stalin (DMK) | X13: திமுக / DMK | Y13: - | Z13: ஆமாம் / Yes | AA13: அதிமுக கூட்டணி / AIADMK Alliance | AB13: திருப்திகரமல்ல / Unsatisfactory | AC13: குறைவான ஈடுபாடு / Inadequate | AD13: • ஆமாம்: அதிமுக கூட்டணி உடையும்/ Yes: AIADMK alliance will break up | AE13: தனித்துப் போட்டியிட வேண்டும் / Contest Independently | AF13: விவசாய நெருக்கடி / Agricultural crisis | AG13: SC | AH13: CHRISTIAN | AI13: =IFERROR(_xlfn.XLOOKUP(Table1[[#This Row],[Audio Url]],Qc!C:C,Qc!F:F),"") -> same voice | AJ13: =IFERROR(_xlfn.XLOOKUP(Table1[[#This Row],[Audio Url]],Qc!C:C,Qc!E:E),"") -> Taking From Friends And Family | AK13: - | AL13: - | AM13: 0.1.12 (60) | AN13: No | AO13: =IF(Table1[[#This Row],[Audio Duration (in secs)]]>180,"Greater than 3 Minutes","Less than 3 Minutes") -> Greater than 3 Minutes | AP13: =VLOOKUP(Table1[[#This Row],[உங்கள் தொகுதியில் வெற்றி பெற வாய்ப்புள்ள கட்சி/கூட்டணி எது என நீங்கள் கருதுகிறீர்கள்?/ Which party/alliance do you think will win in your constituency? ]],MApping!$A$1:$B$13,2,0) -> DMK | AQ13: =IFERROR(VLOOKUP(Table1[[#This Row],[சாதி/Caste]],MApping!$E$1:$F$10,2,0),"Others") -> CHRISTIAN | AR13: =VLOOKUP(Table1[[#This Row],[பாலினம்/Gender]],Factor!$F$26:$I$28,4,0) -> 0.89361702 | AS13: =VLOOKUP(Table1[[#This Row],[பதிலளித்தவரின் வயது/Age Group]],Factor!$F$35:$I$39,4,0) -> 0.84848485 | AT13: =VLOOKUP(Table1[[#This Row],[பதிலளித்தவரின் வயது/Age Group]]&Table1[[#This Row],[பாலினம்/Gender]],Factor!$A$45:$G$53,7,0) -> 0.7 | AU13: =VLOOKUP(Table1[[#This Row],[2021 சட்டமன்றத் தேர்தலில் நீங்கள் எந்தக் கட்சிக்கு வாக்களித்தீர்கள்?/ Which party did you vote in 2021 Assembly Elections? ]],Factor!$F$9:$J$14,5,0) -> 0.59193366 | AV13: =VLOOKUP(Table1[[#This Row],[Rev Caste]],Factor!$F$59:$I$68,4,0) -> 0.76363636 | AW13: =Table1[[#This Row],[2021 Ae Factor]]*Table1[[#This Row],[Age & Gender Factor]] -> 0.41435356 | AX13: =VALUE(MID(D13,2,FIND(",",D13)-2)) -> 10.46286 | AY13: =VALUE(MID(D13, FIND(",",D13)+2, FIND(")",D13)-FIND(",",D13)-2)) -> 78.680814
