Workbook

Sheet Sampling
A1: Valid or Not | B1: Valid | F1: AC Name | G1: Mandal | H1: GP Name | I1: Samples | J1: Collected | K1: Pending | M1: MANDAL | N1: Samples | O1: Collected | P1: Pending | Q1: Req% | R1: Collected% | T1: Caste | U1: MALIKIPURAM | V1: Collected | W1: Pending | X1: MAMIDIKUDURU_PART | Y1: Collected | Z1: Pending | AA1: RAZOLE | AB1: Collected | AC1: Pending | AD1: SAKHINETIPALLE | AE1: Collected | AF1: Pending | AG1: Grand Total | AH1: Collected | AI1: Pending
F2: Razole(SC) | G2: MALIKIPURAM | H2: LAKKAVARAM | I2: 70 | J2: =IFERROR(VLOOKUP(G2&H2,$E$34:$H$62,4,0),0) -> 44 | K2: =I2-J2 -> 26 | M2: MALIKIPURAM | N2: 315 | O2: =IFERROR(VLOOKUP(M2,$N$33:$O$37,2,0),0) -> 161 | P2: =N2-O2 -> 154 | Q2: 0.31016074 | R2: =O2/$O$6 -> 0.1965812 | T2: Mala | U2: 91 | V2: =COUNTIFS(Table1[Caste],$T2,Table1[Taluka],U$1,Table1[Valid or Not],"Valid") -> 32 | W2: =U2-V2 -> 59 | X2: 32 | Y2: =COUNTIFS(Table1[Caste],$T2,Table1[Taluka],X$1,Table1[Valid or Not],"Valid") -> 48 | Z2: =X2-Y2 -> -16 | AA2: 90 | AB2: =COUNTIFS(Table1[Caste],$T2,Table1[Taluka],AA$1,Table1[Valid or Not],"Valid") -> 80 | AC2: =AA2-AB2 -> 10 | AD2: 88 | AE2: =COUNTIFS(Table1[Caste],$T2,Table1[Taluka],AD$1,Table1[Valid or Not],"Valid") -> 49 | AF2: =AD2-AE2 -> 39 | AG2: 301 | AH2: =COUNTIFS(Table1[Caste],$T2,Table1[Valid or Not],"Valid") -> 209 | AI2: =AG2-AH2 -> 92
A3: Date | B3: Surveyor | C3: Count of Q18: Gender | F3: Razole(SC) | G3: MALIKIPURAM | H3: MALIKIPURAM | I3: 35 | J3: =IFERROR(VLOOKUP(G3&H3,$E$34:$H$62,4,0),0) -> 42 | K3: =I3-J3 -> -7 | M3: MAMIDIKUDURU_PART | N3: 140 | O3: =IFERROR(VLOOKUP(M3,$N$33:$O$37,2,0),0) -> 149 | P3: =N3-O3 -> -9 | Q3: 0.11239633 | R3: =O3/$O$6 -> 0.18192918 | T3: Kapu | U3: 101 | V3: =COUNTIFS(Table1[Caste],$T3,Table1[Taluka],U$1,Table1[Valid or Not],"Valid") -> 70 | W3: =U3-V3 -> 31 | X3: 38 | Y3: =COUNTIFS(Table1[Caste],$T3,Table1[Taluka],X$1,Table1[Valid or Not],"Valid") -> 32 | Z3: =X3-Y3 -> 6 | AA3: 70 | AB3: =COUNTIFS(Table1[Caste],$T3,Table1[Taluka],AA$1,Table1[Valid or Not],"Valid") -> 54 | AC3: =AA3-AB3 -> 16 | AD3: 85 | AE3: =COUNTIFS(Table1[Caste],$T3,Table1[Taluka],AD$1,Table1[Valid or Not],"Valid") -> 94 | AF3: =AD3-AE3 -> -9 | AG3: 294 | AH3: =COUNTIFS(Table1[Caste],$T3,Table1[Valid or Not],"Valid") -> 250 | AI3: =AG3-AH3 -> 44
A4: 46041 | B4: Kumpatla venkata satya suryamohan rao | C4: 14 | F4: Razole(SC) | G4: MALIKIPURAM | H4: TURPUPALEM | I4: 35 | J4: =IFERROR(VLOOKUP(G4&H4,$E$34:$H$62,4,0),0) -> 17 | K4: =I4-J4 -> 18 | M4: RAZOLE | N4: 315 | O4: =IFERROR(VLOOKUP(M4,$N$33:$O$37,2,0),0) -> 258 | P4: =N4-O4 -> 57 | Q4: 0.28929878 | R4: =O4/$O$6 -> 0.31501832 | T4: Settibalija | U4: 45 | V4: =COUNTIFS(Table1[Caste],$T4,Table1[Taluka],U$1,Table1[Valid or Not],"Valid") -> 28 | W4: =U4-V4 -> 17 | X4: 25 | Y4: =COUNTIFS(Table1[Caste],$T4,Table1[Taluka],X$1,Table1[Valid or Not],"Valid") -> 34 | Z4: =X4-Y4 -> -9 | AA4: 82 | AB4: =COUNTIFS(Table1[Caste],$T4,Table1[Taluka],AA$1,Table1[Valid or Not],"Valid") -> 62 | AC4: =AA4-AB4 -> 20 | AD4: 32 | AE4: =COUNTIFS(Table1[Caste],$T4,Table1[Taluka],AD$1,Table1[Valid or Not],"Valid") -> 29 | AF4: =AD4-AE4 -> 3 | AG4: 184 | AH4: =COUNTIFS(Table1[Caste],$T4,Table1[Valid or Not],"Valid") -> 153 | AI4: =AG4-AH4 -> 31
A5: 46041 | B5: krishna | C5: 1 | F5: Razole(SC) | G5: MALIKIPURAM | H5: RAMARAJULANKA | I5: 35 | J5: =IFERROR(VLOOKUP(G5&H5,$E$34:$H$62,4,0),0) -> 0 | K5: =I5-J5 -> 35 | M5: SAKHINETIPALLE | N5: 280 | O5: =IFERROR(VLOOKUP(M5,$N$33:$O$37,2,0),0) -> 251 | P5: =N5-O5 -> 29 | Q5: 0.28814415 | R5: =O5/$O$6 -> 0.30647131 | T5: Agnikulakshatriya | U5: 25 | V5: =COUNTIFS(Table1[Caste],$T5,Table1[Taluka],U$1,Table1[Valid or Not],"Valid") -> 12 | W5: =U5-V5 -> 13 | X5: 19 | Y5: =COUNTIFS(Table1[Caste],$T5,Table1[Taluka],X$1,Table1[Valid or Not],"Valid") -> 5 | Z5: =X5-Y5 -> 14 | AA5: 23 | AB5: =COUNTIFS(Table1[Caste],$T5,Table1[Taluka],AA$1,Table1[Valid or Not],"Valid") -> 18 | AC5: =AA5-AB5 -> 5 | AD5: 30 | AE5: =COUNTIFS(Table1[Caste],$T5,Table1[Taluka],AD$1,Table1[Valid or Not],"Valid") -> 38 | AF5: =AD5-AE5 -> -8 | AG5: 97 | AH5: =COUNTIFS(Table1[Caste],$T5,Table1[Valid or Not],"Valid") -> 73 | AI5: =AG5-AH5 -> 24
A6: 46042 | B6: ITABATHULA BHASKAR RAO | C6: 11 | F6: Razole(SC) | G6: MALIKIPURAM | H6: CHINTHALAMORI | I6: 35 | J6: =IFERROR(VLOOKUP(G6&H6,$E$34:$H$62,4,0),0) -> 0 | K6: =I6-J6 -> 35 | M6: Grand Total | N6: 1050 | O6: =SUM(O2:O5) -> 819 | P6: =SUM(P2:P5) -> 231 | Q6: =SUM(Q2:Q5) -> 1 | R6: =SUM(R2:R5) -> 1 | T6: Madiga | U6: 12 | V6: =COUNTIFS(Table1[Caste],$T6,Table1[Taluka],U$1,Table1[Valid or Not],"Valid") -> 6 | W6: =U6-V6 -> 6 | X6: 12 | Y6: =COUNTIFS(Table1[Caste],$T6,Table1[Taluka],X$1,Table1[Valid or Not],"Valid") -> 16 | Z6: =X6-Y6 -> -4 | AA6: 21 | AB6: =COUNTIFS(Table1[Caste],$T6,Table1[Taluka],AA$1,Table1[Valid or Not],"Valid") -> 20 | AC6: =AA6-AB6 -> 1 | AD6: 7 | AE6: =COUNTIFS(Table1[Caste],$T6,Table1[Taluka],AD$1,Table1[Valid or Not],"Valid") -> 8 | AF6: =AD6-AE6 -> -1 | AG6: 52 | AH6: =COUNTIFS(Table1[Caste],$T6,Table1[Valid or Not],"Valid") -> 50 | AI6: =AG6-AH6 -> 2
A7: 46042 | B7: aithabattula venkateswararao | C7: 32 | F7: Razole(SC) | G7: MALIKIPURAM | H7: GUDAPALLI | I7: 35 | J7: =IFERROR(VLOOKUP(G7&H7,$E$34:$H$62,4,0),0) -> 58 | K7: =I7-J7 -> -23 | T7: Padmasali/Devanga | U7: 10 | V7: =COUNTIFS(Table1[Caste],$T7,Table1[Taluka],U$1,Table1[Valid or Not],"Valid") -> 5 | W7: =U7-V7 -> 5 | X7: 7 | Y7: =COUNTIFS(Table1[Caste],$T7,Table1[Taluka],X$1,Table1[Valid or Not],"Valid") -> 2 | Z7: =X7-Y7 -> 5 | AA7: 4 | AB7: =COUNTIFS(Table1[Caste],$T7,Table1[Taluka],AA$1,Table1[Valid or Not],"Valid") -> 5 | AC7: =AA7-AB7 -> -1 | AD7: 10 | AE7: =COUNTIFS(Table1[Caste],$T7,Table1[Taluka],AD$1,Table1[Valid or Not],"Valid") -> 1 | AF7: =AD7-AE7 -> 9 | AG7: 31 | AH7: =COUNTIFS(Table1[Caste],$T7,Table1[Valid or Not],"Valid") -> 13 | AI7: =AG7-AH7 -> 18
A8: 46043 | B8: T Obulesu | C8: 12 | F8: Razole(SC) | G8: MALIKIPURAM | H8: KESANAPALLI | I8: 35 | J8: =IFERROR(VLOOKUP(G8&H8,$E$34:$H$62,4,0),0) -> 0 | K8: =I8-J8 -> 35 | T8: Yadava | U8: 10 | V8: =COUNTIFS(Table1[Caste],$T8,Table1[Taluka],U$1,Table1[Valid or Not],"Valid") -> 1 | W8: =U8-V8 -> 9 | X8: 2 | Y8: =COUNTIFS(Table1[Caste],$T8,Table1[Taluka],X$1,Table1[Valid or Not],"Valid") -> 0 | Z8: =X8-Y8 -> 2 | AA8: 6 | AB8: =COUNTIFS(Table1[Caste],$T8,Table1[Taluka],AA$1,Table1[Valid or Not],"Valid") -> 2 | AC8: =AA8-AB8 -> 4 | AD8: 6 | AE8: =COUNTIFS(Table1[Caste],$T8,Table1[Taluka],AD$1,Table1[Valid or Not],"Valid") -> 16 | AF8: =AD8-AE8 -> -10 | AG8: 24 | AH8: =COUNTIFS(Table1[Caste],$T8,Table1[Valid or Not],"Valid") -> 19 | AI8: =AG8-AH8 -> 5
A9: 46043 | B9: krishna | C9: 59 | F9: Razole(SC) | G9: MALIKIPURAM | H9: PADAMATIPALEM | I9: 35 | J9: =IFERROR(VLOOKUP(G9&H9,$E$34:$H$62,4,0),0) -> 0 | K9: =I9-J9 -> 35 | T9: Kshatriya/Rajulu | U9: 8 | V9: =COUNTIFS(Table1[Caste],$T9,Table1[Taluka],U$1,Table1[Valid or Not],"Valid") -> 3 | W9: =U9-V9 -> 5 | X9: 2 | Y9: =COUNTIFS(Table1[Caste],$T9,Table1[Taluka],X$1,Table1[Valid or Not],"Valid") -> 1 | Z9: =X9-Y9 -> 1 | AA9: 4 | AB9: =COUNTIFS(Table1[Caste],$T9,Table1[Taluka],AA$1,Table1[Valid or Not],"Valid") -> 5 | AC9: =AA9-AB9 -> -1 | AD9: 8 | AE9: =COUNTIFS(Table1[Caste],$T9,Table1[Taluka],AD$1,Table1[Valid or Not],"Valid") -> 2 | AF9: =AD9-AE9 -> 6 | AG9: 22 | AH9: =COUNTIFS(Table1[Caste],$T9,Table1[Valid or Not],"Valid") -> 11 | AI9: =AG9-AH9 -> 11
A10: 46043 | B10: aithabattula venkateswararao | C10: 53 | F10: Razole(SC) | G10: MAMIDIKUDURU_PART | H10: PASARLAPUDI LANKA | I10: 35 | J10: =IFERROR(VLOOKUP(G10&H10,$E$34:$H$62,4,0),0) -> 42 | K10: =I10-J10 -> -7 | T10: Rajaka | U10: 5 | V10: =COUNTIFS(Table1[Caste],$T10,Table1[Taluka],U$1,Table1[Valid or Not],"Valid") -> 3 | W10: =U10-V10 -> 2 | X10: 2 | Y10: =COUNTIFS(Table1[Caste],$T10,Table1[Taluka],X$1,Table1[Valid or Not],"Valid") -> 7 | Z10: =X10-Y10 -> -5 | AA10: 8 | AB10: =COUNTIFS(Table1[Caste],$T10,Table1[Taluka],AA$1,Table1[Valid or Not],"Valid") -> 3 | AC10: =AA10-AB10 -> 5 | AD10: 6 | AE10: =COUNTIFS(Table1[Caste],$T10,Table1[Taluka],AD$1,Table1[Valid or Not],"Valid") -> 6 | AF10: =AD10-AE10 -> 0 | AG10: 21 | AH10: =COUNTIFS(Table1[Caste],$T10,Table1[Valid or Not],"Valid") -> 19 | AI10: =AG10-AH10 -> 2
A11: 46044 | B11: T Obulesu | C11: 29 | F11: Razole(SC) | G11: MAMIDIKUDURU_PART | H11: B.DODDAVARAM | I11: 35 | J11: =IFERROR(VLOOKUP(G11&H11,$E$34:$H$62,4,0),0) -> 32 | K11: =I11-J11 -> 3 | T11: Adi Andhra | U11: 5 | V11: =COUNTIFS(Table1[Caste],$T11,Table1[Taluka],U$1,Table1[Valid or Not],"Valid") -> 1 | W11: =U11-V11 -> 4 | X11: 0 | Y11: =COUNTIFS(Table1[Caste],$T11,Table1[Taluka],X$1,Table1[Valid or Not],"Valid") -> 4 | Z11: =X11-Y11 -> -4 | AA11: 1 | AB11: =COUNTIFS(Table1[Caste],$T11,Table1[Taluka],AA$1,Table1[Valid or Not],"Valid") -> 7 | AC11: =AA11-AB11 -> -6 | AD11: 7 | AE11: =COUNTIFS(Table1[Caste],$T11,Table1[Taluka],AD$1,Table1[Valid or Not],"Valid") -> 0 | AF11: =AD11-AE11 -> 7 | AG11: 13 | AH11: =COUNTIFS(Table1[Caste],$T11,Table1[Valid or Not],"Valid") -> 12 | AI11: =AG11-AH11 -> 1
A12: 46044 | B12: krishna | C12: 67 | F12: Razole(SC) | G12: MAMIDIKUDURU_PART | H12: PEDAPATNAM LANKA | I12: 35 | J12: =IFERROR(VLOOKUP(G12&H12,$E$34:$H$62,4,0),0) -> 41 | K12: =I12-J12 -> -6 | T12: Brahmin | U12: 2 | V12: =COUNTIFS(Table1[Caste],$T12,Table1[Taluka],U$1,Table1[Valid or Not],"Valid") -> 0 | W12: =U12-V12 -> 2 | X12: 1 | Y12: =COUNTIFS(Table1[Caste],$T12,Table1[Taluka],X$1,Table1[Valid or Not],"Valid") -> 0 | Z12: =X12-Y12 -> 1 | AA12: 6 | AB12: =COUNTIFS(Table1[Caste],$T12,Table1[Taluka],AA$1,Table1[Valid or Not],"Valid") -> 2 | AC12: =AA12-AB12 -> 4 | AD12: 2 | AE12: =COUNTIFS(Table1[Caste],$T12,Table1[Taluka],AD$1,Table1[Valid or Not],"Valid") -> 8 | AF12: =AD12-AE12 -> -6 | AG12: 11 | AH12: =COUNTIFS(Table1[Caste],$T12,Table1[Valid or Not],"Valid") -> 10 | AI12: =AG12-AH12 -> 1
A13: 46044 | B13: aithabattula venkateswararao | C13: 29 | F13: Razole(SC) | G13: MAMIDIKUDURU_PART | H13: PEDAPATNAM | I13: 35 | J13: =IFERROR(VLOOKUP(G13&H13,$E$34:$H$62,4,0),0) -> 34 | K13: =I13-J13 -> 1 | T13: Total | U13: 314 | V13: =SUM(V2:V12) -> 161 | W13: =U13-V13 -> 153 | X13: 140 | Y13: =SUM(Y2:Y12) -> 149 | Z13: =SUM(Z2:Z12) -> -9 | AA13: 315 | AB13: =SUM(AB2:AB12) -> 258 | AC13: =AA13-AB13 -> 57 | AD13: 281 | AE13: =SUM(AE2:AE12) -> 251 | AF13: =AD13-AE13 -> 30 | AG13: 1050 | AH13: =SUM(AH2:AH12) -> 819 | AI13: =AG13-AH13 -> 231
A14: 46045 | B14: T Obulesu | C14: 25 | F14: Razole(SC) | G14: RAZOLE | H14: RAZOLE | I14: 70 | J14: =IFERROR(VLOOKUP(G14&H14,$E$34:$H$62,4,0),0) -> 29 | K14: =I14-J14 -> 41
A15: 46045 | B15: krishna | C15: 67 | F15: Razole(SC) | G15: RAZOLE | H15: SIVAKODU | I15: 70 | J15: =IFERROR(VLOOKUP(G15&H15,$E$34:$H$62,4,0),0) -> 70 | K15: =I15-J15 -> 0
A16: 46045 | B16: Bommappagari Obulapathi | C16: 7 | F16: Razole(SC) | G16: RAZOLE | H16: TATIPAKA | I16: 35 | J16: =IFERROR(VLOOKUP(G16&H16,$E$34:$H$62,4,0),0) -> 38 | K16: =I16-J16 -> -3
A17: 46045 | B17: aithabattula venkateswararao | C17: 40 | F17: Razole(SC) | G17: RAZOLE | H17: CHINTALAPALLE | I17: 35 | J17: =IFERROR(VLOOKUP(G17&H17,$E$34:$H$62,4,0),0) -> 47 | K17: =I17-J17 -> -12
A18: 46046 | B18: T Obulesu | C18: 58 | F18: Razole(SC) | G18: RAZOLE | H18: PONNAMANDA | I18: 35 | J18: =IFERROR(VLOOKUP(G18&H18,$E$34:$H$62,4,0),0) -> 1 | K18: =I18-J18 -> 34
A19: 46046 | B19: Nageswararao Nukala | C19: 1 | F19: Razole(SC) | G19: RAZOLE | H19: KADALI | I19: 35 | J19: =IFERROR(VLOOKUP(G19&H19,$E$34:$H$62,4,0),0) -> 28 | K19: =I19-J19 -> 7
A20: 46046 | B20: Kumpatla venkata satya suryamohan rao | C20: 26 | F20: Razole(SC) | G20: RAZOLE | H20: KATRENIPADU | I20: 35 | J20: =IFERROR(VLOOKUP(G20&H20,$E$34:$H$62,4,0),0) -> 45 | K20: =I20-J20 -> -10 | T20: MANDAL | U20: Samples | V20: Req%
A21: 46046 | B21: krishna | C21: 41 | F21: Razole(SC) | G21: SAKHINETIPALLE | H21: SAKINETIPALLE | I21: 70 | J21: =IFERROR(VLOOKUP(G21&H21,$E$34:$H$62,4,0),0) -> 78 | K21: =I21-J21 -> -8 | T21: MALIKIPURAM | U21: 315 | V21: 0.31016074
A22: 46046 | B22: Bommappagari Obulapathi | C22: 33 | F22: Razole(SC) | G22: SAKHINETIPALLE | H22: KESAVADASUPALEM | I22: 70 | J22: =IFERROR(VLOOKUP(G22&H22,$E$34:$H$62,4,0),0) -> 79 | K22: =I22-J22 -> -9 | T22: MAMIDIKUDURU_PART | U22: 140 | V22: 0.11239633
A23: 46046 | B23: aithabattula venkateswararao | C23: 41 | F23: Razole(SC) | G23: SAKHINETIPALLE | H23: VUYYURIVARI MERAKA | I23: 35 | J23: =IFERROR(VLOOKUP(G23&H23,$E$34:$H$62,4,0),0) -> 6 | K23: =I23-J23 -> 29 | T23: RAZOLE | U23: 315 | V23: 0.28929878
A24: 46047 | B24: Kumpatla venkata satya suryamohan rao | C24: 20 | F24: Razole(SC) | G24: SAKHINETIPALLE | H24: ANTARVEDIPALEM | I24: 35 | J24: =IFERROR(VLOOKUP(G24&H24,$E$34:$H$62,4,0),0) -> 35 | K24: =I24-J24 -> 0 | T24: SAKHINETIPALLE | U24: 280 | V24: 0.28814415
A25: 46047 | B25: aithabattula venkateswararao | C25: 29 | F25: Razole(SC) | G25: SAKHINETIPALLE | H25: ANTARVEDI | I25: 35 | J25: =IFERROR(VLOOKUP(G25&H25,$E$34:$H$62,4,0),0) -> 37 | K25: =I25-J25 -> -2 | T25: Grand Total | U25: 1050 | V25: =SUM(V21:V24) -> 1
A26: 46048 | B26: aithabattula venkateswararao | C26: 67 | F26: Razole(SC) | G26: SAKHINETIPALLE | H26: GONDI | I26: 35 | J26: =IFERROR(VLOOKUP(G26&H26,$E$34:$H$62,4,0),0) -> 16 | K26: =I26-J26 -> 19
A27: 46049 | B27: aithabattula venkateswararao | C27: 49
A28: 46050 | B28: aithabattula venkateswararao | C28: 8
A29: Grand Total | C29: 819
F31: Valid or Not | G31: Valid | N31: Valid or Not | O31: Valid | T31: Valid or Not | U31: Valid
F33: Taluka | G33: Locality | H33: Count of Q18: Gender | N33: Taluka | O33: Count of Q18: Gender | T33: Count of Q18: Gender | U33: Q18: Gender
E34: =F34&G34 -> MAMIDIKUDURU_PARTB.DODDAVARAM | F34: MAMIDIKUDURU_PART | G34: B.DODDAVARAM | H34: 32 | N34: MAMIDIKUDURU_PART | O34: 149 | T34: Taluka | U34: Male | V34: Female | W34: Grand Total
E35: =F35&G35 -> MAMIDIKUDURU_PARTPEDAPATNAM | F35: MAMIDIKUDURU_PART | G35: PEDAPATNAM | H35: 34 | N35: RAZOLE | O35: 258 | T35: MAMIDIKUDURU_PART | U35: 109 | V35: 40 | W35: 149
E36: =F36&G36 -> MAMIDIKUDURU_PARTPEDAPATNAM LANKA | F36: MAMIDIKUDURU_PART | G36: PEDAPATNAM LANKA | H36: 41 | N36: SAKHINETIPALLE | O36: 251 | T36: RAZOLE | U36: 148 | V36: 110 | W36: 258
E37: =F37&G37 -> MAMIDIKUDURU_PARTPASARLAPUDI LANKA | F37: MAMIDIKUDURU_PART | G37: PASARLAPUDI LANKA | H37: 42 | N37: MALIKIPURAM | O37: 161 | T37: SAKHINETIPALLE | U37: 201 | V37: 50 | W37: 251
E38: =F38&G38 -> RAZOLERAZOLE | F38: RAZOLE | G38: RAZOLE | H38: 29 | N38: Grand Total | O38: 819 | T38: MALIKIPURAM | U38: 130 | V38: 31 | W38: 161
E39: =F39&G39 -> RAZOLETATIPAKA | F39: RAZOLE | G39: TATIPAKA | H39: 38 | T39: Grand Total | U39: 588 | V39: 231 | W39: 819
E40: =F40&G40 -> RAZOLEKADALI | F40: RAZOLE | G40: KADALI | H40: 28
E41: =F41&G41 -> RAZOLEPONNAMANDA | F41: RAZOLE | G41: PONNAMANDA | H41: 1
E42: =F42&G42 -> RAZOLEKATRENIPADU | F42: RAZOLE | G42: KATRENIPADU | H42: 45
...

Sheet Factor
A1: Caste | B1: Pop% | C1: Rev % | D1: Samples | H1: Caste | I1: Samples | J1: TBT | K1: Factor | N1: Caste | O1: Samples | P1: Female | Q1: Male | R1: TBT | S1: Female/Male TBT | U1: Caste | V1: Gender | W1: =U1&V1 -> CasteGender | X1: Factor | AA1: Valid or Not | AB1: Valid
A2: Mala | B2: 0.26544058 | C2: 0.28917814 | D2: 289.17814 | H2: Mala | I2: =COUNTIFS(Table1[Caste],$H2,Table1[Valid or Not],"Valid") -> 209 | J2: =VLOOKUP(H2,$A$1:$D$13,4,0) -> 289.17814 | K2: =J2/I2 -> 1.3836275 | N2: Mala | O2: =COUNTIFS(Table1[Caste],N2,Table1[Valid or Not],"Valid") -> 209 | P2: =COUNTIFS(Table1[Caste],N2,Table1[Q18: Gender],"Female",Table1[Valid or Not],"Valid") -> 75 | Q2: =COUNTIFS(Table1[Caste],N2,Table1[Q18: Gender],"Male",Table1[Valid or Not],"Valid") -> 134 | R2: =VLOOKUP(N2,$A$1:$C$13,3,0)*1000 -> 289.17814 | S2: =R2*0.5 -> 144.58907 | U2: Mala | V2: Female | W2: =U2&V2 -> MalaFemale | X2: =VLOOKUP(U2,$N$1:$S$13,6,0)/VLOOKUP(U2,$N$1:$S$13,3,0) -> 1.9278542
A3: Kapu | B3: 0.26301958 | C3: 0.28654064 | D3: 286.54064 | H3: Kapu | I3: =COUNTIFS(Table1[Caste],$H3,Table1[Valid or Not],"Valid") -> 250 | J3: =VLOOKUP(H3,$A$1:$D$13,4,0) -> 286.54064 | K3: =J3/I3 -> 1.1461626 | N3: Kapu | O3: =COUNTIFS(Table1[Caste],N3,Table1[Valid or Not],"Valid") -> 250 | P3: =COUNTIFS(Table1[Caste],N3,Table1[Q18: Gender],"Female",Table1[Valid or Not],"Valid") -> 51 | Q3: =COUNTIFS(Table1[Caste],N3,Table1[Q18: Gender],"Male",Table1[Valid or Not],"Valid") -> 199 | R3: =VLOOKUP(N3,$A$1:$C$13,3,0)*1000 -> 286.54064 | S3: =R3*0.5 -> 143.27032 | U3: Kapu | V3: Female | W3: =U3&V3 -> KapuFemale | X3: =VLOOKUP(U3,$N$1:$S$13,6,0)/VLOOKUP(U3,$N$1:$S$13,3,0) -> 2.8092219 | AA3: Count of Q18: Gender | AC3: Q18: Gender
A4: Settibalija | B4: 0.16438776 | C4: 0.17908846 | D4: 179.08846 | H4: Settibalija | I4: =COUNTIFS(Table1[Caste],$H4,Table1[Valid or Not],"Valid") -> 153 | J4: =VLOOKUP(H4,$A$1:$D$13,4,0) -> 179.08846 | K4: =J4/I4 -> 1.1705128 | N4: Settibalija | O4: =COUNTIFS(Table1[Caste],N4,Table1[Valid or Not],"Valid") -> 153 | P4: =COUNTIFS(Table1[Caste],N4,Table1[Q18: Gender],"Female",Table1[Valid or Not],"Valid") -> 41 | Q4: =COUNTIFS(Table1[Caste],N4,Table1[Q18: Gender],"Male",Table1[Valid or Not],"Valid") -> 112 | R4: =VLOOKUP(N4,$A$1:$C$13,3,0)*1000 -> 179.08846 | S4: =R4*0.5 -> 89.544231 | U4: Settibalija | V4: Female | W4: =U4&V4 -> SettibalijaFemale | X4: =VLOOKUP(U4,$N$1:$S$13,6,0)/VLOOKUP(U4,$N$1:$S$13,3,0) -> 2.1840056 | AA4: Taluka | AB4: Caste | AC4: Male | AD4: Female | AE4: Grand Total | AF4: TBT | AG4: TBT Male/Female | AI4: Mandal | AJ4: Caste | AK4: Male | AL4: Factor
A5: Agnikulakshatriya | B5: 0.084511414 | C5: 0.092069017 | D5: 92.069017 | H5: Agnikulakshatriya | I5: =COUNTIFS(Table1[Caste],$H5,Table1[Valid or Not],"Valid") -> 73 | J5: =VLOOKUP(H5,$A$1:$D$13,4,0) -> 92.069017 | K5: =J5/I5 -> 1.2612194 | N5: Agnikulakshatriya | O5: =COUNTIFS(Table1[Caste],N5,Table1[Valid or Not],"Valid") -> 73 | P5: =COUNTIFS(Table1[Caste],N5,Table1[Q18: Gender],"Female",Table1[Valid or Not],"Valid") -> 19 | Q5: =COUNTIFS(Table1[Caste],N5,Table1[Q18: Gender],"Male",Table1[Valid or Not],"Valid") -> 54 | R5: =VLOOKUP(N5,$A$1:$C$13,3,0)*1000 -> 92.069017 | S5: =R5*0.5 -> 46.034508 | U5: Agnikulakshatriya | V5: Female | W5: =U5&V5 -> AgnikulakshatriyaFemale | X5: =VLOOKUP(U5,$N$1:$S$13,6,0)/VLOOKUP(U5,$N$1:$S$13,3,0) -> 2.4228689 | Z5: =AA5&AB5 -> MAMIDIKUDURU_PARTMala | AA5: MAMIDIKUDURU_PART | AB5: Mala | AC5: 31 | AD5: 17 | AE5: 48 | AF5: =VLOOKUP(AA5,$D$42:$E$46,2,0)*VLOOKUP(AB5,$A$1:$C$13,3,0)*1000 -> 32.502562 | AG5: =AF5*0.5 -> 16.251281 | AI5: MAMIDIKUDURU_PART | AJ5: Mala | AK5: =AI5&AJ5&$AK$4 -> MAMIDIKUDURU_PARTMalaMale | AL5: =IFERROR(VLOOKUP(AI5&AJ5,$Z$5:$AG$71,8,0)/VLOOKUP(AI5&AJ5,$Z$5:$AG$71,4,0),0) -> 0.52423487
A6: Madiga | B6: 0.036811568 | C6: 0.040103516 | D6: 40.103516 | H6: Madiga | I6: =COUNTIFS(Table1[Caste],$H6,Table1[Valid or Not],"Valid") -> 50 | J6: =VLOOKUP(H6,$A$1:$D$13,4,0) -> 40.103516 | K6: =J6/I6 -> 0.80207032 | N6: Madiga | O6: =COUNTIFS(Table1[Caste],N6,Table1[Valid or Not],"Valid") -> 50 | P6: =COUNTIFS(Table1[Caste],N6,Table1[Q18: Gender],"Female",Table1[Valid or Not],"Valid") -> 17 | Q6: =COUNTIFS(Table1[Caste],N6,Table1[Q18: Gender],"Male",Table1[Valid or Not],"Valid") -> 33 | R6: =VLOOKUP(N6,$A$1:$C$13,3,0)*1000 -> 40.103516 | S6: =R6*0.5 -> 20.051758 | U6: Madiga | V6: Female | W6: =U6&V6 -> MadigaFemale | X6: =VLOOKUP(U6,$N$1:$S$13,6,0)/VLOOKUP(U6,$N$1:$S$13,3,0) -> 1.1795152 | Z6: =AA6&AB6 -> MAMIDIKUDURU_PARTKapu | AA6: MAMIDIKUDURU_PART | AB6: Kapu | AC6: 29 | AD6: 3 | AE6: 32 | AF6: =VLOOKUP(AA6,$D$42:$E$46,2,0)*VLOOKUP(AB6,$A$1:$C$13,3,0)*1000 -> 32.206117 | AG6: =AF6*0.5 -> 16.103058 | AI6: MAMIDIKUDURU_PART | AJ6: Kapu | AK6: =AI6&AJ6&$AK$4 -> MAMIDIKUDURU_PARTKapuMale | AL6: =IFERROR(VLOOKUP(AI6&AJ6,$Z$5:$AG$71,8,0)/VLOOKUP(AI6&AJ6,$Z$5:$AG$71,4,0),0) -> 0.55527787
A7: Padmasali/Devanga | B7: 0.026076412 | C7: 0.028408348 | D7: 28.408348 | H7: Padmasali/Devanga | I7: =COUNTIFS(Table1[Caste],$H7,Table1[Valid or Not],"Valid") -> 13 | J7: =VLOOKUP(H7,$A$1:$D$13,4,0) -> 28.408348 | K7: =J7/I7 -> 2.1852575 | N7: Padmasali/Devanga | O7: =COUNTIFS(Table1[Caste],N7,Table1[Valid or Not],"Valid") -> 13 | P7: =COUNTIFS(Table1[Caste],N7,Table1[Q18: Gender],"Female",Table1[Valid or Not],"Valid") -> 4 | Q7: =COUNTIFS(Table1[Caste],N7,Table1[Q18: Gender],"Male",Table1[Valid or Not],"Valid") -> 9 | R7: =VLOOKUP(N7,$A$1:$C$13,3,0)*1000 -> 28.408348 | S7: =R7*0.5 -> 14.204174 | U7: Padmasali/Devanga | V7: Female | W7: =U7&V7 -> Padmasali/DevangaFemale | X7: =VLOOKUP(U7,$N$1:$S$13,6,0)/VLOOKUP(U7,$N$1:$S$13,3,0) -> 3.5510435 | Z7: =AA7&AB7 -> MAMIDIKUDURU_PARTSettibalija | AA7: MAMIDIKUDURU_PART | AB7: Settibalija | AC7: 25 | AD7: 9 | AE7: 34 | AF7: =VLOOKUP(AA7,$D$42:$E$46,2,0)*VLOOKUP(AB7,$A$1:$C$13,3,0)*1000 -> 20.128886 | AG7: =AF7*0.5 -> 10.064443 | AI7: MAMIDIKUDURU_PART | AJ7: Settibalija | AK7: =AI7&AJ7&$AK$4 -> MAMIDIKUDURU_PARTSettibalijaMale | AL7: =IFERROR(VLOOKUP(AI7&AJ7,$Z$5:$AG$71,8,0)/VLOOKUP(AI7&AJ7,$Z$5:$AG$71,4,0),0) -> 0.40257772
A8: Yadava | B8: 0.019550067 | C8: 0.021298371 | D8: 21.298371 | H8: Yadava | I8: =COUNTIFS(Table1[Caste],$H8,Table1[Valid or Not],"Valid") -> 19 | J8: =VLOOKUP(H8,$A$1:$D$13,4,0) -> 21.298371 | K8: =J8/I8 -> 1.1209669 | N8: Yadava | O8: =COUNTIFS(Table1[Caste],N8,Table1[Valid or Not],"Valid") -> 19 | P8: =COUNTIFS(Table1[Caste],N8,Table1[Q18: Gender],"Female",Table1[Valid or Not],"Valid") -> 8 | Q8: =COUNTIFS(Table1[Caste],N8,Table1[Q18: Gender],"Male",Table1[Valid or Not],"Valid") -> 11 | R8: =VLOOKUP(N8,$A$1:$C$13,3,0)*1000 -> 21.298371 | S8: =R8*0.5 -> 10.649186 | U8: Yadava | V8: Female | W8: =U8&V8 -> YadavaFemale | X8: =VLOOKUP(U8,$N$1:$S$13,6,0)/VLOOKUP(U8,$N$1:$S$13,3,0) -> 1.3311482 | Z8: =AA8&AB8 -> MAMIDIKUDURU_PARTAgnikulakshatriya | AA8: MAMIDIKUDURU_PART | AB8: Agnikulakshatriya | AC8: 4 | AD8: 1 | AE8: 5 | AF8: =VLOOKUP(AA8,$D$42:$E$46,2,0)*VLOOKUP(AB8,$A$1:$C$13,3,0)*1000 -> 10.34822 | AG8: =AF8*0.5 -> 5.1741099 | AI8: MAMIDIKUDURU_PART | AJ8: Agnikulakshatriya | AK8: =AI8&AJ8&$AK$4 -> MAMIDIKUDURU_PARTAgnikulakshatriyaMale | AL8: =IFERROR(VLOOKUP(AI8&AJ8,$Z$5:$AG$71,8,0)/VLOOKUP(AI8&AJ8,$Z$5:$AG$71,4,0),0) -> 1.2935275
A9: Kshatriya/Rajulu | B9: 0.01863133 | C9: 0.020297474 | D9: 20.297474 | H9: Kshatriya/Rajulu | I9: =COUNTIFS(Table1[Caste],$H9,Table1[Valid or Not],"Valid") -> 11 | J9: =VLOOKUP(H9,$A$1:$D$13,4,0) -> 20.297474 | K9: =J9/I9 -> 1.8452249 | N9: Kshatriya/Rajulu | O9: =COUNTIFS(Table1[Caste],N9,Table1[Valid or Not],"Valid") -> 11 | P9: =COUNTIFS(Table1[Caste],N9,Table1[Q18: Gender],"Female",Table1[Valid or Not],"Valid") -> 4 | Q9: =COUNTIFS(Table1[Caste],N9,Table1[Q18: Gender],"Male",Table1[Valid or Not],"Valid") -> 7 | R9: =VLOOKUP(N9,$A$1:$C$13,3,0)*1000 -> 20.297474 | S9: =R9*0.5 -> 10.148737 | U9: Kshatriya/Rajulu | V9: Female | W9: =U9&V9 -> Kshatriya/RajuluFemale | X9: =VLOOKUP(U9,$N$1:$S$13,6,0)/VLOOKUP(U9,$N$1:$S$13,3,0) -> 2.5371842 | Z9: =AA9&AB9 -> MAMIDIKUDURU_PARTMadiga | AA9: MAMIDIKUDURU_PART | AB9: Madiga | AC9: 10 | AD9: 6 | AE9: 16 | AF9: =VLOOKUP(AA9,$D$42:$E$46,2,0)*VLOOKUP(AB9,$A$1:$C$13,3,0)*1000 -> 4.5074881 | AG9: =AF9*0.5 -> 2.2537441 | AI9: MAMIDIKUDURU_PART | AJ9: Madiga | AK9: =AI9&AJ9&$AK$4 -> MAMIDIKUDURU_PARTMadigaMale | AL9: =IFERROR(VLOOKUP(AI9&AJ9,$Z$5:$AG$71,8,0)/VLOOKUP(AI9&AJ9,$Z$5:$AG$71,4,0),0) -> 0.22537441
A10: Rajaka | B10: 0.018275423 | C10: 0.019909739 | D10: 19.909739 | H10: Rajaka | I10: =COUNTIFS(Table1[Caste],$H10,Table1[Valid or Not],"Valid") -> 19 | J10: =VLOOKUP(H10,$A$1:$D$13,4,0) -> 19.909739 | K10: =J10/I10 -> 1.047881 | N10: Rajaka | O10: =COUNTIFS(Table1[Caste],N10,Table1[Valid or Not],"Valid") -> 19 | P10: =COUNTIFS(Table1[Caste],N10,Table1[Q18: Gender],"Female",Table1[Valid or Not],"Valid") -> 6 | Q10: =COUNTIFS(Table1[Caste],N10,Table1[Q18: Gender],"Male",Table1[Valid or Not],"Valid") -> 13 | R10: =VLOOKUP(N10,$A$1:$C$13,3,0)*1000 -> 19.909739 | S10: =R10*0.5 -> 9.9548695 | U10: Rajaka | V10: Female | W10: =U10&V10 -> RajakaFemale | X10: =VLOOKUP(U10,$N$1:$S$13,6,0)/VLOOKUP(U10,$N$1:$S$13,3,0) -> 1.6591449 | Z10: =AA10&AB10 -> MAMIDIKUDURU_PARTPadmasali/Devanga | AA10: MAMIDIKUDURU_PART | AB10: Padmasali/Devanga | AC10: 2 | AE10: 2 | AF10: =VLOOKUP(AA10,$D$42:$E$46,2,0)*VLOOKUP(AB10,$A$1:$C$13,3,0)*1000 -> 3.1929941 | AG10: =AF10*0.5 -> 1.5964971 | AI10: MAMIDIKUDURU_PART | AJ10: Padmasali/Devanga | AK10: =AI10&AJ10&$AK$4 -> MAMIDIKUDURU_PARTPadmasali/DevangaMale | AL10: =IFERROR(VLOOKUP(AI10&AJ10,$Z$5:$AG$71,8,0)/VLOOKUP(AI10&AJ10,$Z$5:$AG$71,4,0),0) -> 0.79824853
A11: Adi Andhra | B11: 0.011881508 | C11: 0.012944035 | D11: 12.944035 | H11: Adi Andhra | I11: =COUNTIFS(Table1[Caste],$H11,Table1[Valid or Not],"Valid") -> 12 | J11: =VLOOKUP(H11,$A$1:$D$13,4,0) -> 12.944035 | K11: =J11/I11 -> 1.0786696 | N11: Adi Andhra | O11: =COUNTIFS(Table1[Caste],N11,Table1[Valid or Not],"Valid") -> 12 | P11: =COUNTIFS(Table1[Caste],N11,Table1[Q18: Gender],"Female",Table1[Valid or Not],"Valid") -> 6 | Q11: =COUNTIFS(Table1[Caste],N11,Table1[Q18: Gender],"Male",Table1[Valid or Not],"Valid") -> 6 | R11: =VLOOKUP(N11,$A$1:$C$13,3,0)*1000 -> 12.944035 | S11: =R11*0.5 -> 6.4720177 | U11: Adi Andhra | V11: Female | W11: =U11&V11 -> Adi AndhraFemale | X11: =VLOOKUP(U11,$N$1:$S$13,6,0)/VLOOKUP(U11,$N$1:$S$13,3,0) -> 1.0786696 | Z11: =AA11&AB11 -> MAMIDIKUDURU_PARTKshatriya/Rajulu | AA11: MAMIDIKUDURU_PART | AB11: Kshatriya/Rajulu | AC11: 1 | AE11: 1 | AF11: =VLOOKUP(AA11,$D$42:$E$46,2,0)*VLOOKUP(AB11,$A$1:$C$13,3,0)*1000 -> 2.2813616 | AG11: =AF11*0.5 -> 1.1406808 | AI11: MAMIDIKUDURU_PART | AJ11: Yadava | AK11: =AI11&AJ11&$AK$4 -> MAMIDIKUDURU_PARTYadavaMale | AL11: =IFERROR(VLOOKUP(AI11&AJ11,$Z$5:$AG$71,8,0)/VLOOKUP(AI11&AJ11,$Z$5:$AG$71,4,0),0) -> 0
A12: Brahmin | B12: 0.0093280803 | C12: 0.010162263 | D12: 10.162263 | H12: Brahmin | I12: =COUNTIFS(Table1[Caste],$H12,Table1[Valid or Not],"Valid") -> 10 | J12: =VLOOKUP(H12,$A$1:$D$13,4,0) -> 10.162263 | K12: =J12/I12 -> 1.0162263 | N12: Brahmin | O12: =COUNTIFS(Table1[Caste],N12,Table1[Valid or Not],"Valid") -> 10 | P12: =COUNTIFS(Table1[Caste],N12,Table1[Q18: Gender],"Female",Table1[Valid or Not],"Valid") -> 0 | Q12: =COUNTIFS(Table1[Caste],N12,Table1[Q18: Gender],"Male",Table1[Valid or Not],"Valid") -> 10 | R12: =VLOOKUP(N12,$A$1:$C$13,3,0)*1000 -> 10.162263 | S12: =R12*0.5 -> 5.0811313 | U12: Brahmin | V12: Female | W12: =U12&V12 -> BrahminFemale | X12: =VLOOKUP(U12,$N$1:$S$13,6,0)/VLOOKUP(U12,$N$1:$S$13,3,0) -> #DIV/0! | Z12: =AA12&AB12 -> MAMIDIKUDURU_PARTAdi Andhra | AA12: MAMIDIKUDURU_PART | AB12: Adi Andhra | AC12: 2 | AD12: 2 | AE12: 4 | AF12: =VLOOKUP(AA12,$D$42:$E$46,2,0)*VLOOKUP(AB12,$A$1:$C$13,3,0)*1000 -> 1.4548621 | AG12: =AF12*0.5 -> 0.72743105 | AI12: MAMIDIKUDURU_PART | AJ12: Kshatriya/Rajulu | AK12: =AI12&AJ12&$AK$4 -> MAMIDIKUDURU_PARTKshatriya/RajuluMale | AL12: =IFERROR(VLOOKUP(AI12&AJ12,$Z$5:$AG$71,8,0)/VLOOKUP(AI12&AJ12,$Z$5:$AG$71,4,0),0) -> 1.1406808
B13: 0.91791372 | C13: 1 | D13: =SUM(D2:D12) -> 1000 | H13: Grand Total | I13: =SUM(I2:I12) -> 819 | J13: =SUM(J2:J12) -> 1000 | N13: Grand Total | O13: =SUM(O2:O12) -> 819 | P13: =SUM(P2:P12) -> 231 | Q13: =SUM(Q2:Q12) -> 588 | R13: =SUM(R2:R12) -> 1000 | S13: =SUM(S2:S12) -> 500 | U13: Mala | V13: Male | W13: =U13&V13 -> MalaMale | X13: =VLOOKUP(U13,$N$1:$S$13,6,0)/VLOOKUP(U13,$N$1:$S$13,4,0) -> 1.0790229 | Z13: =AA13&AB13 -> MAMIDIKUDURU_PARTRajaka | AA13: MAMIDIKUDURU_PART | AB13: Rajaka | AC13: 5 | AD13: 2 | AE13: 7 | AF13: =VLOOKUP(AA13,$D$42:$E$46,2,0)*VLOOKUP(AB13,$A$1:$C$13,3,0)*1000 -> 2.2377816 | AG13: =AF13*0.5 -> 1.1188908 | AI13: MAMIDIKUDURU_PART | AJ13: Rajaka | AK13: =AI13&AJ13&$AK$4 -> MAMIDIKUDURU_PARTRajakaMale | AL13: =IFERROR(VLOOKUP(AI13&AJ13,$Z$5:$AG$71,8,0)/VLOOKUP(AI13&AJ13,$Z$5:$AG$71,4,0),0) -> 0.22377816
U14: Kapu | V14: Male | W14: =U14&V14 -> KapuMale | X14: =VLOOKUP(U14,$N$1:$S$13,6,0)/VLOOKUP(U14,$N$1:$S$13,4,0) -> 0.71995135 | Z14: =AA14&AB14 -> RAZOLEMala | AA14: RAZOLE | AB14: Mala | AC14: 46 | AD14: 34 | AE14: 80 | AF14: =VLOOKUP(AA14,$D$42:$E$46,2,0)*VLOOKUP(AB14,$A$1:$C$13,3,0)*1000 -> 83.658882 | AG14: =AF14*0.5 -> 41.829441 | AI14: MAMIDIKUDURU_PART | AJ14: Adi Andhra | AK14: =AI14&AJ14&$AK$4 -> MAMIDIKUDURU_PARTAdi AndhraMale | AL14: =IFERROR(VLOOKUP(AI14&AJ14,$Z$5:$AG$71,8,0)/VLOOKUP(AI14&AJ14,$Z$5:$AG$71,4,0),0) -> 0.36371552
U15: Settibalija | V15: Male | W15: =U15&V15 -> SettibalijaMale | X15: =VLOOKUP(U15,$N$1:$S$13,6,0)/VLOOKUP(U15,$N$1:$S$13,4,0) -> 0.79950206 | Z15: =AA15&AB15 -> RAZOLEKapu | AA15: RAZOLE | AB15: Kapu | AC15: 31 | AD15: 23 | AE15: 54 | AF15: =VLOOKUP(AA15,$D$42:$E$46,2,0)*VLOOKUP(AB15,$A$1:$C$13,3,0)*1000 -> 82.895857 | AG15: =AF15*0.5 -> 41.447928 | AI15: MAMIDIKUDURU_PART | AJ15: Brahmin | AK15: =AI15&AJ15&$AK$4 -> MAMIDIKUDURU_PARTBrahminMale | AL15: =IFERROR(VLOOKUP(AI15&AJ15,$Z$5:$AG$71,8,0)/VLOOKUP(AI15&AJ15,$Z$5:$AG$71,4,0),0) -> 0
U16: Agnikulakshatriya | V16: Male | W16: =U16&V16 -> AgnikulakshatriyaMale | X16: =VLOOKUP(U16,$N$1:$S$13,6,0)/VLOOKUP(U16,$N$1:$S$13,4,0) -> 0.8524909 | Z16: =AA16&AB16 -> RAZOLESettibalija | AA16: RAZOLE | AB16: Settibalija | AC16: 35 | AD16: 27 | AE16: 62 | AF16: =VLOOKUP(AA16,$D$42:$E$46,2,0)*VLOOKUP(AB16,$A$1:$C$13,3,0)*1000 -> 51.810074 | AG16: =AF16*0.5 -> 25.905037 | AI16: RAZOLE | AJ16: Mala | AK16: =AI16&AJ16&$AK$4 -> RAZOLEMalaMale | AL16: =IFERROR(VLOOKUP(AI16&AJ16,$Z$5:$AG$71,8,0)/VLOOKUP(AI16&AJ16,$Z$5:$AG$71,4,0),0) -> 0.90933568
U17: Madiga | V17: Male | W17: =U17&V17 -> MadigaMale | X17: =VLOOKUP(U17,$N$1:$S$13,6,0)/VLOOKUP(U17,$N$1:$S$13,4,0) -> 0.60762903 | Z17: =AA17&AB17 -> RAZOLEAgnikulakshatriya | AA17: RAZOLE | AB17: Agnikulakshatriya | AC17: 10 | AD17: 8 | AE17: 18 | AF17: =VLOOKUP(AA17,$D$42:$E$46,2,0)*VLOOKUP(AB17,$A$1:$C$13,3,0)*1000 -> 26.635454 | AG17: =AF17*0.5 -> 13.317727 | AI17: RAZOLE | AJ17: Kapu | AK17: =AI17&AJ17&$AK$4 -> RAZOLEKapuMale | AL17: =IFERROR(VLOOKUP(AI17&AJ17,$Z$5:$AG$71,8,0)/VLOOKUP(AI17&AJ17,$Z$5:$AG$71,4,0),0) -> 1.33703
U18: Padmasali/Devanga | V18: Male | W18: =U18&V18 -> Padmasali/DevangaMale | X18: =VLOOKUP(U18,$N$1:$S$13,6,0)/VLOOKUP(U18,$N$1:$S$13,4,0) -> 1.5782416 | Z18: =AA18&AB18 -> RAZOLEMadiga | AA18: RAZOLE | AB18: Madiga | AC18: 15 | AD18: 5 | AE18: 20 | AF18: =VLOOKUP(AA18,$D$42:$E$46,2,0)*VLOOKUP(AB18,$A$1:$C$13,3,0)*1000 -> 11.601898 | AG18: =AF18*0.5 -> 5.8009492 | AI18: RAZOLE | AJ18: Settibalija | AK18: =AI18&AJ18&$AK$4 -> RAZOLESettibalijaMale | AL18: =IFERROR(VLOOKUP(AI18&AJ18,$Z$5:$AG$71,8,0)/VLOOKUP(AI18&AJ18,$Z$5:$AG$71,4,0),0) -> 0.74014391
A19: Valid or Not | B19: Valid | U19: Yadava | V19: Male | W19: =U19&V19 -> YadavaMale | X19: =VLOOKUP(U19,$N$1:$S$13,6,0)/VLOOKUP(U19,$N$1:$S$13,4,0) -> 0.96810778 | Z19: =AA19&AB19 -> RAZOLEPadmasali/Devanga | AA19: RAZOLE | AB19: Padmasali/Devanga | AC19: 1 | AD19: 4 | AE19: 5 | AF19: =VLOOKUP(AA19,$D$42:$E$46,2,0)*VLOOKUP(AB19,$A$1:$C$13,3,0)*1000 -> 8.2185004 | AG19: =AF19*0.5 -> 4.1092502 | AI19: RAZOLE | AJ19: Agnikulakshatriya | AK19: =AI19&AJ19&$AK$4 -> RAZOLEAgnikulakshatriyaMale | AL19: =IFERROR(VLOOKUP(AI19&AJ19,$Z$5:$AG$71,8,0)/VLOOKUP(AI19&AJ19,$Z$5:$AG$71,4,0),0) -> 1.3317727
U20: Kshatriya/Rajulu | V20: Male | W20: =U20&V20 -> Kshatriya/RajuluMale | X20: =VLOOKUP(U20,$N$1:$S$13,6,0)/VLOOKUP(U20,$N$1:$S$13,4,0) -> 1.4498196 | Z20: =AA20&AB20 -> RAZOLEYadava | AA20: RAZOLE | AB20: Yadava | AD20: 2 | AE20: 2 | AF20: =VLOOKUP(AA20,$D$42:$E$46,2,0)*VLOOKUP(AB20,$A$1:$C$13,3,0)*1000 -> 6.1615928 | AG20: =AF20*0.5 -> 3.0807964 | AI20: RAZOLE | AJ20: Madiga | AK20: =AI20&AJ20&$AK$4 -> RAZOLEMadigaMale | AL20: =IFERROR(VLOOKUP(AI20&AJ20,$Z$5:$AG$71,8,0)/VLOOKUP(AI20&AJ20,$Z$5:$AG$71,4,0),0) -> 0.38672994
A21: 2024 AE | B21: Count of Q18: Gender | C21: Count of Q18: Gender2 | E21: Collected | F21: 2024 Result | G21: TBT | H21: Factor | U21: Rajaka | V21: Male | W21: =U21&V21 -> RajakaMale | X21: =VLOOKUP(U21,$N$1:$S$13,6,0)/VLOOKUP(U21,$N$1:$S$13,4,0) -> 0.76575919 | Z21: =AA21&AB21 -> RAZOLEKshatriya/Rajulu | AA21: RAZOLE | AB21: Kshatriya/Rajulu | AC21: 3 | AD21: 2 | AE21: 5 | AF21: =VLOOKUP(AA21,$D$42:$E$46,2,0)*VLOOKUP(AB21,$A$1:$C$13,3,0)*1000 -> 5.8720344 | AG21: =AF21*0.5 -> 2.9360172 | AI21: RAZOLE | AJ21: Padmasali/Devanga | AK21: =AI21&AJ21&$AK$4 -> RAZOLEPadmasali/DevangaMale | AL21: =IFERROR(VLOOKUP(AI21&AJ21,$Z$5:$AG$71,8,0)/VLOOKUP(AI21&AJ21,$Z$5:$AG$71,4,0),0) -> 4.1092502
A22: YSRCP (వైఎస్‌ఆర్‌సీపీ) | B22: 197 | C22: 0.24053724 | D22: YSRCP (వైఎస్‌ఆర్‌సీపీ) | E22: =VLOOKUP(D22,$A$22:$B$25,2,0) -> 197 | F22: 0.3557 | G22: =F22*1000 -> 355.7 | H22: =G22/E22 -> 1.8055838 | U22: Adi Andhra | V22: Male | W22: =U22&V22 -> Adi AndhraMale | X22: =VLOOKUP(U22,$N$1:$S$13,6,0)/VLOOKUP(U22,$N$1:$S$13,4,0) -> 1.0786696 | Z22: =AA22&AB22 -> RAZOLEAdi Andhra | AA22: RAZOLE | AB22: Adi Andhra | AC22: 4 | AD22: 3 | AE22: 7 | AF22: =VLOOKUP(AA22,$D$42:$E$46,2,0)*VLOOKUP(AB22,$A$1:$C$13,3,0)*1000 -> 3.7446937 | AG22: =AF22*0.5 -> 1.8723468 | AI22: RAZOLE | AJ22: Yadava | AK22: =AI22&AJ22&$AK$4 -> RAZOLEYadavaMale | AL22: =IFERROR(VLOOKUP(AI22&AJ22,$Z$5:$AG$71,8,0)/VLOOKUP(AI22&AJ22,$Z$5:$AG$71,4,0),0) -> 0
A23: TDP/JSP/BJP (కూటమి) | B23: 557 | C23: 0.68009768 | D23: TDP/JSP/BJP (కూటమి) | E23: =VLOOKUP(D23,$A$22:$B$25,2,0) -> 557 | F23: 0.6013 | G23: =F23*1000 -> 601.3 | H23: =G23/E23 -> 1.0795332 | U23: Brahmin | V23: Male | W23: =U23&V23 -> BrahminMale | X23: =VLOOKUP(U23,$N$1:$S$13,6,0)/VLOOKUP(U23,$N$1:$S$13,4,0) -> 0.50811313 | Z23: =AA23&AB23 -> RAZOLERajaka | AA23: RAZOLE | AB23: Rajaka | AC23: 1 | AD23: 2 | AE23: 3 | AF23: =VLOOKUP(AA23,$D$42:$E$46,2,0)*VLOOKUP(AB23,$A$1:$C$13,3,0)*1000 -> 5.7598632 | AG23: =AF23*0.5 -> 2.8799316 | AI23: RAZOLE | AJ23: Kshatriya/Rajulu | AK23: =AI23&AJ23&$AK$4 -> RAZOLEKshatriya/RajuluMale | AL23: =IFERROR(VLOOKUP(AI23&AJ23,$Z$5:$AG$71,8,0)/VLOOKUP(AI23&AJ23,$Z$5:$AG$71,4,0),0) -> 0.9786724
A24: Others (ఇతరులు) | B24: 53 | C24: 0.064713065 | E24: =B27-SUM(E22:E23) -> 65 | F24: =1-SUM(F22:F23) -> 0.043 | G24: =F24*1000 -> 43 | H24: =G24/E24 -> 0.66153846 | Z24: =AA24&AB24 -> RAZOLEBrahmin | AA24: RAZOLE | AB24: Brahmin | AC24: 2 | AE24: 2 | AF24: =VLOOKUP(AA24,$D$42:$E$46,2,0)*VLOOKUP(AB24,$A$1:$C$13,3,0)*1000 -> 2.9399302 | AG24: =AF24*0.5 -> 1.4699651 | AI24: RAZOLE | AJ24: Rajaka | AK24: =AI24&AJ24&$AK$4 -> RAZOLERajakaMale | AL24: =IFERROR(VLOOKUP(AI24&AJ24,$Z$5:$AG$71,8,0)/VLOOKUP(AI24&AJ24,$Z$5:$AG$71,4,0),0) -> 2.8799316
A25: Did Not Vote | B25: 8 | C25: 0.0097680098 | Z25: =AA25&AB25 -> SAKHINETIPALLEMala | AA25: SAKHINETIPALLE | AB25: Mala | AC25: 36 | AD25: 13 | AE25: 49 | AF25: =VLOOKUP(AA25,$D$42:$E$46,2,0)*VLOOKUP(AB25,$A$1:$C$13,3,0)*1000 -> 83.324989 | AG25: =AF25*0.5 -> 41.662494 | AI25: RAZOLE | AJ25: Adi Andhra | AK25: =AI25&AJ25&$AK$4 -> RAZOLEAdi AndhraMale | AL25: =IFERROR(VLOOKUP(AI25&AJ25,$Z$5:$AG$71,8,0)/VLOOKUP(AI25&AJ25,$Z$5:$AG$71,4,0),0) -> 0.46808671
A26: INC (కాంగ్రెస్) | B26: 4 | C26: 0.0048840049 | Z26: =AA26&AB26 -> SAKHINETIPALLEKapu | AA26: SAKHINETIPALLE | AB26: Kapu | AC26: 76 | AD26: 18 | AE26: 94 | AF26: =VLOOKUP(AA26,$D$42:$E$46,2,0)*VLOOKUP(AB26,$A$1:$C$13,3,0)*1000 -> 82.565009 | AG26: =AF26*0.5 -> 41.282504 | AI26: RAZOLE | AJ26: Brahmin | AK26: =AI26&AJ26&$AK$4 -> RAZOLEBrahminMale | AL26: =IFERROR(VLOOKUP(AI26&AJ26,$Z$5:$AG$71,8,0)/VLOOKUP(AI26&AJ26,$Z$5:$AG$71,4,0),0) -> 0.73498254
A27: Grand Total | B27: 819 | C27: 1 | Z27: =AA27&AB27 -> SAKHINETIPALLESettibalija | AA27: SAKHINETIPALLE | AB27: Settibalija | AC27: 28 | AD27: 1 | AE27: 29 | AF27: =VLOOKUP(AA27,$D$42:$E$46,2,0)*VLOOKUP(AB27,$A$1:$C$13,3,0)*1000 -> 51.603293 | AG27: =AF27*0.5 -> 25.801646 | AI27: SAKHINETIPALLE | AJ27: Mala | AK27: =AI27&AJ27&$AK$4 -> SAKHINETIPALLEMalaMale | AL27: =IFERROR(VLOOKUP(AI27&AJ27,$Z$5:$AG$71,8,0)/VLOOKUP(AI27&AJ27,$Z$5:$AG$71,4,0),0) -> 1.1572915
Z28: =AA28&AB28 -> SAKHINETIPALLEAgnikulakshatriya | AA28: SAKHINETIPALLE | AB28: Agnikulakshatriya | AC28: 32 | AD28: 6 | AE28: 38 | AF28: =VLOOKUP(AA28,$D$42:$E$46,2,0)*VLOOKUP(AB28,$A$1:$C$13,3,0)*1000 -> 26.529149 | AG28: =AF28*0.5 -> 13.264574 | AI28: SAKHINETIPALLE | AJ28: Kapu | AK28: =AI28&AJ28&$AK$4 -> SAKHINETIPALLEKapuMale | AL28: =IFERROR(VLOOKUP(AI28&AJ28,$Z$5:$AG$71,8,0)/VLOOKUP(AI28&AJ28,$Z$5:$AG$71,4,0),0) -> 0.54319085
Z29: =AA29&AB29 -> SAKHINETIPALLEMadiga | AA29: SAKHINETIPALLE | AB29: Madiga | AC29: 5 | AD29: 3 | AE29: 8 | AF29: =VLOOKUP(AA29,$D$42:$E$46,2,0)*VLOOKUP(AB29,$A$1:$C$13,3,0)*1000 -> 11.555594 | AG29: =AF29*0.5 -> 5.7777968 | AI29: SAKHINETIPALLE | AJ29: Settibalija | AK29: =AI29&AJ29&$AK$4 -> SAKHINETIPALLESettibalijaMale | AL29: =IFERROR(VLOOKUP(AI29&AJ29,$Z$5:$AG$71,8,0)/VLOOKUP(AI29&AJ29,$Z$5:$AG$71,4,0),0) -> 0.92148737
Z30: =AA30&AB30 -> SAKHINETIPALLEPadmasali/Devanga | AA30: SAKHINETIPALLE | AB30: Padmasali/Devanga | AC30: 1 | AE30: 1 | AF30: =VLOOKUP(AA30,$D$42:$E$46,2,0)*VLOOKUP(AB30,$A$1:$C$13,3,0)*1000 -> 8.1856993 | AG30: =AF30*0.5 -> 4.0928497 | AI30: SAKHINETIPALLE | AJ30: Agnikulakshatriya | AK30: =AI30&AJ30&$AK$4 -> SAKHINETIPALLEAgnikulakshatriyaMale | AL30: =IFERROR(VLOOKUP(AI30&AJ30,$Z$5:$AG$71,8,0)/VLOOKUP(AI30&AJ30,$Z$5:$AG$71,4,0),0) -> 0.41451795
A31: Valid or Not | B31: Valid | Z31: =AA31&AB31 -> SAKHINETIPALLEYadava | AA31: SAKHINETIPALLE | AB31: Yadava | AC31: 10 | AD31: 6 | AE31: 16 | AF31: =VLOOKUP(AA31,$D$42:$E$46,2,0)*VLOOKUP(AB31,$A$1:$C$13,3,0)*1000 -> 6.137001 | AG31: =AF31*0.5 -> 3.0685005 | AI31: SAKHINETIPALLE | AJ31: Madiga | AK31: =AI31&AJ31&$AK$4 -> SAKHINETIPALLEMadigaMale | AL31: =IFERROR(VLOOKUP(AI31&AJ31,$Z$5:$AG$71,8,0)/VLOOKUP(AI31&AJ31,$Z$5:$AG$71,4,0),0) -> 1.1555594
Z32: =AA32&AB32 -> SAKHINETIPALLEKshatriya/Rajulu | AA32: SAKHINETIPALLE | AB32: Kshatriya/Rajulu | AC32: 1 | AD32: 1 | AE32: 2 | AF32: =VLOOKUP(AA32,$D$42:$E$46,2,0)*VLOOKUP(AB32,$A$1:$C$13,3,0)*1000 -> 5.8485984 | AG32: =AF32*0.5 -> 2.9242992 | AI32: SAKHINETIPALLE | AJ32: Padmasali/Devanga | AK32: =AI32&AJ32&$AK$4 -> SAKHINETIPALLEPadmasali/DevangaMale | AL32: =IFERROR(VLOOKUP(AI32&AJ32,$Z$5:$AG$71,8,0)/VLOOKUP(AI32&AJ32,$Z$5:$AG$71,4,0),0) -> 4.0928497
A33: Q18: Gender | B33: Count of Q18: Gender | C33: Count of Q18: Gender2 | D33: TBT | E33: Factor | Z33: =AA33&AB33 -> SAKHINETIPALLERajaka | AA33: SAKHINETIPALLE | AB33: Rajaka | AC33: 4 | AD33: 2 | AE33: 6 | AF33: =VLOOKUP(AA33,$D$42:$E$46,2,0)*VLOOKUP(AB33,$A$1:$C$13,3,0)*1000 -> 5.7368748 | AG33: =AF33*0.5 -> 2.8684374 | AI33: SAKHINETIPALLE | AJ33: Yadava | AK33: =AI33&AJ33&$AK$4 -> SAKHINETIPALLEYadavaMale | AL33: =IFERROR(VLOOKUP(AI33&AJ33,$Z$5:$AG$71,8,0)/VLOOKUP(AI33&AJ33,$Z$5:$AG$71,4,0),0) -> 0.30685005
A34: Male | B34: 588 | C34: 0.71794872 | D34: 500 | E34: =D34/B34 -> 0.85034014 | Z34: =AA34&AB34 -> SAKHINETIPALLEBrahmin | AA34: SAKHINETIPALLE | AB34: Brahmin | AC34: 8 | AE34: 8 | AF34: =VLOOKUP(AA34,$D$42:$E$46,2,0)*VLOOKUP(AB34,$A$1:$C$13,3,0)*1000 -> 2.9281965 | AG34: =AF34*0.5 -> 1.4640983 | AI34: SAKHINETIPALLE | AJ34: Kshatriya/Rajulu | AK34: =AI34&AJ34&$AK$4 -> SAKHINETIPALLEKshatriya/RajuluMale | AL34: =IFERROR(VLOOKUP(AI34&AJ34,$Z$5:$AG$71,8,0)/VLOOKUP(AI34&AJ34,$Z$5:$AG$71,4,0),0) -> 2.9242992
A35: Female | B35: 231 | C35: 0.28205128 | D35: 500 | E35: =D35/B35 -> 2.1645022 | Z35: =AA35&AB35 -> MALIKIPURAMMala | AA35: MALIKIPURAM | AB35: Mala | AC35: 21 | AD35: 11 | AE35: 32 | AF35: =VLOOKUP(AA35,$D$42:$E$46,2,0)*VLOOKUP(AB35,$A$1:$C$13,3,0)*1000 -> 89.691704 | AG35: =AF35*0.5 -> 44.845852 | AI35: SAKHINETIPALLE | AJ35: Rajaka | AK35: =AI35&AJ35&$AK$4 -> SAKHINETIPALLERajakaMale | AL35: =IFERROR(VLOOKUP(AI35&AJ35,$Z$5:$AG$71,8,0)/VLOOKUP(AI35&AJ35,$Z$5:$AG$71,4,0),0) -> 0.71710935
A36: Grand Total | B36: 819 | C36: 1 | Z36: =AA36&AB36 -> MALIKIPURAMKapu | AA36: MALIKIPURAM | AB36: Kapu | AC36: 63 | AD36: 7 | AE36: 70 | AF36: =VLOOKUP(AA36,$D$42:$E$46,2,0)*VLOOKUP(AB36,$A$1:$C$13,3,0)*1000 -> 88.873656 | AG36: =AF36*0.5 -> 44.436828 | AI36: SAKHINETIPALLE | AJ36: Adi Andhra | AK36: =AI36&AJ36&$AK$4 -> SAKHINETIPALLEAdi AndhraMale | AL36: =IFERROR(VLOOKUP(AI36&AJ36,$Z$5:$AG$71,8,0)/VLOOKUP(AI36&AJ36,$Z$5:$AG$71,4,0),0) -> 0
Z37: =AA37&AB37 -> MALIKIPURAMSettibalija | AA37: MALIKIPURAM | AB37: Settibalija | AC37: 24 | AD37: 4 | AE37: 28 | AF37: =VLOOKUP(AA37,$D$42:$E$46,2,0)*VLOOKUP(AB37,$A$1:$C$13,3,0)*1000 -> 55.54621 | AG37: =AF37*0.5 -> 27.773105 | AI37: SAKHINETIPALLE | AJ37: Brahmin | AK37: =AI37&AJ37&$AK$4 -> SAKHINETIPALLEBrahminMale | AL37: =IFERROR(VLOOKUP(AI37&AJ37,$Z$5:$AG$71,8,0)/VLOOKUP(AI37&AJ37,$Z$5:$AG$71,4,0),0) -> 0.18301228
Z38: =AA38&AB38 -> MALIKIPURAMAgnikulakshatriya | AA38: MALIKIPURAM | AB38: Agnikulakshatriya | AC38: 8 | AD38: 4 | AE38: 12 | AF38: =VLOOKUP(AA38,$D$42:$E$46,2,0)*VLOOKUP(AB38,$A$1:$C$13,3,0)*1000 -> 28.556194 | AG38: =AF38*0.5 -> 14.278097 | AI38: MALIKIPURAM | AJ38: Mala | AK38: =AI38&AJ38&$AK$4 -> MALIKIPURAMMalaMale | AL38: =IFERROR(VLOOKUP(AI38&AJ38,$Z$5:$AG$71,8,0)/VLOOKUP(AI38&AJ38,$Z$5:$AG$71,4,0),0) -> 2.1355168
Z39: =AA39&AB39 -> MALIKIPURAMMadiga | AA39: MALIKIPURAM | AB39: Madiga | AC39: 3 | AD39: 3 | AE39: 6 | AF39: =VLOOKUP(AA39,$D$42:$E$46,2,0)*VLOOKUP(AB39,$A$1:$C$13,3,0)*1000 -> 12.438536 | AG39: =AF39*0.5 -> 6.2192681 | AI39: MALIKIPURAM | AJ39: Kapu | AK39: =AI39&AJ39&$AK$4 -> MALIKIPURAMKapuMale | AL39: =IFERROR(VLOOKUP(AI39&AJ39,$Z$5:$AG$71,8,0)/VLOOKUP(AI39&AJ39,$Z$5:$AG$71,4,0),0) -> 0.70534647
A40: Valid or Not | B40: Valid | Z40: =AA40&AB40 -> MALIKIPURAMPadmasali/Devanga | AA40: MALIKIPURAM | AB40: Padmasali/Devanga | AC40: 5 | AE40: 5 | AF40: =VLOOKUP(AA40,$D$42:$E$46,2,0)*VLOOKUP(AB40,$A$1:$C$13,3,0)*1000 -> 8.8111542 | AG40: =AF40*0.5 -> 4.4055771 | AI40: MALIKIPURAM | AJ40: Settibalija | AK40: =AI40&AJ40&$AK$4 -> MALIKIPURAMSettibalijaMale | AL40: =IFERROR(VLOOKUP(AI40&AJ40,$Z$5:$AG$71,8,0)/VLOOKUP(AI40&AJ40,$Z$5:$AG$71,4,0),0) -> 1.1572127
...

Sheet Pivot
E1: Valid or Not | F1: Valid
A2: Valid or Not | B2: Valid | E2: Q10: మీరు 2024 అసెంబ్లీ ఎన్నికలో ఏ పార్టీ కి వోట్ వేశారు? | F2: YSRCP (వైఎస్‌ఆర్‌సీపీ)
A4: 2029 Party Pref | B4: Count of Q18: Gender | C4: Count of Q18: Gender2 | E4: Q11: YSRCP నియోజకవర్గ ఇంచార్జి(Gollalapalli Surya Rao) అందుబాటులో ఉంటున్నారా? | F4: Count of Q18: Gender | G4: Count of Q18: Gender2
A5: TDP/JSP/BJP (కూటమి | B5: 0.63369963 | C5: 519 | E5: ఉన్నారు, వారినే కొనసాగించాలి | F5: 0.62436548 | G5: 123
A6: YSRCP (వైఎస్‌ఆర్‌సీపీ) | B6: 0.25763126 | C6: 211 | E6: లేరు, వారిని మార్చాలి | F6: 0.19796954 | G6: 39
A7: Others (ఇతరులు) | B7: 0.10866911 | C7: 89 | E7: నాకు తెలీదు/ ఏమి చెప్పలేను | F7: 0.17766497 | G7: 35
A8: Grand Total | B8: 1 | C8: 819 | E8: Grand Total | F8: 1 | G8: 197
E11: Valid or Not | F11: Valid
A12: RAZOLE(SC) | E12: Q10: మీరు 2024 అసెంబ్లీ ఎన్నికలో ఏ పార్టీ కి వోట్ వేశారు? | F12: YSRCP (వైఎస్‌ఆర్‌సీపీ)
A14: Valid or Not | B14: Sample Count | E14: Q12: ఒకవేళ YSRCP నియోజకవర్గ ఇంచార్జి ని మార్చాల్సి వస్తే ఎవరైతే బాగుంటుంది అని మీరు భావిస్తున్నారు? (ఈ ప్రశ్న 2024 అసెంబ్లీ ఎన్నికలో YSRCPకి ఓటు వేసినవారికి మాత్రమే చూపించబడుతుంది) | F14: Count of Q18: Gender | G14: Count of Q18: Gender2
A15: Not Valid | B15: 91 | E15: Gollapalli Surya Rao | F15: 0.65482234 | G15: 129
A16: Valid | B16: 819 | E16: Pamula Rajeswari Devi | F16: 0.14720812 | G16: 29
A17: Grand Total | B17: 910 | E17: Gollapalli Sridhar | F17: 0.10152284 | G17: 20
E18: Matta Sailaja Ravi Kumar | F18: 0.050761421 | G18: 10
E19: Balla Prasanna Kumari | F19: 0.045685279 | G19: 9
E20: Grand Total | F20: 1 | G20: 197

Sheet Data
A1: Sample ID | B1: Date | C1: Timestamp | D1: Location | E1: Address | F1: Surveyor | G1: Company | H1: Audio URL | I1: Caste | J1: Taluka | K1: Locality | L1: Q13: వృత్తి | M1: Q14: మతం | N1: Q15: వయసు | O1: Q16: మీ పేరు | P1: Q17: మీ ఫోన్ నంబర్ | Q1: Q18: Gender | R1: Q1: స్థానికంగా మీకున్న ప్రధానమైన సమస్యలు ఏమిటి? | S1: Q2: మీ ఎమ్మెల్యే గారి పనితీరు ఎలాగా ఉంది? | T1: Q3: చంద్రబాబు నాయుడు గారి ప్రభుత్వ పనితీరు పై మీ అభిప్రాయం? | U1: Q4: సూపర్ 6/7 పధకాలు ఎన్నికల ముందు చెప్పినట్లు గా అమలుఅవుతున్నాయా? | V1: Q5: సంక్షేమ పధకాలు ఎవరి హయాంలో బాగా అమలు అయ్యాయి అని మీరు అనుకుంటున్నారు? | W1: Q6: మీ ద్రుష్టి లో అభివృద్ధి అంటే ముఖ్యంగా ఏమిటి (మీకు మ్రుఖ్యమైన 3 చెప్పండి)? | X1: Q7: అభివృద్ధి కార్యక్రమాలు ఎవరి హయాంలో బాగా జరిగాయి అని మీరు భావిస్తున్నారు? | Y1: Q8: గత ఎన్నికలలో వేసిన ఓటు పై మీ అభిప్రాయం ఏమిటి? | Z1: Q9: 2029 లో/ ఇప్పటికి ఇప్పుడు ఎన్నికలు జరిగితే మీరు ఏ పార్టీకి ఓటు వేస్తారు ? | AA1: Q10: మీరు 2024 అసెంబ్లీ ఎన్నికలో ఏ పార్టీ కి వోట్ వేశారు? | AB1: Q11: YSRCP నియోజకవర్గ ఇంచార్జి(Gollalapalli Surya Rao) అందుబాటులో ఉంటున్నారా? | AC1: Q12: ఒకవేళ YSRCP నియోజకవర్గ ఇంచార్జి ని మార్చాల్సి వస్తే ఎవరైతే బాగుంటుంది అని మీరు భావిస్తున్నారు? (ఈ ప్రశ్న 2024 అసెంబ్లీ ఎన్నికలో YSRCPకి ఓటు వేసినవారికి మాత్రమే చూపించబడుతుంది) | AD1: QC Username | AE1: QC Comment | AF1: QC Remark | AG1: Valid or Not | AH1: Caste Factor | AI1: 2024 Factor | AJ1: Multi Factor | AK1: Gender factor | AL1: Mandal Factor | AM1: Factor_1 | AN1: Factor_2 | AO1: Satis | AP1: Sch Sat | AQ1: Wel | AR1: Dev | AS1: 24 | AT1: 29 | AU1: Core Cal | AV1: Hard Core Score | AW1: Sympethiser1 Score | AX1: Sympethiser 2 Score | AY1: Neutral Score | AZ1: Category
A2: bcd15c14-125b-48b2-a857-8992a52f6a22 | B2: 46041 | C2: 1/19/2026, 10:53:11 AM | D2: 16.535880, 81.944867 | E2: GWPV+MV3, Botlakurru Doddavaram, Andhra Pradesh, India | F2: Kumpatla venkata satya suryamohan rao | G2: Naeem | H2: http://164.52.221.216/localmedia/media/surveys/samples/recording_2026-01-19_10-47-30_samples_WIgA6Z2O6U.mp4 | I2: Mala | J2: MALIKIPURAM | K2: LAKKAVARAM | L2: కార్మిక/రోజువారీ కూలీ | M2: హిందూ | N2: 41-59 | O2: Sivaramakrishnan.thadi | P2: 9550492165 | Q2: Male | R2: సాగునీరు | S2: ఏమి చెప్పలేను | T2: బాగాలేదు | U2: అమలవడం లేదు | V2: జగన్ మోహన్ రెడ్డి గారు | W2: విద్య రంగం అభివృద్ధి చేయటం,ఆరోగ్య రంగం అభివృద్ధి చేయటం,సంక్షేమ పథకాలు (నగదు) | X2: జగన్ మోహన్ రెడ్డి గారు | Y2: సరైన పార్టీకి వేసాను | Z2: YSRCP (వైఎస్‌ఆర్‌సీపీ) | AA2: YSRCP (వైఎస్‌ఆర్‌సీపీ) | AB2: ఉన్నారు, వారినే కొనసాగించాలి | AC2: Gollapalli Surya Rao | AD2: Bhagya | AE2: Correctly Done | AF2: Incharge -Rambabu?? | AG2: Valid | AH2: =VLOOKUP(Table1[[#This Row],[Caste]],Factor!$H$1:$K$13,4,0) -> 1.3836275 | AI2: =IFERROR(VLOOKUP(Table1[[#This Row],[Q10: మీరు 2024 అసెంబ్లీ ఎన్నికలో ఏ పార్టీ కి వోట్ వేశారు?]],Factor!$D$22:$H$23,5,0),Factor!$H$24) -> 1.8055838 | AJ2: =Table1[[#This Row],[Factor_1]]*Table1[[#This Row],[2024 Factor]] -> 1.9482662 | AK2: =VLOOKUP(Table1[[#This Row],[Q18: Gender]],Factor!$A$33:$E$35,5,0) -> 0.85034014 | AL2: =VLOOKUP(Table1[[#This Row],[Taluka]],Factor!$A$42:$G$46,7,0) -> 1.9264642 | AM2: =VLOOKUP(Table1[[#This Row],[Caste]]&Table1[[#This Row],[Q18: Gender]],Factor!$W$1:$X$23,2,0) -> 1.0790229 | AN2: =VLOOKUP(Table1[[#This Row],[Taluka]]&Table1[[#This Row],[Caste]]&Table1[[#This Row],[Q18: Gender]],Factor!$AK$4:$AL$93,2,0) -> 2.1355168 | AO2: =IF(T2="బాగుంది",-1,1) -> 1 | AP2: =IF(U2="అమలవడం లేదు",1,-1) -> 1 | AQ2: =IF(V2="జగన్ మోహన్ రెడ్డి గారు",1,-1) -> 1 | AR2: =IF(X2="జగన్ మోహన్ రెడ్డి గారు",1,-1) -> 1 | AS2: =IF(AA2="YSRCP (వైఎస్‌ఆర్‌సీపీ)",1,-1) -> 1 | AT2: =IF(Z2="YSRCP (వైఎస్‌ఆర్‌సీపీ)",1,-1) -> 1 | AU2: =AO2+AP2+AQ2+AR2+(0.5*AS2)+AT2 -> 5.5 | AV2: =SUM(Table1[[#This Row],[Satis]:[29]]) -> 6 | AW2: =AO2+AQ2+AR2+AS2+AT2 -> 5 | AX2: =AQ2+AR2+AS2+AT2 -> 4 | AY2: =IF(AND(AO2=1,AS2=1,AT2=1),3,IF(AND(AO2=-1,AS2=-1,AT2=-1),-3,IF(AND(AO2=1,AS2=-1,AT2=1),2,IF(AND(AO2=-1,AS2=1,AT2=-1),-2,IF(AND(AS2=1,AT2=1),2,IF(AND(AS2=-1,AT2=-1),-2,"ND")))))) -> 3 | AZ2: =IFERROR(IF(AV2=6,"YSRCP HardCore",IF(AV2=-6,"TDP HardCore",IF(AW2>=4,"YSRCP Sympathiser",IF(AW2<=-4,"TDP Sympathiser",IF(AX2>=3,"YSRCP Sympathiser",IF(AX2<=-3,"TDP Sympathiser",IF(AY2="ND","ND",IF(AY2>=2,"Neutral YSRCP",IF(AY2<=-2,"Neutral TDP",0))))))))),"ND") -> YSRCP HardCore
A3: 45c3ab84-6136-4d54-9601-544bdb5d7c6d | B3: 46041 | C3: 1/19/2026, 11:06:27 AM | D3: 16.537167, 81.944575 | E3: GWPV+MV3, Botlakurru Doddavaram, Andhra Pradesh, India | F3: Kumpatla venkata satya suryamohan rao | G3: Naeem | H3: http://164.52.221.216/localmedia/media/surveys/samples/recording_2026-01-19_11-01-53_samples_ly90HBESLu.mp4 | I3: Settibalija | J3: MALIKIPURAM | K3: LAKKAVARAM | L3: వ్యాపారం | M3: హిందూ | N3: 41-59 | O3: kudupudi.kkrihna | P3: 8790918772 | Q3: Male | R3: సాగునీరు | S3: బాగుంది | T3: బాగుంది | U3: అమలుఅవుతున్నాయి | V3: చంద్రబాబు నాయుడు గారు | W3: ఉద్యొగ్య అవకాశాలు కల్పించటం,శాంతి భద్రతలను కాపాడటం,ఆరోగ్య రంగం అభివృద్ధి చేయటం | X3: చంద్రబాబు నాయుడు గారు | Y3: సరైన పార్టీకి వేసాను | Z3: TDP/JSP/BJP (కూటమి | AA3: TDP/JSP/BJP (కూటమి) | AB3: No response | AC3: No response | AD3: Bhagya | AE3: Correctly Done | AF3: Not asking the question as it is in the questionnaire | AG3: Valid | AH3: =VLOOKUP(Table1[[#This Row],[Caste]],Factor!$H$1:$K$13,4,0) -> 1.1705128 | AI3: =IFERROR(VLOOKUP(Table1[[#This Row],[Q10: మీరు 2024 అసెంబ్లీ ఎన్నికలో ఏ పార్టీ కి వోట్ వేశారు?]],Factor!$D$22:$H$23,5,0),Factor!$H$24) -> 1.0795332 | AJ3: =Table1[[#This Row],[Factor_1]]*Table1[[#This Row],[2024 Factor]] -> 0.86308903 | AK3: =VLOOKUP(Table1[[#This Row],[Q18: Gender]],Factor!$A$33:$E$35,5,0) -> 0.85034014 | AL3: =VLOOKUP(Table1[[#This Row],[Taluka]],Factor!$A$42:$G$46,7,0) -> 1.9264642 | AM3: =VLOOKUP(Table1[[#This Row],[Caste]]&Table1[[#This Row],[Q18: Gender]],Factor!$W$1:$X$23,2,0) -> 0.79950206 | AN3: =VLOOKUP(Table1[[#This Row],[Taluka]]&Table1[[#This Row],[Caste]]&Table1[[#This Row],[Q18: Gender]],Factor!$AK$4:$AL$93,2,0) -> 1.1572127 | AO3: =IF(T3="బాగుంది",-1,1) -> -1 | AP3: =IF(U3="అమలవడం లేదు",1,-1) -> -1 | AQ3: =IF(V3="జగన్ మోహన్ రెడ్డి గారు",1,-1) -> -1 | AR3: =IF(X3="జగన్ మోహన్ రెడ్డి గారు",1,-1) -> -1 | AS3: =IF(AA3="YSRCP (వైఎస్‌ఆర్‌సీపీ)",1,-1) -> -1 | AT3: =IF(Z3="YSRCP (వైఎస్‌ఆర్‌సీపీ)",1,-1) -> -1 | AU3: =AO3+AP3+AQ3+AR3+(0.5*AS3)+AT3 -> -5.5 | AV3: =SUM(Table1[[#This Row],[Satis]:[29]]) -> -6 | AW3: =AO3+AQ3+AR3+AS3+AT3 -> -5 | AX3: =AQ3+AR3+AS3+AT3 -> -4 | AY3: =IF(AND(AO3=1,AS3=1,AT3=1),3,IF(AND(AO3=-1,AS3=-1,AT3=-1),-3,IF(AND(AO3=1,AS3=-1,AT3=1),2,IF(AND(AO3=-1,AS3=1,AT3=-1),-2,IF(AND(AS3=1,AT3=1),2,IF(AND(AS3=-1,AT3=-1),-2,"ND")))))) -> -3 | AZ3: =IFERROR(IF(AV3=6,"YSRCP HardCore",IF(AV3=-6,"TDP HardCore",IF(AW3>=4,"YSRCP Sympathiser",IF(AW3<=-4,"TDP Sympathiser",IF(AX3>=3,"YSRCP Sympathiser",IF(AX3<=-3,"TDP Sympathiser",IF(AY3="ND","ND",IF(AY3>=2,"Neutral YSRCP",IF(AY3<=-2,"Neutral TDP",0))))))))),"ND") -> TDP HardCore
A4: 5b87a98e-34d1-4f46-bded-b50856d41691 | B4: 46041 | C4: 1/19/2026, 9:13:52 AM | D4: 16.628410, 80.582359 | E4: JHHM+94J Mulla Manzil, Kavuluru, Andhra Pradesh, India | F4: krishna | G4: Naeem | H4: http://164.52.221.216/localmedia/media/surveys/samples/recording_2026-01-19_09-06-08_samples_05T440VZk7.mp4 | I4: Mala | J4: RAZOLE | K4: RAZOLE | L4: ప్రైవేట్ ఉద్యోగం | M4: హిందూ | N4: 41-59 | O4: krishna | P4: 0 | Q4: Male | R4: కరెంట్ | S4: బాగుంది | T4: బాగుంది | U4: అమలుఅవుతున్నాయి | V4: చంద్రబాబు నాయుడు గారు | W4: రోడ్లు వేయటం | X4: చంద్రబాబు నాయుడు గారు | Y4: సరైన పార్టీకి వేసాను | Z4: TDP/JSP/BJP (కూటమి | AA4: TDP/JSP/BJP (కూటమి) | AB4: No response | AC4: No response | AD4: Bhagya | AE4: Correctly Done | AF4: 0 | AG4: Valid | AH4: =VLOOKUP(Table1[[#This Row],[Caste]],Factor!$H$1:$K$13,4,0) -> 1.3836275 | AI4: =IFERROR(VLOOKUP(Table1[[#This Row],[Q10: మీరు 2024 అసెంబ్లీ ఎన్నికలో ఏ పార్టీ కి వోట్ వేశారు?]],Factor!$D$22:$H$23,5,0),Factor!$H$24) -> 1.0795332 | AJ4: =Table1[[#This Row],[Factor_1]]*Table1[[#This Row],[2024 Factor]] -> 1.1648411 | AK4: =VLOOKUP(Table1[[#This Row],[Q18: Gender]],Factor!$A$33:$E$35,5,0) -> 0.85034014 | AL4: =VLOOKUP(Table1[[#This Row],[Taluka]],Factor!$A$42:$G$46,7,0) -> 1.1213131 | AM4: =VLOOKUP(Table1[[#This Row],[Caste]]&Table1[[#This Row],[Q18: Gender]],Factor!$W$1:$X$23,2,0) -> 1.0790229 | AN4: =VLOOKUP(Table1[[#This Row],[Taluka]]&Table1[[#This Row],[Caste]]&Table1[[#This Row],[Q18: Gender]],Factor!$AK$4:$AL$93,2,0) -> 0.90933568 | AO4: =IF(T4="బాగుంది",-1,1) -> -1 | AP4: =IF(U4="అమలవడం లేదు",1,-1) -> -1 | AQ4: =IF(V4="జగన్ మోహన్ రెడ్డి గారు",1,-1) -> -1 | AR4: =IF(X4="జగన్ మోహన్ రెడ్డి గారు",1,-1) -> -1 | AS4: =IF(AA4="YSRCP (వైఎస్‌ఆర్‌సీపీ)",1,-1) -> -1 | AT4: =IF(Z4="YSRCP (వైఎస్‌ఆర్‌సీపీ)",1,-1) -> -1 | AU4: =AO4+AP4+AQ4+AR4+(0.5*AS4)+AT4 -> -5.5 | AV4: =SUM(Table1[[#This Row],[Satis]:[29]]) -> -6 | AW4: =AO4+AQ4+AR4+AS4+AT4 -> -5 | AX4: =AQ4+AR4+AS4+AT4 -> -4 | AY4: =IF(AND(AO4=1,AS4=1,AT4=1),3,IF(AND(AO4=-1,AS4=-1,AT4=-1),-3,IF(AND(AO4=1,AS4=-1,AT4=1),2,IF(AND(AO4=-1,AS4=1,AT4=-1),-2,IF(AND(AS4=1,AT4=1),2,IF(AND(AS4=-1,AT4=-1),-2,"ND")))))) -> -3 | AZ4: =IFERROR(IF(AV4=6,"YSRCP HardCore",IF(AV4=-6,"TDP HardCore",IF(AW4>=4,"YSRCP Sympathiser",IF(AW4<=-4,"TDP Sympathiser",IF(AX4>=3,"YSRCP Sympathiser",IF(AX4<=-3,"TDP Sympathiser",IF(AY4="ND","ND",IF(AY4>=2,"Neutral YSRCP",IF(AY4<=-2,"Neutral TDP",0))))))))),"ND") -> TDP HardCore
A5: fc0457dc-d165-4b76-99de-99c0cb3953a6 | B5: 46041 | C5: 1/19/2026, 9:45:45 AM | D5: 16.574904, 81.921684 | E5: HWFC+WP9, Munjavarapukottu, Andhra Pradesh, India | F5: Kumpatla venkata satya suryamohan rao | G5: Naeem | H5: http://164.52.221.216/localmedia/media/surveys/samples/recording_2026-01-19_09-42-18_samples_XmxhOLnKVA.mp4 | I5: Kapu | J5: MAMIDIKUDURU_PART | K5: PEDAPATNAM | L5: వ్యవసాయం | M5: హిందూ | N5: 41-59 | O5: mohan | P5: 9912576664 | Q5: Male | R5: డ్రైనేజి | S5: బాగుంది | T5: బాగుంది | U5: అమలుఅవుతున్నాయి | V5: చంద్రబాబు నాయుడు గారు | W5: రోడ్లు వేయటం,ఉద్యొగ్య అవకాశాలు కల్పించటం,శాంతి భద్రతలను కాపాడటం | X5: చంద్రబాబు నాయుడు గారు | Y5: సరైన పార్టీకి వేసాను | Z5: TDP/JSP/BJP (కూటమి | AA5: TDP/JSP/BJP (కూటమి) | AB5: No response | AC5: No response | AD5: Bhagya | AE5: Correctly Done | AF5: 0 | AG5: Valid | AH5: =VLOOKUP(Table1[[#This Row],[Caste]],Factor!$H$1:$K$13,4,0) -> 1.1461626 | AI5: =IFERROR(VLOOKUP(Table1[[#This Row],[Q10: మీరు 2024 అసెంబ్లీ ఎన్నికలో ఏ పార్టీ కి వోట్ వేశారు?]],Factor!$D$22:$H$23,5,0),Factor!$H$24) -> 1.0795332 | AJ5: =Table1[[#This Row],[Factor_1]]*Table1[[#This Row],[2024 Factor]] -> 0.7772114 | AK5: =VLOOKUP(Table1[[#This Row],[Q18: Gender]],Factor!$A$33:$E$35,5,0) -> 0.85034014 | AL5: =VLOOKUP(Table1[[#This Row],[Taluka]],Factor!$A$42:$G$46,7,0) -> 0.7543378 | AM5: =VLOOKUP(Table1[[#This Row],[Caste]]&Table1[[#This Row],[Q18: Gender]],Factor!$W$1:$X$23,2,0) -> 0.71995135 | AN5: =VLOOKUP(Table1[[#This Row],[Taluka]]&Table1[[#This Row],[Caste]]&Table1[[#This Row],[Q18: Gender]],Factor!$AK$4:$AL$93,2,0) -> 0.55527787 | AO5: =IF(T5="బాగుంది",-1,1) -> -1 | AP5: =IF(U5="అమలవడం లేదు",1,-1) -> -1 | AQ5: =IF(V5="జగన్ మోహన్ రెడ్డి గారు",1,-1) -> -1 | AR5: =IF(X5="జగన్ మోహన్ రెడ్డి గారు",1,-1) -> -1 | AS5: =IF(AA5="YSRCP (వైఎస్‌ఆర్‌సీపీ)",1,-1) -> -1 | AT5: =IF(Z5="YSRCP (వైఎస్‌ఆర్‌సీపీ)",1,-1) -> -1 | AU5: =AO5+AP5+AQ5+AR5+(0.5*AS5)+AT5 -> -5.5 | AV5: =SUM(Table1[[#This Row],[Satis]:[29]]) -> -6 | AW5: =AO5+AQ5+AR5+AS5+AT5 -> -5 | AX5: =AQ5+AR5+AS5+AT5 -> -4 | AY5: =IF(AND(AO5=1,AS5=1,AT5=1),3,IF(AND(AO5=-1,AS5=-1,AT5=-1),-3,IF(AND(AO5=1,AS5=-1,AT5=1),2,IF(AND(AO5=-1,AS5=1,AT5=-1),-2,IF(AND(AS5=1,AT5=1),2,IF(AND(AS5=-1,AT5=-1),-2,"ND")))))) -> -3 | AZ5: =IFERROR(IF(AV5=6,"YSRCP HardCore",IF(AV5=-6,"TDP HardCore",IF(AW5>=4,"YSRCP Sympathiser",IF(AW5<=-4,"TDP Sympathiser",IF(AX5>=3,"YSRCP Sympathiser",IF(AX5<=-3,"TDP Sympathiser",IF(AY5="ND","ND",IF(AY5>=2,"Neutral YSRCP",IF(AY5<=-2,"Neutral TDP",0))))))))),"ND") -> TDP HardCore
A6: f8124df2-5ce1-40dd-938a-7b7e6403fea9 | B6: 46041 | C6: 1/19/2026, 11:16:27 AM | D6: 16.533828, 81.946129 | E6: GWMW+G94, Botlakurru Doddavaram, Andhra Pradesh, India | F6: Kumpatla venkata satya suryamohan rao | G6: Naeem | H6: http://164.52.221.216/localmedia/media/surveys/samples/recording_2026-01-19_11-11-50_samples_zXAWLUUd8q.mp4 | I6: Kapu | J6: MALIKIPURAM | K6: LAKKAVARAM | L6: కార్మిక/రోజువారీ కూలీ | M6: హిందూ | N6: 26-40 | O6: Rajesh.javadhi | P6: 7569733861 | Q6: Male | R6: డ్రైనేజి | S6: బాగుంది | T6: బాగుంది | U6: అమలుఅవుతున్నాయి | V6: చంద్రబాబు నాయుడు గారు | W6: ఉద్యొగ్య అవకాశాలు కల్పించటం,ఆరోగ్య రంగం అభివృద్ధి చేయటం,సంక్షేమ పథకాలు (నగదు) | X6: చంద్రబాబు నాయుడు గారు | Y6: సరైన పార్టీకి వేసాను | Z6: TDP/JSP/BJP (కూటమి | AA6: TDP/JSP/BJP (కూటమి) | AB6: No response | AC6: No response | AD6: Bhagya | AE6: Correctly Done | AF6: Not asking the question as it is in the questionnaire | AG6: Valid | AH6: =VLOOKUP(Table1[[#This Row],[Caste]],Factor!$H$1:$K$13,4,0) -> 1.1461626 | AI6: =IFERROR(VLOOKUP(Table1[[#This Row],[Q10: మీరు 2024 అసెంబ్లీ ఎన్నికలో ఏ పార్టీ కి వోట్ వేశారు?]],Factor!$D$22:$H$23,5,0),Factor!$H$24) -> 1.0795332 | AJ6: =Table1[[#This Row],[Factor_1]]*Table1[[#This Row],[2024 Factor]] -> 0.7772114 | AK6: =VLOOKUP(Table1[[#This Row],[Q18: Gender]],Factor!$A$33:$E$35,5,0) -> 0.85034014 | AL6: =VLOOKUP(Table1[[#This Row],[Taluka]],Factor!$A$42:$G$46,7,0) -> 1.9264642 | AM6: =VLOOKUP(Table1[[#This Row],[Caste]]&Table1[[#This Row],[Q18: Gender]],Factor!$W$1:$X$23,2,0) -> 0.71995135 | AN6: =VLOOKUP(Table1[[#This Row],[Taluka]]&Table1[[#This Row],[Caste]]&Table1[[#This Row],[Q18: Gender]],Factor!$AK$4:$AL$93,2,0) -> 0.70534647 | AO6: =IF(T6="బాగుంది",-1,1) -> -1 | AP6: =IF(U6="అమలవడం లేదు",1,-1) -> -1 | AQ6: =IF(V6="జగన్ మోహన్ రెడ్డి గారు",1,-1) -> -1 | AR6: =IF(X6="జగన్ మోహన్ రెడ్డి గారు",1,-1) -> -1 | AS6: =IF(AA6="YSRCP (వైఎస్‌ఆర్‌సీపీ)",1,-1) -> -1 | AT6: =IF(Z6="YSRCP (వైఎస్‌ఆర్‌సీపీ)",1,-1) -> -1 | AU6: =AO6+AP6+AQ6+AR6+(0.5*AS6)+AT6 -> -5.5 | AV6: =SUM(Table1[[#This Row],[Satis]:[29]]) -> -6 | AW6: =AO6+AQ6+AR6+AS6+AT6 -> -5 | AX6: =AQ6+AR6+AS6+AT6 -> -4 | AY6: =IF(AND(AO6=1,AS6=1,AT6=1),3,IF(AND(AO6=-1,AS6=-1,AT6=-1),-3,IF(AND(AO6=1,AS6=-1,AT6=1),2,IF(AND(AO6=-1,AS6=1,AT6=-1),-2,IF(AND(AS6=1,AT6=1),2,IF(AND(AS6=-1,AT6=-1),-2,"ND")))))) -> -3 | AZ6: =IFERROR(IF(AV6=6,"YSRCP HardCore",IF(AV6=-6,"TDP HardCore",IF(AW6>=4,"YSRCP Sympathiser",IF(AW6<=-4,"TDP Sympathiser",IF(AX6>=3,"YSRCP Sympathiser",IF(AX6<=-3,"TDP Sympathiser",IF(AY6="ND","ND",IF(AY6>=2,"Neutral YSRCP",IF(AY6<=-2,"Neutral TDP",0))))))))),"ND") -> TDP HardCore
